Workbook
Name ACURA: 'Staff & Lists'!$T$5:$T$22
Name AdSourceList: 'Staff & Lists'!$J$5:INDEX('Staff & Lists'!$J$5:$J$204,COUNTA('Staff & Lists'!$J$5:$J$204))
Name ALFA_ROMEO: 'Staff & Lists'!$U$5:$U$11
Name ASTON_MARTIN: 'Staff & Lists'!$V$5:$V$16
Name AUDI: 'Staff & Lists'!$W$5:$W$43
Name BENTLEY: 'Staff & Lists'!$X$5:$X$14
Name BMW: 'Staff & Lists'!$Y$5:$Y$56
Name BUICK: 'Staff & Lists'!$Z$5:$Z$24
Name CADILLAC: 'Staff & Lists'!$AA$5:$AA$32
Name CHEVROLET: 'Staff & Lists'!$AB$5:$AB$54
Name CHRYSLER: 'Staff & Lists'!$AC$5:$AC$21
Name DODGE: 'Staff & Lists'!$AD$5:$AD$30
Name FERRARI: 'Staff & Lists'!$AE$5:$AE$32
Name FIAT: 'Staff & Lists'!$AF$5:$AF$9
Name FinanceManagerList: 'Staff & Lists'!$G$5:INDEX('Staff & Lists'!$G$5:$G$204,COUNTA('Staff & Lists'!$G$5:$G$204))
Name FORD: 'Staff & Lists'!$AG$5:$AG$51
Name GENESIS: 'Staff & Lists'!$AH$5:$AH$12
Name GMC: 'Staff & Lists'!$AI$5:$AI$24
Name GoalGrossNew: Goals!$C$12
Name GoalGrossPerDay: Goals!$B$25
Name GoalGrossTotal: Goals!$C$14
Name GoalGrossUsed: Goals!$C$13
Name GoalPVRBack: Goals!$B$19
Name GoalPVRFront: Goals!$B$18
Name GoalPVRTotal: Goals!$B$20
Name GoalSellingDays: Goals!$C$8
Name GoalUnitsNew: Goals!$B$12
Name GoalUnitsPerDay: Goals!$B$24
Name GoalUnitsTotal: Goals!$B$14
Name GoalUnitsUsed: Goals!$B$13
Name HONDA: 'Staff & Lists'!$AJ$5:$AJ$23
Name HUMMER: 'Staff & Lists'!$AK$5:$AK$8
Name HYUNDAI: 'Staff & Lists'!$AL$5:$AL$29
Name INFINITI: 'Staff & Lists'!$AM$5:$AM$32
Name ISUZU: 'Staff & Lists'!$AN$5:$AN$16
Name JAGUAR: 'Staff & Lists'!$AO$5:$AO$21
Name JEEP: 'Staff & Lists'!$AP$5:$AP$19
Name KIA: 'Staff & Lists'!$AQ$5:$AQ$27
Name LAMBORGHINI: 'Staff & Lists'!$AR$5:$AR$13
Name LAND_ROVER: 'Staff & Lists'!$AS$5:$AS$15
Name LenderList: 'Staff & Lists'!$M$5:INDEX('Staff & Lists'!$M$5:$M$204,COUNTA('Staff & Lists'!$M$5:$M$204))
Name LEXUS: 'Staff & Lists'!$AT$5:$AT$53
Name LINCOLN: 'Staff & Lists'!$AU$5:$AU$20
Name LOTUS: 'Staff & Lists'!$AV$5:$AV$10
Name LUCID: 'Staff & Lists'!$AW$5:$AW$6
Name MakeList: 'Staff & Lists'!$R$5:$R$61
Name MASERATI: 'Staff & Lists'!$AX$5:$AX$14
Name MAZDA: 'Staff & Lists'!$AY$5:$AY$30
Name MCLAREN: 'Staff & Lists'!$AZ$5:$AZ$16
Name MERCEDES_BENZ: 'Staff & Lists'!$BA$5:$BA$40
Name MERCURY: 'Staff & Lists'!$BB$5:$BB$16
Name MINI: 'Staff & Lists'!$BC$5:$BC$15
Name MITSUBISHI: 'Staff & Lists'!$BD$5:$BD$19
Name N_ONLY: 'Staff & Lists'!$P$43
Name NISSAN: 'Staff & Lists'!$BE$5:$BE$33
Name OLDSMOBILE: 'Staff & Lists'!$BF$5:$BF$16
Name PLYMOUTH: 'Staff & Lists'!$BG$5:$BG$11
Name POLESTAR: 'Staff & Lists'!$BH$5:$BH$8
Name PONTIAC: 'Staff & Lists'!$BI$5:$BI$20
Name PORSCHE: 'Staff & Lists'!$BJ$5:$BJ$20

Sheet Guide
A1: GUIDE | C1: GUIDE — HOW THIS WORKBOOK WORKS | G1: =" as of "&TEXT(TODAY(),"ddd mmm d") -> as of Sat Aug 1
C3: Gallatin Ford · Advanced Deal Log v6 · daily driver
B5: ="PVR month-to-date: "&IF('Jul 31'!$C$62=0,"— (no delivered units yet)",TEXT('Jul 31'!$C$63/'Jul 31'!$C$62,"$#,##0")&" per copy · "&'Jul 31'!$C$62&" units · "&TEXT('Jul 31'!$C$63,"$#,##0")&" total gross") -> PVR month-to-date: — (no delivered units yet)
B7: Daily flow | C7: Open today’s day tab (gold TODAY chip on the nav rail). Enter each deal on one row: type, deal#, stock, customer, SP1/SP2, vehicle, gross, status. Splits: put both reps in SP1 and SP2 — credit auto-splits ½/½.
B8: Status drives everything | C8: Delivered counts toward units, gross, pace and pay. Pending / Unwind / Back Out are isolated — they never credit a rollup and surface only in the pipeline and FLAGS.
B9: Dashboard | C9: Live month-to-date roll-up of all 31 day tabs: MTD cards, goal & pace band, calendar (click a day to jump), salesperson leaderboard, channel mix, products.
B10: Deal Explorer | C10: Every deal in one filterable ledger. Set the criteria (Salesperson matches SP1 or SP2, Type, Status, Certified, Min Gross, Search), then filter the ✓ column (Data → Reapply).
B11: Commissions | C11: Retro pay: each rep’s final monthly units set the tier for every deal. Draw is entered by payroll (yellow column); Balance = Earnings − Draw. Six internal audits sit under the table.
B12: Trade Report | C12: Per-day trades, turned-in vs kept, and ACV, with a month recap. Kept (not-turned-in) trades are flagged.
B13: Nightly Text | C13: Fill the yellow live inputs, wait for “✅ READY TO COPY”, then copy the box at the bottom into Teams. Day-override cell lets you re-run a prior day.
B14: Scoreboard / Leaderboard | C14: Scoreboard is goal-vs-MTD with pace %. Leaderboard is the printable rep ranking. Both stay blank (“-”) until goals and deals exist.
B15: Goals & Pay Plan | C15: Set monthly Unit / Gross / PVR goals on the Goals tab — they flow to every surface. The Pay Plan tab is the single source of truth for commission math (edit the dollar cells).

Sheet Goals
A1: GALLATIN FORD — JULY 2026 GOALS
A4: MONTH FACTS
A5: Month | C5: July 2026
A6: Days in Month | C6: 31
A7: Closed (Sundays) | C7: 4
A8: Selling Days | C8: 27
A10: MONTHLY GOALS
B11: Units | C11: Gross
A12: New
A13: Used
A14: Total | B14: =IF(COUNT(B12:B13)=0,"",SUM(B12:B13)) | C14: =IF(COUNT(C12:C13)=0,"",SUM(C12:C13))
A17: PVR GOALS (per copy)
A18: Front PVR
A19: Back PVR
A20: Total PVR | B20: =IF(COUNT(B18:B19)=0,"",SUM(B18:B19))
A23: PER-SELLING-DAY TARGETS
A24: Units / Day | B24: =IF(OR($C$8="",$C$8=0,B14=""),"",ROUND(B14/$C$8,1))
A25: Gross / Day | B25: =IF(OR($C$8="",$C$8=0,C14=""),"",ROUND(C14/$C$8,0))
A28: CONSISTENCY CHECK (±2%)
A29: =IF(OR(B14="",C14="",B18="",B19=""),"-",IF(ABS(B14*(B18+B19)-C14)<=0.02*C14,"✓ CONSISTENT — units × PVR ≈ gross goal","⚠ CHECK — units × PVR ≠ gross goal (±2%)")) -> -

Sheet Scoreboard
A1: SCOREBOARD | C1: SCOREBOARD — JULY 2026 | E1: =" as of "&TEXT(TODAY(),"ddd mmm d") -> as of Sat Aug 1
C3: Goal vs month-to-date · blank until goals + deals are entered
A6: UNITS
C7: Goal | D7: MTD | E7: % Goal | F7: To Go
B8: New | C8: =IF(GoalUnitsNew="","-",GoalUnitsNew) -> - | D8: =$B$36 -> 0 | E8: =IF(OR(GoalUnitsNew="",GoalUnitsNew=0),"-",$B$36/GoalUnitsNew) -> - | F8: =IF(GoalUnitsNew="","-",MAX(0,GoalUnitsNew-$B$36)) -> -
B9: Used | C9: =IF(GoalUnitsUsed="","-",GoalUnitsUsed) -> - | D9: =$B$37 -> 0 | E9: =IF(OR(GoalUnitsUsed="",GoalUnitsUsed=0),"-",$B$37/GoalUnitsUsed) -> - | F9: =IF(GoalUnitsUsed="","-",MAX(0,GoalUnitsUsed-$B$37)) -> -
B10: Total | C10: =IF(GoalUnitsTotal="","-",GoalUnitsTotal) -> - | D10: ='Jul 31'!$C$62 -> 0 | E10: =IF(OR(GoalUnitsTotal="",GoalUnitsTotal=0),"-",'Jul 31'!$C$62/GoalUnitsTotal) -> - | F10: =IF(GoalUnitsTotal="","-",MAX(0,GoalUnitsTotal-'Jul 31'!$C$62)) -> -
A12: GROSS
C13: Goal | D13: MTD | E13: % Goal | F13: To Go
B14: New | C14: =IF(GoalGrossNew="","-",GoalGrossNew) -> - | D14: =$B$38 -> 0 | E14: =IF(OR(GoalGrossNew="",GoalGrossNew=0),"-",$B$38/GoalGrossNew) -> - | F14: =IF(GoalGrossNew="","-",MAX(0,GoalGrossNew-$B$38)) -> -
B15: Used | C15: =IF(GoalGrossUsed="","-",GoalGrossUsed) -> - | D15: =$B$39 -> 0 | E15: =IF(OR(GoalGrossUsed="",GoalGrossUsed=0),"-",$B$39/GoalGrossUsed) -> - | F15: =IF(GoalGrossUsed="","-",MAX(0,GoalGrossUsed-$B$39)) -> -
B16: Total | C16: =IF(GoalGrossTotal="","-",GoalGrossTotal) -> - | D16: ='Jul 31'!$C$63 -> 0 | E16: =IF(OR(GoalGrossTotal="",GoalGrossTotal=0),"-",'Jul 31'!$C$63/GoalGrossTotal) -> - | F16: =IF(GoalGrossTotal="","-",MAX(0,GoalGrossTotal-'Jul 31'!$C$63)) -> -
A18: PVR & PACE
B19: PVR (MTD) | C19: goal | D19: =IF('Jul 31'!$C$62=0,"-",'Jul 31'!$C$63/'Jul 31'!$C$62) -> - | E19: =IF(GoalPVRTotal="","-",GoalPVRTotal) -> -
B20: Selling days left | D20: =Dashboard!$BT$5 -> 0
B21: % to unit goal | D21: =IF(OR(GoalUnitsTotal="",GoalUnitsTotal=0),"-",'Jul 31'!$C$62/GoalUnitsTotal) -> -
B22: % to gross goal | D22: =IF(OR(GoalGrossTotal="",GoalGrossTotal=0),"-",'Jul 31'!$C$63/GoalGrossTotal) -> -
B36: ='Jul 1'!$C$46+'Jul 2'!$C$46+'Jul 3'!$C$46+'Jul 4'!$C$46+'Jul 5'!$C$46+'Jul 6'!$C$46+'Jul 7'!$C$46+'Jul 8'!$C$46+'Jul 9'!$C$46+'Jul 10'!$C$46+'Jul 11'!$C$46+'Jul 12'!$C$46+'Jul 13'!$C$46+'Jul 14'!$C$46+'Jul 15'!$C$46+'Jul 16'!$C$46+'Jul 17'!$C$46+'Jul 18'!$C$46+'Jul 19'!$C$46+'Jul 20'!$C$46+'Jul 21'!$C$46+'Jul 22'!$C$46+'Jul 23'!$C$46+'Jul 24'!$C$46+'Jul 25'!$C$46+'Jul 26'!$C$46+'Jul 27'!$C$46+'Jul 28'!$C$46+'Jul 29'!$C$46+'Jul 30'!$C$46+'Jul 31'!$C$46 -> 0
B37: ='Jul 1'!$E$46+'Jul 2'!$E$46+'Jul 3'!$E$46+'Jul 4'!$E$46+'Jul 5'!$E$46+'Jul 6'!$E$46+'Jul 7'!$E$46+'Jul 8'!$E$46+'Jul 9'!$E$46+'Jul 10'!$E$46+'Jul 11'!$E$46+'Jul 12'!$E$46+'Jul 13'!$E$46+'Jul 14'!$E$46+'Jul 15'!$E$46+'Jul 16'!$E$46+'Jul 17'!$E$46+'Jul 18'!$E$46+'Jul 19'!$E$46+'Jul 20'!$E$46+'Jul 21'!$E$46+'Jul 22'!$E$46+'Jul 23'!$E$46+'Jul 24'!$E$46+'Jul 25'!$E$46+'Jul 26'!$E$46+'Jul 27'!$E$46+'Jul 28'!$E$46+'Jul 29'!$E$46+'Jul 30'!$E$46+'Jul 31'!$E$46 -> 0
B38: ='Jul 1'!$C$49+'Jul 2'!$C$49+'Jul 3'!$C$49+'Jul 4'!$C$49+'Jul 5'!$C$49+'Jul 6'!$C$49+'Jul 7'!$C$49+'Jul 8'!$C$49+'Jul 9'!$C$49+'Jul 10'!$C$49+'Jul 11'!$C$49+'Jul 12'!$C$49+'Jul 13'!$C$49+'Jul 14'!$C$49+'Jul 15'!$C$49+'Jul 16'!$C$49+'Jul 17'!$C$49+'Jul 18'!$C$49+'Jul 19'!$C$49+'Jul 20'!$C$49+'Jul 21'!$C$49+'Jul 22'!$C$49+'Jul 23'!$C$49+'Jul 24'!$C$49+'Jul 25'!$C$49+'Jul 26'!$C$49+'Jul 27'!$C$49+'Jul 28'!$C$49+'Jul 29'!$C$49+'Jul 30'!$C$49+'Jul 31'!$C$49 -> 0
B39: ='Jul 1'!$E$49+'Jul 2'!$E$49+'Jul 3'!$E$49+'Jul 4'!$E$49+'Jul 5'!$E$49+'Jul 6'!$E$49+'Jul 7'!$E$49+'Jul 8'!$E$49+'Jul 9'!$E$49+'Jul 10'!$E$49+'Jul 11'!$E$49+'Jul 12'!$E$49+'Jul 13'!$E$49+'Jul 14'!$E$49+'Jul 15'!$E$49+'Jul 16'!$E$49+'Jul 17'!$E$49+'Jul 18'!$E$49+'Jul 19'!$E$49+'Jul 20'!$E$49+'Jul 21'!$E$49+'Jul 22'!$E$49+'Jul 23'!$E$49+'Jul 24'!$E$49+'Jul 25'!$E$49+'Jul 26'!$E$49+'Jul 27'!$E$49+'Jul 28'!$E$49+'Jul 29'!$E$49+'Jul 30'!$E$49+'Jul 31'!$E$49 -> 0

Sheet Deal Explorer
A1: DEAL EXPLORER | C1: DEAL EXPLORER — JULY 2026
C3: Every deal in the month, one filterable ledger · set criteria below, then filter the ✓ column (Data → Reapply)
B4: Salesperson (SP1 or SP2) | D4: Type | E4: Status | G4: Cert? | H4: Min Gross | I4: Search text
B6: ="Showing "&COUNTIF(A8:A1092,"✓")&" of "&COUNTA(C8:C1092)&" deals booked this month" -> Showing 1085 of 1085 deals booked this month
A7: ✓ | B7: Date | C7: Deal# | D7: Stock | E7: Customer | F7: Type | G7: SP1 | H7: SP2 | I7: Vehicle | J7: Gross | K7: Status | L7: Cert
A8: =IF(C8="","",IF(AND(OR($B$5="",G8=$B$5,H8=$B$5),OR($D$5="",F8=$D$5),OR($E$5="",K8=$E$5),OR($G$5="",L8=$G$5),OR($H$5="",N(J8)>=$H$5),OR($I$5="",ISNUMBER(SEARCH($I$5,C8&" "&D8&" "&E8&" "&I8)))),"✓","")) -> ✓ | B8: 46204 | C8: ='Jul 1'!$D$8 -> 0 | D8: ='Jul 1'!$B$8 -> 0 | E8: ='Jul 1'!$E$8 -> 0 | F8: ='Jul 1'!$A$8 -> 0 | G8: ='Jul 1'!$F$8 -> 0 | H8: ='Jul 1'!$G$8 -> 0 | I8: ='Jul 1'!$M$8 | J8: ='Jul 1'!$S$8 | K8: ='Jul 1'!$AG$8 -> 0 | L8: ='Jul 1'!$N$8 -> 0
A9: =IF(C9="","",IF(AND(OR($B$5="",G9=$B$5,H9=$B$5),OR($D$5="",F9=$D$5),OR($E$5="",K9=$E$5),OR($G$5="",L9=$G$5),OR($H$5="",N(J9)>=$H$5),OR($I$5="",ISNUMBER(SEARCH($I$5,C9&" "&D9&" "&E9&" "&I9)))),"✓","")) -> ✓ | B9: 46204 | C9: ='Jul 1'!$D$9 -> 0 | D9: ='Jul 1'!$B$9 -> 0 | E9: ='Jul 1'!$E$9 -> 0 | F9: ='Jul 1'!$A$9 -> 0 | G9: ='Jul 1'!$F$9 -> 0 | H9: ='Jul 1'!$G$9 -> 0 | I9: ='Jul 1'!$M$9 | J9: ='Jul 1'!$S$9 | K9: ='Jul 1'!$AG$9 -> 0 | L9: ='Jul 1'!$N$9 -> 0
A10: =IF(C10="","",IF(AND(OR($B$5="",G10=$B$5,H10=$B$5),OR($D$5="",F10=$D$5),OR($E$5="",K10=$E$5),OR($G$5="",L10=$G$5),OR($H$5="",N(J10)>=$H$5),OR($I$5="",ISNUMBER(SEARCH($I$5,C10&" "&D10&" "&E10&" "&I10)))),"✓","")) -> ✓ | B10: 46204 | C10: ='Jul 1'!$D$10 -> 0 | D10: ='Jul 1'!$B$10 -> 0 | E10: ='Jul 1'!$E$10 -> 0 | F10: ='Jul 1'!$A$10 -> 0 | G10: ='Jul 1'!$F$10 -> 0 | H10: ='Jul 1'!$G$10 -> 0 | I10: ='Jul 1'!$M$10 | J10: ='Jul 1'!$S$10 | K10: ='Jul 1'!$AG$10 -> 0 | L10: ='Jul 1'!$N$10 -> 0
A11: =IF(C11="","",IF(AND(OR($B$5="",G11=$B$5,H11=$B$5),OR($D$5="",F11=$D$5),OR($E$5="",K11=$E$5),OR($G$5="",L11=$G$5),OR($H$5="",N(J11)>=$H$5),OR($I$5="",ISNUMBER(SEARCH($I$5,C11&" "&D11&" "&E11&" "&I11)))),"✓","")) -> ✓ | B11: 46204 | C11: ='Jul 1'!$D$11 -> 0 | D11: ='Jul 1'!$B$11 -> 0 | E11: ='Jul 1'!$E$11 -> 0 | F11: ='Jul 1'!$A$11 -> 0 | G11: ='Jul 1'!$F$11 -> 0 | H11: ='Jul 1'!$G$11 -> 0 | I11: ='Jul 1'!$M$11 | J11: ='Jul 1'!$S$11 | K11: ='Jul 1'!$AG$11 -> 0 | L11: ='Jul 1'!$N$11 -> 0
A12: =IF(C12="","",IF(AND(OR($B$5="",G12=$B$5,H12=$B$5),OR($D$5="",F12=$D$5),OR($E$5="",K12=$E$5),OR($G$5="",L12=$G$5),OR($H$5="",N(J12)>=$H$5),OR($I$5="",ISNUMBER(SEARCH($I$5,C12&" "&D12&" "&E12&" "&I12)))),"✓","")) -> ✓ | B12: 46204 | C12: ='Jul 1'!$D$12 -> 0 | D12: ='Jul 1'!$B$12 -> 0 | E12: ='Jul 1'!$E$12 -> 0 | F12: ='Jul 1'!$A$12 -> 0 | G12: ='Jul 1'!$F$12 -> 0 | H12: ='Jul 1'!$G$12 -> 0 | I12: ='Jul 1'!$M$12 | J12: ='Jul 1'!$S$12 | K12: ='Jul 1'!$AG$12 -> 0 | L12: ='Jul 1'!$N$12 -> 0
A13: =IF(C13="","",IF(AND(OR($B$5="",G13=$B$5,H13=$B$5),OR($D$5="",F13=$D$5),OR($E$5="",K13=$E$5),OR($G$5="",L13=$G$5),OR($H$5="",N(J13)>=$H$5),OR($I$5="",ISNUMBER(SEARCH($I$5,C13&" "&D13&" "&E13&" "&I13)))),"✓","")) -> ✓ | B13: 46204 | C13: ='Jul 1'!$D$13 -> 0 | D13: ='Jul 1'!$B$13 -> 0 | E13: ='Jul 1'!$E$13 -> 0 | F13: ='Jul 1'!$A$13 -> 0 | G13: ='Jul 1'!$F$13 -> 0 | H13: ='Jul 1'!$G$13 -> 0 | I13: ='Jul 1'!$M$13 | J13: ='Jul 1'!$S$13 | K13: ='Jul 1'!$AG$13 -> 0 | L13: ='Jul 1'!$N$13 -> 0
A14: =IF(C14="","",IF(AND(OR($B$5="",G14=$B$5,H14=$B$5),OR($D$5="",F14=$D$5),OR($E$5="",K14=$E$5),OR($G$5="",L14=$G$5),OR($H$5="",N(J14)>=$H$5),OR($I$5="",ISNUMBER(SEARCH($I$5,C14&" "&D14&" "&E14&" "&I14)))),"✓","")) -> ✓ | B14: 46204 | C14: ='Jul 1'!$D$14 -> 0 | D14: ='Jul 1'!$B$14 -> 0 | E14: ='Jul 1'!$E$14 -> 0 | F14: ='Jul 1'!$A$14 -> 0 | G14: ='Jul 1'!$F$14 -> 0 | H14: ='Jul 1'!$G$14 -> 0 | I14: ='Jul 1'!$M$14 | J14: ='Jul 1'!$S$14 | K14: ='Jul 1'!$AG$14 -> 0 | L14: ='Jul 1'!$N$14 -> 0
A15: =IF(C15="","",IF(AND(OR($B$5="",G15=$B$5,H15=$B$5),OR($D$5="",F15=$D$5),OR($E$5="",K15=$E$5),OR($G$5="",L15=$G$5),OR($H$5="",N(J15)>=$H$5),OR($I$5="",ISNUMBER(SEARCH($I$5,C15&" "&D15&" "&E15&" "&I15)))),"✓","")) -> ✓ | B15: 46204 | C15: ='Jul 1'!$D$15 -> 0 | D15: ='Jul 1'!$B$15 -> 0 | E15: ='Jul 1'!$E$15 -> 0 | F15: ='Jul 1'!$A$15 -> 0 | G15: ='Jul 1'!$F$15 -> 0 | H15: ='Jul 1'!$G$15 -> 0 | I15: ='Jul 1'!$M$15 | J15: ='Jul 1'!$S$15 | K15: ='Jul 1'!$AG$15 -> 0 | L15: ='Jul 1'!$N$15 -> 0
A16: =IF(C16="","",IF(AND(OR($B$5="",G16=$B$5,H16=$B$5),OR($D$5="",F16=$D$5),OR($E$5="",K16=$E$5),OR($G$5="",L16=$G$5),OR($H$5="",N(J16)>=$H$5),OR($I$5="",ISNUMBER(SEARCH($I$5,C16&" "&D16&" "&E16&" "&I16)))),"✓","")) -> ✓ | B16: 46204 | C16: ='Jul 1'!$D$16 -> 0 | D16: ='Jul 1'!$B$16 -> 0 | E16: ='Jul 1'!$E$16 -> 0 | F16: ='Jul 1'!$A$16 -> 0 | G16: ='Jul 1'!$F$16 -> 0 | H16: ='Jul 1'!$G$16 -> 0 | I16: ='Jul 1'!$M$16 | J16: ='Jul 1'!$S$16 | K16: ='Jul 1'!$AG$16 -> 0 | L16: ='Jul 1'!$N$16 -> 0
A17: =IF(C17="","",IF(AND(OR($B$5="",G17=$B$5,H17=$B$5),OR($D$5="",F17=$D$5),OR($E$5="",K17=$E$5),OR($G$5="",L17=$G$5),OR($H$5="",N(J17)>=$H$5),OR($I$5="",ISNUMBER(SEARCH($I$5,C17&" "&D17&" "&E17&" "&I17)))),"✓","")) -> ✓ | B17: 46204 | C17: ='Jul 1'!$D$17 -> 0 | D17: ='Jul 1'!$B$17 -> 0 | E17: ='Jul 1'!$E$17 -> 0 | F17: ='Jul 1'!$A$17 -> 0 | G17: ='Jul 1'!$F$17 -> 0 | H17: ='Jul 1'!$G$17 -> 0 | I17: ='Jul 1'!$M$17 | J17: ='Jul 1'!$S$17 | K17: ='Jul 1'!$AG$17 -> 0 | L17: ='Jul 1'!$N$17 -> 0
A18: =IF(C18="","",IF(AND(OR($B$5="",G18=$B$5,H18=$B$5),OR($D$5="",F18=$D$5),OR($E$5="",K18=$E$5),OR($G$5="",L18=$G$5),OR($H$5="",N(J18)>=$H$5),OR($I$5="",ISNUMBER(SEARCH($I$5,C18&" "&D18&" "&E18&" "&I18)))),"✓","")) -> ✓ | B18: 46204 | C18: ='Jul 1'!$D$18 -> 0 | D18: ='Jul 1'!$B$18 -> 0 | E18: ='Jul 1'!$E$18 -> 0 | F18: ='Jul 1'!$A$18 -> 0 | G18: ='Jul 1'!$F$18 -> 0 | H18: ='Jul 1'!$G$18 -> 0 | I18: ='Jul 1'!$M$18 | J18: ='Jul 1'!$S$18 | K18: ='Jul 1'!$AG$18 -> 0 | L18: ='Jul 1'!$N$18 -> 0
A19: =IF(C19="","",IF(AND(OR($B$5="",G19=$B$5,H19=$B$5),OR($D$5="",F19=$D$5),OR($E$5="",K19=$E$5),OR($G$5="",L19=$G$5),OR($H$5="",N(J19)>=$H$5),OR($I$5="",ISNUMBER(SEARCH($I$5,C19&" "&D19&" "&E19&" "&I19)))),"✓","")) -> ✓ | B19: 46204 | C19: ='Jul 1'!$D$19 -> 0 | D19: ='Jul 1'!$B$19 -> 0 | E19: ='Jul 1'!$E$19 -> 0 | F19: ='Jul 1'!$A$19 -> 0 | G19: ='Jul 1'!$F$19 -> 0 | H19: ='Jul 1'!$G$19 -> 0 | I19: ='Jul 1'!$M$19 | J19: ='Jul 1'!$S$19 | K19: ='Jul 1'!$AG$19 -> 0 | L19: ='Jul 1'!$N$19 -> 0
A20: =IF(C20="","",IF(AND(OR($B$5="",G20=$B$5,H20=$B$5),OR($D$5="",F20=$D$5),OR($E$5="",K20=$E$5),OR($G$5="",L20=$G$5),OR($H$5="",N(J20)>=$H$5),OR($I$5="",ISNUMBER(SEARCH($I$5,C20&" "&D20&" "&E20&" "&I20)))),"✓","")) -> ✓ | B20: 46204 | C20: ='Jul 1'!$D$20 -> 0 | D20: ='Jul 1'!$B$20 -> 0 | E20: ='Jul 1'!$E$20 -> 0 | F20: ='Jul 1'!$A$20 -> 0 | G20: ='Jul 1'!$F$20 -> 0 | H20: ='Jul 1'!$G$20 -> 0 | I20: ='Jul 1'!$M$20 | J20: ='Jul 1'!$S$20 | K20: ='Jul 1'!$AG$20 -> 0 | L20: ='Jul 1'!$N$20 -> 0
A21: =IF(C21="","",IF(AND(OR($B$5="",G21=$B$5,H21=$B$5),OR($D$5="",F21=$D$5),OR($E$5="",K21=$E$5),OR($G$5="",L21=$G$5),OR($H$5="",N(J21)>=$H$5),OR($I$5="",ISNUMBER(SEARCH($I$5,C21&" "&D21&" "&E21&" "&I21)))),"✓","")) -> ✓ | B21: 46204 | C21: ='Jul 1'!$D$21 -> 0 | D21: ='Jul 1'!$B$21 -> 0 | E21: ='Jul 1'!$E$21 -> 0 | F21: ='Jul 1'!$A$21 -> 0 | G21: ='Jul 1'!$F$21 -> 0 | H21: ='Jul 1'!$G$21 -> 0 | I21: ='Jul 1'!$M$21 | J21: ='Jul 1'!$S$21 | K21: ='Jul 1'!$AG$21 -> 0 | L21: ='Jul 1'!$N$21 -> 0
A22: =IF(C22="","",IF(AND(OR($B$5="",G22=$B$5,H22=$B$5),OR($D$5="",F22=$D$5),OR($E$5="",K22=$E$5),OR($G$5="",L22=$G$5),OR($H$5="",N(J22)>=$H$5),OR($I$5="",ISNUMBER(SEARCH($I$5,C22&" "&D22&" "&E22&" "&I22)))),"✓","")) -> ✓ | B22: 46204 | C22: ='Jul 1'!$D$22 -> 0 | D22: ='Jul 1'!$B$22 -> 0 | E22: ='Jul 1'!$E$22 -> 0 | F22: ='Jul 1'!$A$22 -> 0 | G22: ='Jul 1'!$F$22 -> 0 | H22: ='Jul 1'!$G$22 -> 0 | I22: ='Jul 1'!$M$22 | J22: ='Jul 1'!$S$22 | K22: ='Jul 1'!$AG$22 -> 0 | L22: ='Jul 1'!$N$22 -> 0
A23: =IF(C23="","",IF(AND(OR($B$5="",G23=$B$5,H23=$B$5),OR($D$5="",F23=$D$5),OR($E$5="",K23=$E$5),OR($G$5="",L23=$G$5),OR($H$5="",N(J23)>=$H$5),OR($I$5="",ISNUMBER(SEARCH($I$5,C23&" "&D23&" "&E23&" "&I23)))),"✓","")) -> ✓ | B23: 46204 | C23: ='Jul 1'!$D$23 -> 0 | D23: ='Jul 1'!$B$23 -> 0 | E23: ='Jul 1'!$E$23 -> 0 | F23: ='Jul 1'!$A$23 -> 0 | G23: ='Jul 1'!$F$23 -> 0 | H23: ='Jul 1'!$G$23 -> 0 | I23: ='Jul 1'!$M$23 | J23: ='Jul 1'!$S$23 | K23: ='Jul 1'!$AG$23 -> 0 | L23: ='Jul 1'!$N$23 -> 0
A24: =IF(C24="","",IF(AND(OR($B$5="",G24=$B$5,H24=$B$5),OR($D$5="",F24=$D$5),OR($E$5="",K24=$E$5),OR($G$5="",L24=$G$5),OR($H$5="",N(J24)>=$H$5),OR($I$5="",ISNUMBER(SEARCH($I$5,C24&" "&D24&" "&E24&" "&I24)))),"✓","")) -> ✓ | B24: 46204 | C24: ='Jul 1'!$D$24 -> 0 | D24: ='Jul 1'!$B$24 -> 0 | E24: ='Jul 1'!$E$24 -> 0 | F24: ='Jul 1'!$A$24 -> 0 | G24: ='Jul 1'!$F$24 -> 0 | H24: ='Jul 1'!$G$24 -> 0 | I24: ='Jul 1'!$M$24 | J24: ='Jul 1'!$S$24 | K24: ='Jul 1'!$AG$24 -> 0 | L24: ='Jul 1'!$N$24 -> 0
A25: =IF(C25="","",IF(AND(OR($B$5="",G25=$B$5,H25=$B$5),OR($D$5="",F25=$D$5),OR($E$5="",K25=$E$5),OR($G$5="",L25=$G$5),OR($H$5="",N(J25)>=$H$5),OR($I$5="",ISNUMBER(SEARCH($I$5,C25&" "&D25&" "&E25&" "&I25)))),"✓","")) -> ✓ | B25: 46204 | C25: ='Jul 1'!$D$25 -> 0 | D25: ='Jul 1'!$B$25 -> 0 | E25: ='Jul 1'!$E$25 -> 0 | F25: ='Jul 1'!$A$25 -> 0 | G25: ='Jul 1'!$F$25 -> 0 | H25: ='Jul 1'!$G$25 -> 0 | I25: ='Jul 1'!$M$25 | J25: ='Jul 1'!$S$25 | K25: ='Jul 1'!$AG$25 -> 0 | L25: ='Jul 1'!$N$25 -> 0
A26: =IF(C26="","",IF(AND(OR($B$5="",G26=$B$5,H26=$B$5),OR($D$5="",F26=$D$5),OR($E$5="",K26=$E$5),OR($G$5="",L26=$G$5),OR($H$5="",N(J26)>=$H$5),OR($I$5="",ISNUMBER(SEARCH($I$5,C26&" "&D26&" "&E26&" "&I26)))),"✓","")) -> ✓ | B26: 46204 | C26: ='Jul 1'!$D$26 -> 0 | D26: ='Jul 1'!$B$26 -> 0 | E26: ='Jul 1'!$E$26 -> 0 | F26: ='Jul 1'!$A$26 -> 0 | G26: ='Jul 1'!$F$26 -> 0 | H26: ='Jul 1'!$G$26 -> 0 | I26: ='Jul 1'!$M$26 | J26: ='Jul 1'!$S$26 | K26: ='Jul 1'!$AG$26 -> 0 | L26: ='Jul 1'!$N$26 -> 0
A27: =IF(C27="","",IF(AND(OR($B$5="",G27=$B$5,H27=$B$5),OR($D$5="",F27=$D$5),OR($E$5="",K27=$E$5),OR($G$5="",L27=$G$5),OR($H$5="",N(J27)>=$H$5),OR($I$5="",ISNUMBER(SEARCH($I$5,C27&" "&D27&" "&E27&" "&I27)))),"✓","")) -> ✓ | B27: 46204 | C27: ='Jul 1'!$D$27 -> 0 | D27: ='Jul 1'!$B$27 -> 0 | E27: ='Jul 1'!$E$27 -> 0 | F27: ='Jul 1'!$A$27 -> 0 | G27: ='Jul 1'!$F$27 -> 0 | H27: ='Jul 1'!$G$27 -> 0 | I27: ='Jul 1'!$M$27 | J27: ='Jul 1'!$S$27 | K27: ='Jul 1'!$AG$27 -> 0 | L27: ='Jul 1'!$N$27 -> 0
A28: =IF(C28="","",IF(AND(OR($B$5="",G28=$B$5,H28=$B$5),OR($D$5="",F28=$D$5),OR($E$5="",K28=$E$5),OR($G$5="",L28=$G$5),OR($H$5="",N(J28)>=$H$5),OR($I$5="",ISNUMBER(SEARCH($I$5,C28&" "&D28&" "&E28&" "&I28)))),"✓","")) -> ✓ | B28: 46204 | C28: ='Jul 1'!$D$28 -> 0 | D28: ='Jul 1'!$B$28 -> 0 | E28: ='Jul 1'!$E$28 -> 0 | F28: ='Jul 1'!$A$28 -> 0 | G28: ='Jul 1'!$F$28 -> 0 | H28: ='Jul 1'!$G$28 -> 0 | I28: ='Jul 1'!$M$28 | J28: ='Jul 1'!$S$28 | K28: ='Jul 1'!$AG$28 -> 0 | L28: ='Jul 1'!$N$28 -> 0
A29: =IF(C29="","",IF(AND(OR($B$5="",G29=$B$5,H29=$B$5),OR($D$5="",F29=$D$5),OR($E$5="",K29=$E$5),OR($G$5="",L29=$G$5),OR($H$5="",N(J29)>=$H$5),OR($I$5="",ISNUMBER(SEARCH($I$5,C29&" "&D29&" "&E29&" "&I29)))),"✓","")) -> ✓ | B29: 46204 | C29: ='Jul 1'!$D$29 -> 0 | D29: ='Jul 1'!$B$29 -> 0 | E29: ='Jul 1'!$E$29 -> 0 | F29: ='Jul 1'!$A$29 -> 0 | G29: ='Jul 1'!$F$29 -> 0 | H29: ='Jul 1'!$G$29 -> 0 | I29: ='Jul 1'!$M$29 | J29: ='Jul 1'!$S$29 | K29: ='Jul 1'!$AG$29 -> 0 | L29: ='Jul 1'!$N$29 -> 0
A30: =IF(C30="","",IF(AND(OR($B$5="",G30=$B$5,H30=$B$5),OR($D$5="",F30=$D$5),OR($E$5="",K30=$E$5),OR($G$5="",L30=$G$5),OR($H$5="",N(J30)>=$H$5),OR($I$5="",ISNUMBER(SEARCH($I$5,C30&" "&D30&" "&E30&" "&I30)))),"✓","")) -> ✓ | B30: 46204 | C30: ='Jul 1'!$D$30 -> 0 | D30: ='Jul 1'!$B$30 -> 0 | E30: ='Jul 1'!$E$30 -> 0 | F30: ='Jul 1'!$A$30 -> 0 | G30: ='Jul 1'!$F$30 -> 0 | H30: ='Jul 1'!$G$30 -> 0 | I30: ='Jul 1'!$M$30 | J30: ='Jul 1'!$S$30 | K30: ='Jul 1'!$AG$30 -> 0 | L30: ='Jul 1'!$N$30 -> 0
A31: =IF(C31="","",IF(AND(OR($B$5="",G31=$B$5,H31=$B$5),OR($D$5="",F31=$D$5),OR($E$5="",K31=$E$5),OR($G$5="",L31=$G$5),OR($H$5="",N(J31)>=$H$5),OR($I$5="",ISNUMBER(SEARCH($I$5,C31&" "&D31&" "&E31&" "&I31)))),"✓","")) -> ✓ | B31: 46204 | C31: ='Jul 1'!$D$31 -> 0 | D31: ='Jul 1'!$B$31 -> 0 | E31: ='Jul 1'!$E$31 -> 0 | F31: ='Jul 1'!$A$31 -> 0 | G31: ='Jul 1'!$F$31 -> 0 | H31: ='Jul 1'!$G$31 -> 0 | I31: ='Jul 1'!$M$31 | J31: ='Jul 1'!$S$31 | K31: ='Jul 1'!$AG$31 -> 0 | L31: ='Jul 1'!$N$31 -> 0
A32: =IF(C32="","",IF(AND(OR($B$5="",G32=$B$5,H32=$B$5),OR($D$5="",F32=$D$5),OR($E$5="",K32=$E$5),OR($G$5="",L32=$G$5),OR($H$5="",N(J32)>=$H$5),OR($I$5="",ISNUMBER(SEARCH($I$5,C32&" "&D32&" "&E32&" "&I32)))),"✓","")) -> ✓ | B32: 46204 | C32: ='Jul 1'!$D$32 -> 0 | D32: ='Jul 1'!$B$32 -> 0 | E32: ='Jul 1'!$E$32 -> 0 | F32: ='Jul 1'!$A$32 -> 0 | G32: ='Jul 1'!$F$32 -> 0 | H32: ='Jul 1'!$G$32 -> 0 | I32: ='Jul 1'!$M$32 | J32: ='Jul 1'!$S$32 | K32: ='Jul 1'!$AG$32 -> 0 | L32: ='Jul 1'!$N$32 -> 0
A33: =IF(C33="","",IF(AND(OR($B$5="",G33=$B$5,H33=$B$5),OR($D$5="",F33=$D$5),OR($E$5="",K33=$E$5),OR($G$5="",L33=$G$5),OR($H$5="",N(J33)>=$H$5),OR($I$5="",ISNUMBER(SEARCH($I$5,C33&" "&D33&" "&E33&" "&I33)))),"✓","")) -> ✓ | B33: 46204 | C33: ='Jul 1'!$D$33 -> 0 | D33: ='Jul 1'!$B$33 -> 0 | E33: ='Jul 1'!$E$33 -> 0 | F33: ='Jul 1'!$A$33 -> 0 | G33: ='Jul 1'!$F$33 -> 0 | H33: ='Jul 1'!$G$33 -> 0 | I33: ='Jul 1'!$M$33 | J33: ='Jul 1'!$S$33 | K33: ='Jul 1'!$AG$33 -> 0 | L33: ='Jul 1'!$N$33 -> 0
A34: =IF(C34="","",IF(AND(OR($B$5="",G34=$B$5,H34=$B$5),OR($D$5="",F34=$D$5),OR($E$5="",K34=$E$5),OR($G$5="",L34=$G$5),OR($H$5="",N(J34)>=$H$5),OR($I$5="",ISNUMBER(SEARCH($I$5,C34&" "&D34&" "&E34&" "&I34)))),"✓","")) -> ✓ | B34: 46204 | C34: ='Jul 1'!$D$34 -> 0 | D34: ='Jul 1'!$B$34 -> 0 | E34: ='Jul 1'!$E$34 -> 0 | F34: ='Jul 1'!$A$34 -> 0 | G34: ='Jul 1'!$F$34 -> 0 | H34: ='Jul 1'!$G$34 -> 0 | I34: ='Jul 1'!$M$34 | J34: ='Jul 1'!$S$34 | K34: ='Jul 1'!$AG$34 -> 0 | L34: ='Jul 1'!$N$34 -> 0
A35: =IF(C35="","",IF(AND(OR($B$5="",G35=$B$5,H35=$B$5),OR($D$5="",F35=$D$5),OR($E$5="",K35=$E$5),OR($G$5="",L35=$G$5),OR($H$5="",N(J35)>=$H$5),OR($I$5="",ISNUMBER(SEARCH($I$5,C35&" "&D35&" "&E35&" "&I35)))),"✓","")) -> ✓ | B35: 46204 | C35: ='Jul 1'!$D$35 -> 0 | D35: ='Jul 1'!$B$35 -> 0 | E35: ='Jul 1'!$E$35 -> 0 | F35: ='Jul 1'!$A$35 -> 0 | G35: ='Jul 1'!$F$35 -> 0 | H35: ='Jul 1'!$G$35 -> 0 | I35: ='Jul 1'!$M$35 | J35: ='Jul 1'!$S$35 | K35: ='Jul 1'!$AG$35 -> 0 | L35: ='Jul 1'!$N$35 -> 0
A36: =IF(C36="","",IF(AND(OR($B$5="",G36=$B$5,H36=$B$5),OR($D$5="",F36=$D$5),OR($E$5="",K36=$E$5),OR($G$5="",L36=$G$5),OR($H$5="",N(J36)>=$H$5),OR($I$5="",ISNUMBER(SEARCH($I$5,C36&" "&D36&" "&E36&" "&I36)))),"✓","")) -> ✓ | B36: 46204 | C36: ='Jul 1'!$D$36 -> 0 | D36: ='Jul 1'!$B$36 -> 0 | E36: ='Jul 1'!$E$36 -> 0 | F36: ='Jul 1'!$A$36 -> 0 | G36: ='Jul 1'!$F$36 -> 0 | H36: ='Jul 1'!$G$36 -> 0 | I36: ='Jul 1'!$M$36 | J36: ='Jul 1'!$S$36 | K36: ='Jul 1'!$AG$36 -> 0 | L36: ='Jul 1'!$N$36 -> 0
A37: =IF(C37="","",IF(AND(OR($B$5="",G37=$B$5,H37=$B$5),OR($D$5="",F37=$D$5),OR($E$5="",K37=$E$5),OR($G$5="",L37=$G$5),OR($H$5="",N(J37)>=$H$5),OR($I$5="",ISNUMBER(SEARCH($I$5,C37&" "&D37&" "&E37&" "&I37)))),"✓","")) -> ✓ | B37: 46204 | C37: ='Jul 1'!$D$37 -> 0 | D37: ='Jul 1'!$B$37 -> 0 | E37: ='Jul 1'!$E$37 -> 0 | F37: ='Jul 1'!$A$37 -> 0 | G37: ='Jul 1'!$F$37 -> 0 | H37: ='Jul 1'!$G$37 -> 0 | I37: ='Jul 1'!$M$37 | J37: ='Jul 1'!$S$37 | K37: ='Jul 1'!$AG$37 -> 0 | L37: ='Jul 1'!$N$37 -> 0
A38: =IF(C38="","",IF(AND(OR($B$5="",G38=$B$5,H38=$B$5),OR($D$5="",F38=$D$5),OR($E$5="",K38=$E$5),OR($G$5="",L38=$G$5),OR($H$5="",N(J38)>=$H$5),OR($I$5="",ISNUMBER(SEARCH($I$5,C38&" "&D38&" "&E38&" "&I38)))),"✓","")) -> ✓ | B38: 46204 | C38: ='Jul 1'!$D$38 -> 0 | D38: ='Jul 1'!$B$38 -> 0 | E38: ='Jul 1'!$E$38 -> 0 | F38: ='Jul 1'!$A$38 -> 0 | G38: ='Jul 1'!$F$38 -> 0 | H38: ='Jul 1'!$G$38 -> 0 | I38: ='Jul 1'!$M$38 | J38: ='Jul 1'!$S$38 | K38: ='Jul 1'!$AG$38 -> 0 | L38: ='Jul 1'!$N$38 -> 0
A39: =IF(C39="","",IF(AND(OR($B$5="",G39=$B$5,H39=$B$5),OR($D$5="",F39=$D$5),OR($E$5="",K39=$E$5),OR($G$5="",L39=$G$5),OR($H$5="",N(J39)>=$H$5),OR($I$5="",ISNUMBER(SEARCH($I$5,C39&" "&D39&" "&E39&" "&I39)))),"✓","")) -> ✓ | B39: 46204 | C39: ='Jul 1'!$D$39 -> 0 | D39: ='Jul 1'!$B$39 -> 0 | E39: ='Jul 1'!$E$39 -> 0 | F39: ='Jul 1'!$A$39 -> 0 | G39: ='Jul 1'!$F$39 -> 0 | H39: ='Jul 1'!$G$39 -> 0 | I39: ='Jul 1'!$M$39 | J39: ='Jul 1'!$S$39 | K39: ='Jul 1'!$AG$39 -> 0 | L39: ='Jul 1'!$N$39 -> 0
A40: =IF(C40="","",IF(AND(OR($B$5="",G40=$B$5,H40=$B$5),OR($D$5="",F40=$D$5),OR($E$5="",K40=$E$5),OR($G$5="",L40=$G$5),OR($H$5="",N(J40)>=$H$5),OR($I$5="",ISNUMBER(SEARCH($I$5,C40&" "&D40&" "&E40&" "&I40)))),"✓","")) -> ✓ | B40: 46204 | C40: ='Jul 1'!$D$40 -> 0 | D40: ='Jul 1'!$B$40 -> 0 | E40: ='Jul 1'!$E$40 -> 0 | F40: ='Jul 1'!$A$40 -> 0 | G40: ='Jul 1'!$F$40 -> 0 | H40: ='Jul 1'!$G$40 -> 0 | I40: ='Jul 1'!$M$40 | J40: ='Jul 1'!$S$40 | K40: ='Jul 1'!$AG$40 -> 0 | L40: ='Jul 1'!$N$40 -> 0
A41: =IF(C41="","",IF(AND(OR($B$5="",G41=$B$5,H41=$B$5),OR($D$5="",F41=$D$5),OR($E$5="",K41=$E$5),OR($G$5="",L41=$G$5),OR($H$5="",N(J41)>=$H$5),OR($I$5="",ISNUMBER(SEARCH($I$5,C41&" "&D41&" "&E41&" "&I41)))),"✓","")) -> ✓ | B41: 46204 | C41: ='Jul 1'!$D$41 -> 0 | D41: ='Jul 1'!$B$41 -> 0 | E41: ='Jul 1'!$E$41 -> 0 | F41: ='Jul 1'!$A$41 -> 0 | G41: ='Jul 1'!$F$41 -> 0 | H41: ='Jul 1'!$G$41 -> 0 | I41: ='Jul 1'!$M$41 | J41: ='Jul 1'!$S$41 | K41: ='Jul 1'!$AG$41 -> 0 | L41: ='Jul 1'!$N$41 -> 0
A42: =IF(C42="","",IF(AND(OR($B$5="",G42=$B$5,H42=$B$5),OR($D$5="",F42=$D$5),OR($E$5="",K42=$E$5),OR($G$5="",L42=$G$5),OR($H$5="",N(J42)>=$H$5),OR($I$5="",ISNUMBER(SEARCH($I$5,C42&" "&D42&" "&E42&" "&I42)))),"✓","")) -> ✓ | B42: 46204 | C42: ='Jul 1'!$D$42 -> 0 | D42: ='Jul 1'!$B$42 -> 0 | E42: ='Jul 1'!$E$42 -> 0 | F42: ='Jul 1'!$A$42 -> 0 | G42: ='Jul 1'!$F$42 -> 0 | H42: ='Jul 1'!$G$42 -> 0 | I42: ='Jul 1'!$M$42 | J42: ='Jul 1'!$S$42 | K42: ='Jul 1'!$AG$42 -> 0 | L42: ='Jul 1'!$N$42 -> 0
...

Sheet Commissions
A1: COMMISSIONS | D1: COMMISSIONS — JULY 2026 | N1: =" as of "&TEXT(TODAY(),"ddd mmm d") -> as of Sat Aug 1
D3: Retro pay — final monthly units set the tier for every deal · qualifying = delivered · split = ½ flat · product $ to SP1 · draws entered by payroll | T3: COMMISSIONS AGG
T4: FEDY ALI | U4: =SUMPRODUCT((('Jul 1'!$F$8:$F$42=$T4)*(0.5+0.5*('Jul 1'!$G$8:$G$42=""))+('Jul 1'!$G$8:$G$42=$T4)*0.5)*('Jul 1'!$AG$8:$AG$42="Delivered")) -> 0 | V4: =SUMPRODUCT((('Jul 2'!$F$8:$F$42=$T4)*(0.5+0.5*('Jul 2'!$G$8:$G$42=""))+('Jul 2'!$G$8:$G$42=$T4)*0.5)*('Jul 2'!$AG$8:$AG$42="Delivered")) -> 0 | W4: =SUMPRODUCT((('Jul 3'!$F$8:$F$42=$T4)*(0.5+0.5*('Jul 3'!$G$8:$G$42=""))+('Jul 3'!$G$8:$G$42=$T4)*0.5)*('Jul 3'!$AG$8:$AG$42="Delivered")) -> 0 | X4: =SUMPRODUCT((('Jul 4'!$F$8:$F$42=$T4)*(0.5+0.5*('Jul 4'!$G$8:$G$42=""))+('Jul 4'!$G$8:$G$42=$T4)*0.5)*('Jul 4'!$AG$8:$AG$42="Delivered")) -> 0 | Y4: =SUMPRODUCT((('Jul 5'!$F$8:$F$42=$T4)*(0.5+0.5*('Jul 5'!$G$8:$G$42=""))+('Jul 5'!$G$8:$G$42=$T4)*0.5)*('Jul 5'!$AG$8:$AG$42="Delivered")) -> 0 | Z4: =SUMPRODUCT((('Jul 6'!$F$8:$F$42=$T4)*(0.5+0.5*('Jul 6'!$G$8:$G$42=""))+('Jul 6'!$G$8:$G$42=$T4)*0.5)*('Jul 6'!$AG$8:$AG$42="Delivered")) -> 0 | AA4: =SUMPRODUCT((('Jul 7'!$F$8:$F$42=$T4)*(0.5+0.5*('Jul 7'!$G$8:$G$42=""))+('Jul 7'!$G$8:$G$42=$T4)*0.5)*('Jul 7'!$AG$8:$AG$42="Delivered")) -> 0 | AB4: =SUMPRODUCT((('Jul 8'!$F$8:$F$42=$T4)*(0.5+0.5*('Jul 8'!$G$8:$G$42=""))+('Jul 8'!$G$8:$G$42=$T4)*0.5)*('Jul 8'!$AG$8:$AG$42="Delivered")) -> 0 | AC4: =SUMPRODUCT((('Jul 9'!$F$8:$F$42=$T4)*(0.5+0.5*('Jul 9'!$G$8:$G$42=""))+('Jul 9'!$G$8:$G$42=$T4)*0.5)*('Jul 9'!$AG$8:$AG$42="Delivered")) -> 0 | AD4: =SUMPRODUCT((('Jul 10'!$F$8:$F$42=$T4)*(0.5+0.5*('Jul 10'!$G$8:$G$42=""))+('Jul 10'!$G$8:$G$42=$T4)*0.5)*('Jul 10'!$AG$8:$AG$42="Delivered")) -> 0 | AE4: =SUMPRODUCT((('Jul 11'!$F$8:$F$42=$T4)*(0.5+0.5*('Jul 11'!$G$8:$G$42=""))+('Jul 11'!$G$8:$G$42=$T4)*0.5)*('Jul 11'!$AG$8:$AG$42="Delivered")) -> 0 | AF4: =SUMPRODUCT((('Jul 12'!$F$8:$F$42=$T4)*(0.5+0.5*('Jul 12'!$G$8:$G$42=""))+('Jul 12'!$G$8:$G$42=$T4)*0.5)*('Jul 12'!$AG$8:$AG$42="Delivered")) -> 0 | AG4: =SUMPRODUCT((('Jul 13'!$F$8:$F$42=$T4)*(0.5+0.5*('Jul 13'!$G$8:$G$42=""))+('Jul 13'!$G$8:$G$42=$T4)*0.5)*('Jul 13'!$AG$8:$AG$42="Delivered")) -> 0 | AH4: =SUMPRODUCT((('Jul 14'!$F$8:$F$42=$T4)*(0.5+0.5*('Jul 14'!$G$8:$G$42=""))+('Jul 14'!$G$8:$G$42=$T4)*0.5)*('Jul 14'!$AG$8:$AG$42="Delivered")) -> 0 | AI4: =SUMPRODUCT((('Jul 15'!$F$8:$F$42=$T4)*(0.5+0.5*('Jul 15'!$G$8:$G$42=""))+('Jul 15'!$G$8:$G$42=$T4)*0.5)*('Jul 15'!$AG$8:$AG$42="Delivered")) -> 0 | AJ4: =SUMPRODUCT((('Jul 16'!$F$8:$F$42=$T4)*(0.5+0.5*('Jul 16'!$G$8:$G$42=""))+('Jul 16'!$G$8:$G$42=$T4)*0.5)*('Jul 16'!$AG$8:$AG$42="Delivered")) -> 0 | AK4: =SUMPRODUCT((('Jul 17'!$F$8:$F$42=$T4)*(0.5+0.5*('Jul 17'!$G$8:$G$42=""))+('Jul 17'!$G$8:$G$42=$T4)*0.5)*('Jul 17'!$AG$8:$AG$42="Delivered")) -> 0 | AL4: =SUMPRODUCT((('Jul 18'!$F$8:$F$42=$T4)*(0.5+0.5*('Jul 18'!$G$8:$G$42=""))+('Jul 18'!$G$8:$G$42=$T4)*0.5)*('Jul 18'!$AG$8:$AG$42="Delivered")) -> 0 | AM4: =SUMPRODUCT((('Jul 19'!$F$8:$F$42=$T4)*(0.5+0.5*('Jul 19'!$G$8:$G$42=""))+('Jul 19'!$G$8:$G$42=$T4)*0.5)*('Jul 19'!$AG$8:$AG$42="Delivered")) -> 0 | AN4: =SUMPRODUCT((('Jul 20'!$F$8:$F$42=$T4)*(0.5+0.5*('Jul 20'!$G$8:$G$42=""))+('Jul 20'!$G$8:$G$42=$T4)*0.5)*('Jul 20'!$AG$8:$AG$42="Delivered")) -> 0 | AO4: =SUMPRODUCT((('Jul 21'!$F$8:$F$42=$T4)*(0.5+0.5*('Jul 21'!$G$8:$G$42=""))+('Jul 21'!$G$8:$G$42=$T4)*0.5)*('Jul 21'!$AG$8:$AG$42="Delivered")) -> 0 | AP4: =SUMPRODUCT((('Jul 22'!$F$8:$F$42=$T4)*(0.5+0.5*('Jul 22'!$G$8:$G$42=""))+('Jul 22'!$G$8:$G$42=$T4)*0.5)*('Jul 22'!$AG$8:$AG$42="Delivered")) -> 0 | AQ4: =SUMPRODUCT((('Jul 23'!$F$8:$F$42=$T4)*(0.5+0.5*('Jul 23'!$G$8:$G$42=""))+('Jul 23'!$G$8:$G$42=$T4)*0.5)*('Jul 23'!$AG$8:$AG$42="Delivered")) -> 0 | AR4: =SUMPRODUCT((('Jul 24'!$F$8:$F$42=$T4)*(0.5+0.5*('Jul 24'!$G$8:$G$42=""))+('Jul 24'!$G$8:$G$42=$T4)*0.5)*('Jul 24'!$AG$8:$AG$42="Delivered")) -> 0 | AS4: =SUMPRODUCT((('Jul 25'!$F$8:$F$42=$T4)*(0.5+0.5*('Jul 25'!$G$8:$G$42=""))+('Jul 25'!$G$8:$G$42=$T4)*0.5)*('Jul 25'!$AG$8:$AG$42="Delivered")) -> 0 | AT4: =SUMPRODUCT((('Jul 26'!$F$8:$F$42=$T4)*(0.5+0.5*('Jul 26'!$G$8:$G$42=""))+('Jul 26'!$G$8:$G$42=$T4)*0.5)*('Jul 26'!$AG$8:$AG$42="Delivered")) -> 0 | AU4: =SUMPRODUCT((('Jul 27'!$F$8:$F$42=$T4)*(0.5+0.5*('Jul 27'!$G$8:$G$42=""))+('Jul 27'!$G$8:$G$42=$T4)*0.5)*('Jul 27'!$AG$8:$AG$42="Delivered")) -> 0 | AV4: =SUMPRODUCT((('Jul 28'!$F$8:$F$42=$T4)*(0.5+0.5*('Jul 28'!$G$8:$G$42=""))+('Jul 28'!$G$8:$G$42=$T4)*0.5)*('Jul 28'!$AG$8:$AG$42="Delivered")) -> 0 | AW4: =SUMPRODUCT((('Jul 29'!$F$8:$F$42=$T4)*(0.5+0.5*('Jul 29'!$G$8:$G$42=""))+('Jul 29'!$G$8:$G$42=$T4)*0.5)*('Jul 29'!$AG$8:$AG$42="Delivered")) -> 0 | AX4: =SUMPRODUCT((('Jul 30'!$F$8:$F$42=$T4)*(0.5+0.5*('Jul 30'!$G$8:$G$42=""))+('Jul 30'!$G$8:$G$42=$T4)*0.5)*('Jul 30'!$AG$8:$AG$42="Delivered")) -> 0 | AY4: =SUMPRODUCT((('Jul 31'!$F$8:$F$42=$T4)*(0.5+0.5*('Jul 31'!$G$8:$G$42=""))+('Jul 31'!$G$8:$G$42=$T4)*0.5)*('Jul 31'!$AG$8:$AG$42="Delivered")) -> 0 | BA4: =SUM(U4:AD4) -> 0 | BB4: =MATCH(BD4,'Pay Plan'!$C$6:$C$12,1) -> 1 | BC4: =SUMPRODUCT(('Jul 1'!$F$8:$F$42=$T4)*('Jul 1'!$AG$8:$AG$42="Delivered")*(('Jul 1'!$AM$8:$AM$42="Y")+('Jul 1'!$AN$8:$AN$42="Y")+('Jul 1'!$AO$8:$AO$42="Y")))+SUMPRODUCT(('Jul 2'!$F$8:$F$42=$T4)*('Jul 2'!$AG$8:$AG$42="Delivered")*(('Jul 2'!$AM$8:$AM$42="Y")+('Jul 2'!$AN$8:$AN$42="Y")+('Jul 2'!$AO$8:$AO$42="Y")))+SUMPRODUCT(('Jul 3'!$F$8:$F$42=$T4)*('Jul 3'!$AG$8:$AG$42="Delivered")*(('Jul 3'!$AM$8:$AM$42="Y")+('Jul 3'!$AN$8:$AN$42="Y")+('Jul 3'!$AO$8:$AO$42="Y")))+SUMPRODUCT(('Jul 4'!$F$8:$F$42=$T4)*('Jul 4'!$AG$8:$AG$42="Delivered")*(('Jul 4'!$AM$8:$AM$42="Y")+('Jul 4'!$AN$8:$AN$42="Y")+('Jul 4'!$AO$8:$AO$42="Y")))+SUMPRODUCT(('Jul 5'!$F$8:$F$42=$T4)*('Jul 5'!$AG$8:$AG$42="Delivered")*(('Jul 5'!$AM$8:$AM$42="Y")+('Jul 5'!$AN$8:$AN$42="Y")+('Jul 5'!$AO$8:$AO$42="Y")))+SUMPRODUCT(('Jul 6'!$F$8:$F$42=$T4)*('Jul 6'!$AG$8:$AG$42="Delivered")*(('Jul 6'!$AM$8:$AM$42="Y")+('Jul 6'!$AN$8:$AN$42="Y")+('Jul 6'!$AO$8:$AO$42="Y")))+SUMPRODUCT(('Jul 7'!$F$8:$F$42=$T4)*('Jul 7'!$AG$8:$AG$42="Delivered")*(('Jul 7'!$AM$8:$AM$42="Y")+('Jul 7'!$AN$8:$AN$42="Y")+('Jul 7'!$AO$8:$AO$42="Y")))+SUMPRODUCT(('Jul 8'!$F$8:$F$42=$T4)*('Jul 8'!$AG$8:$AG$42="Delivered")*(('Jul 8'!$AM$8:$AM$42="Y")+('Jul 8'!$AN$8:$AN$42="Y")+('Jul 8'!$AO$8:$AO$42="Y")))+SUMPRODUCT(('Jul 9'!$F$8:$F$42=$T4)*('Jul 9'!$AG$8:$AG$42="Delivered")*(('Jul 9'!$AM$8:$AM$42="Y")+('Jul 9'!$AN$8:$AN$42="Y")+('Jul 9'!$AO$8:$AO$42="Y")))+SUMPRODUCT(('Jul 10'!$F$8:$F$42=$T4)*('Jul 10'!$AG$8:$AG$42="Delivered")*(('Jul 10'!$AM$8:$AM$42="Y")+('Jul 10'!$AN$8:$AN$42="Y")+('Jul 10'!$AO$8:$AO$42="Y")))+SUMPRODUCT(('Jul 11'!$F$8:$F$42=$T4)*('Jul 11'!$AG$8:$AG$42="Delivered")*(('Jul 11'!$AM$8:$AM$42="Y")+('Jul 11'!$AN$8:$AN$42="Y")+('Jul 11'!$AO$8:$AO$42="Y")))+SUMPRODUCT(('Jul 12'!$F$8:$F$42=$T4)*('Jul 12'!$AG$8:$AG$42="Delivered")*(('Jul 12'!$AM$8:$AM$42="Y")+('Jul 12'!$AN$8:$AN$42="Y")+('Jul 12'!$AO$8:$AO$42="Y")))+SUMPRODUCT(('Jul 13'!$F$8:$F$42=$T4)*('Jul 13'!$AG$8:$AG$42="Delivered")*(('Jul 13'!$AM$8:$AM$42="Y")+('Jul 13'!$AN$8:$AN$42="Y")+('Jul 13'!$AO$8:$AO$42="Y")))+SUMPRODUCT(('Jul 14'!$F$8:$F$42=$T4)*('Jul 14'!$AG$8:$AG$42="Delivered")*(('Jul 14'!$AM$8:$AM$42="Y")+('Jul 14'!$AN$8:$AN$42="Y")+('Jul 14'!$AO$8:$AO$42="Y")))+SUMPRODUCT(('Jul 15'!$F$8:$F$42=$T4)*('Jul 15'!$AG$8:$AG$42="Delivered")*(('Jul 15'!$AM$8:$AM$42="Y")+('Jul 15'!$AN$8:$AN$42="Y")+('Jul 15'!$AO$8:$AO$42="Y")))+SUMPRODUCT(('Jul 16'!$F$8:$F$42=$T4)*('Jul 16'!$AG$8:$AG$42="Delivered")*(('Jul 16'!$AM$8:$AM$42="Y")+('Jul 16'!$AN$8:$AN$42="Y")+('Jul 16'!$AO$8:$AO$42="Y")))+SUMPRODUCT(('Jul 17'!$F$8:$F$42=$T4)*('Jul 17'!$AG$8:$AG$42="Delivered")*(('Jul 17'!$AM$8:$AM$42="Y")+('Jul 17'!$AN$8:$AN$42="Y")+('Jul 17'!$AO$8:$AO$42="Y")))+SUMPRODUCT(('Jul 18'!$F$8:$F$42=$T4)*('Jul 18'!$AG$8:$AG$42="Delivered")*(('Jul 18'!$AM$8:$AM$42="Y")+('Jul 18'!$AN$8:$AN$42="Y")+('Jul 18'!$AO$8:$AO$42="Y")))+SUMPRODUCT(('Jul 19'!$F$8:$F$42=$T4)*('Jul 19'!$AG$8:$AG$42="Delivered")*(('Jul 19'!$AM$8:$AM$42="Y")+('Jul 19'!$AN$8:$AN$42="Y")+('Jul 19'!$AO$8:$AO$42="Y")))+SUMPRODUCT(('Jul 20'!$F$8:$F$42=$T4)*('Jul 20'!$AG$8:$AG$42="Delivered")*(('Jul 20'!$AM$8:$AM$42="Y")+('Jul 20'!$AN$8:$AN$42="Y")+('Jul 20'!$AO$8:$AO$42="Y")))+SUMPRODUCT(('Jul 21'!$F$8:$F$42=$T4)*('Jul 21'!$AG$8:$AG$42="Delivered")*(('Jul 21'!$AM$8:$AM$42="Y")+('Jul 21'!$AN$8:$AN$42="Y")+('Jul 21'!$AO$8:$AO$42="Y")))+SUMPRODUCT(('Jul 22'!$F$8:$F$42=$T4)*('Jul 22'!$AG$8:$AG$42="Delivered")*(('Jul 22'!$AM$8:$AM$42="Y")+('Jul 22'!$AN$8:$AN$42="Y")+('Jul 22'!$AO$8:$AO$42="Y")))+SUMPRODUCT(('Jul 23'!$F$8:$F$42=$T4)*('Jul 23'!$AG$8:$AG$42="Delivered")*(('Jul 23'!$AM$8:$AM$42="Y")+('Jul 23'!$AN$8:$AN$42="Y")+('Jul 23'!$AO$8:$AO$42="Y")))+SUMPRODUCT(('Jul 24'!$F$8:$F$42=$T4)*('Jul 24'!$AG$8:$AG$42="Delivered")*(('Jul 24'!$AM$8:$AM$42="Y")+('Jul 24'!$AN$8:$AN$42="Y")+('Jul 24'!$AO$8:$AO$42="Y")))+SUMPRODUCT(('Jul 25'!$F$8:$F$42=$T4)*('Jul 25'!$AG$8:$AG$42="Delivered")*(('Jul 25'!$AM$8:$AM$42="Y")+('Jul 25'!$AN$8:$AN$42="Y")+('Jul 25'!$AO$8:$AO$42="Y")))+SUMPRODUCT(('Jul 26'!$F$8:$F$42=$T4)*('Jul 26'!$AG$8:$AG$42="Delivered")*(('Jul 26'!$AM$8:$AM$42="Y")+('Jul 26'!$AN$8:$AN$42="Y")+('Jul 26'!$AO$8:$AO$42="Y")))+SUMPRODUCT(('Jul 27'!$F$8:$F$42=$T4)*('Jul 27'!$AG$8:$AG$42="Delivered")*(('Jul 27'!$AM$8:$AM$42="Y")+('Jul 27'!$AN$8:$AN$42="Y")+('Jul 27'!$AO$8:$AO$42="Y")))+SUMPRODUCT(('Jul 28'!$F$8:$F$42=$T4)*('Jul 28'!$AG$8:$AG$42="Delivered")*(('Jul 28'!$AM$8:$AM$42="Y")+('Jul 28'!$AN$8:$AN$42="Y")+('Jul 28'!$AO$8:$AO$42="Y")))+SUMPRODUCT(('Jul 29'!$F$8:$F$42=$T4)*('Jul 29'!$AG$8:$AG$42="Delivered")*(('Jul 29'!$AM$8:$AM$42="Y")+('Jul 29'!$AN$8:$AN$42="Y")+('Jul 29'!$AO$8:$AO$42="Y")))+SUMPRODUCT(('Jul 30'!$F$8:$F$42=$T4)*('Jul 30'!$AG$8:$AG$42="Delivered")*(('Jul 30'!$AM$8:$AM$42="Y")+('Jul 30'!$AN$8:$AN$42="Y")+('Jul 30'!$AO$8:$AO$42="Y")))+SUMPRODUCT(('Jul 31'!$F$8:$F$42=$T4)*('Jul 31'!$AG$8:$AG$42="Delivered")*(('Jul 31'!$AM$8:$AM$42="Y")+('Jul 31'!$AN$8:$AN$42="Y")+('Jul 31'!$AO$8:$AO$42="Y"))) -> 0 | BD4: =SUM(U4:AY4) -> 0 | BE4: =SUM(U23:AY23) -> 0 | BF4: =SUM(U42:AY42) -> 0 | BH4: =SUMPRODUCT(('Jul 1'!$AG$8:$AG$42="Delivered")*('Jul 1'!$D$8:$D$42<>""))+SUMPRODUCT(('Jul 2'!$AG$8:$AG$42="Delivered")*('Jul 2'!$D$8:$D$42<>""))+SUMPRODUCT(('Jul 3'!$AG$8:$AG$42="Delivered")*('Jul 3'!$D$8:$D$42<>""))+SUMPRODUCT(('Jul 4'!$AG$8:$AG$42="Delivered")*('Jul 4'!$D$8:$D$42<>""))+SUMPRODUCT(('Jul 5'!$AG$8:$AG$42="Delivered")*('Jul 5'!$D$8:$D$42<>""))+SUMPRODUCT(('Jul 6'!$AG$8:$AG$42="Delivered")*('Jul 6'!$D$8:$D$42<>""))+SUMPRODUCT(('Jul 7'!$AG$8:$AG$42="Delivered")*('Jul 7'!$D$8:$D$42<>""))+SUMPRODUCT(('Jul 8'!$AG$8:$AG$42="Delivered")*('Jul 8'!$D$8:$D$42<>""))+SUMPRODUCT(('Jul 9'!$AG$8:$AG$42="Delivered")*('Jul 9'!$D$8:$D$42<>""))+SUMPRODUCT(('Jul 10'!$AG$8:$AG$42="Delivered")*('Jul 10'!$D$8:$D$42<>""))+SUMPRODUCT(('Jul 11'!$AG$8:$AG$42="Delivered")*('Jul 11'!$D$8:$D$42<>""))+SUMPRODUCT(('Jul 12'!$AG$8:$AG$42="Delivered")*('Jul 12'!$D$8:$D$42<>""))+SUMPRODUCT(('Jul 13'!$AG$8:$AG$42="Delivered")*('Jul 13'!$D$8:$D$42<>""))+SUMPRODUCT(('Jul 14'!$AG$8:$AG$42="Delivered")*('Jul 14'!$D$8:$D$42<>""))+SUMPRODUCT(('Jul 15'!$AG$8:$AG$42="Delivered")*('Jul 15'!$D$8:$D$42<>""))+SUMPRODUCT(('Jul 16'!$AG$8:$AG$42="Delivered")*('Jul 16'!$D$8:$D$42<>""))+SUMPRODUCT(('Jul 17'!$AG$8:$AG$42="Delivered")*('Jul 17'!$D$8:$D$42<>""))+SUMPRODUCT(('Jul 18'!$AG$8:$AG$42="Delivered")*('Jul 18'!$D$8:$D$42<>""))+SUMPRODUCT(('Jul 19'!$AG$8:$AG$42="Delivered")*('Jul 19'!$D$8:$D$42<>""))+SUMPRODUCT(('Jul 20'!$AG$8:$AG$42="Delivered")*('Jul 20'!$D$8:$D$42<>""))+SUMPRODUCT(('Jul 21'!$AG$8:$AG$42="Delivered")*('Jul 21'!$D$8:$D$42<>""))+SUMPRODUCT(('Jul 22'!$AG$8:$AG$42="Delivered")*('Jul 22'!$D$8:$D$42<>""))+SUMPRODUCT(('Jul 23'!$AG$8:$AG$42="Delivered")*('Jul 23'!$D$8:$D$42<>""))+SUMPRODUCT(('Jul 24'!$AG$8:$AG$42="Delivered")*('Jul 24'!$D$8:$D$42<>""))+SUMPRODUCT(('Jul 25'!$AG$8:$AG$42="Delivered")*('Jul 25'!$D$8:$D$42<>""))+SUMPRODUCT(('Jul 26'!$AG$8:$AG$42="Delivered")*('Jul 26'!$D$8:$D$42<>""))+SUMPRODUCT(('Jul 27'!$AG$8:$AG$42="Delivered")*('Jul 27'!$D$8:$D$42<>""))+SUMPRODUCT(('Jul 28'!$AG$8:$AG$42="Delivered")*('Jul 28'!$D$8:$D$42<>""))+SUMPRODUCT(('Jul 29'!$AG$8:$AG$42="Delivered")*('Jul 29'!$D$8:$D$42<>""))+SUMPRODUCT(('Jul 30'!$AG$8:$AG$42="Delivered")*('Jul 30'!$D$8:$D$42<>""))+SUMPRODUCT(('Jul 31'!$AG$8:$AG$42="Delivered")*('Jul 31'!$D$8:$D$42<>"")) -> 0
T5: CHAD EMBRY | U5: =SUMPRODUCT((('Jul 1'!$F$8:$F$42=$T5)*(0.5+0.5*('Jul 1'!$G$8:$G$42=""))+('Jul 1'!$G$8:$G$42=$T5)*0.5)*('Jul 1'!$AG$8:$AG$42="Delivered")) -> 0 | V5: =SUMPRODUCT((('Jul 2'!$F$8:$F$42=$T5)*(0.5+0.5*('Jul 2'!$G$8:$G$42=""))+('Jul 2'!$G$8:$G$42=$T5)*0.5)*('Jul 2'!$AG$8:$AG$42="Delivered")) -> 0 | W5: =SUMPRODUCT((('Jul 3'!$F$8:$F$42=$T5)*(0.5+0.5*('Jul 3'!$G$8:$G$42=""))+('Jul 3'!$G$8:$G$42=$T5)*0.5)*('Jul 3'!$AG$8:$AG$42="Delivered")) -> 0 | X5: =SUMPRODUCT((('Jul 4'!$F$8:$F$42=$T5)*(0.5+0.5*('Jul 4'!$G$8:$G$42=""))+('Jul 4'!$G$8:$G$42=$T5)*0.5)*('Jul 4'!$AG$8:$AG$42="Delivered")) -> 0 | Y5: =SUMPRODUCT((('Jul 5'!$F$8:$F$42=$T5)*(0.5+0.5*('Jul 5'!$G$8:$G$42=""))+('Jul 5'!$G$8:$G$42=$T5)*0.5)*('Jul 5'!$AG$8:$AG$42="Delivered")) -> 0 | Z5: =SUMPRODUCT((('Jul 6'!$F$8:$F$42=$T5)*(0.5+0.5*('Jul 6'!$G$8:$G$42=""))+('Jul 6'!$G$8:$G$42=$T5)*0.5)*('Jul 6'!$AG$8:$AG$42="Delivered")) -> 0 | AA5: =SUMPRODUCT((('Jul 7'!$F$8:$F$42=$T5)*(0.5+0.5*('Jul 7'!$G$8:$G$42=""))+('Jul 7'!$G$8:$G$42=$T5)*0.5)*('Jul 7'!$AG$8:$AG$42="Delivered")) -> 0 | AB5: =SUMPRODUCT((('Jul 8'!$F$8:$F$42=$T5)*(0.5+0.5*('Jul 8'!$G$8:$G$42=""))+('Jul 8'!$G$8:$G$42=$T5)*0.5)*('Jul 8'!$AG$8:$AG$42="Delivered")) -> 0 | AC5: =SUMPRODUCT((('Jul 9'!$F$8:$F$42=$T5)*(0.5+0.5*('Jul 9'!$G$8:$G$42=""))+('Jul 9'!$G$8:$G$42=$T5)*0.5)*('Jul 9'!$AG$8:$AG$42="Delivered")) -> 0 | AD5: =SUMPRODUCT((('Jul 10'!$F$8:$F$42=$T5)*(0.5+0.5*('Jul 10'!$G$8:$G$42=""))+('Jul 10'!$G$8:$G$42=$T5)*0.5)*('Jul 10'!$AG$8:$AG$42="Delivered")) -> 0 | AE5: =SUMPRODUCT((('Jul 11'!$F$8:$F$42=$T5)*(0.5+0.5*('Jul 11'!$G$8:$G$42=""))+('Jul 11'!$G$8:$G$42=$T5)*0.5)*('Jul 11'!$AG$8:$AG$42="Delivered")) -> 0 | AF5: =SUMPRODUCT((('Jul 12'!$F$8:$F$42=$T5)*(0.5+0.5*('Jul 12'!$G$8:$G$42=""))+('Jul 12'!$G$8:$G$42=$T5)*0.5)*('Jul 12'!$AG$8:$AG$42="Delivered")) -> 0 | AG5: =SUMPRODUCT((('Jul 13'!$F$8:$F$42=$T5)*(0.5+0.5*('Jul 13'!$G$8:$G$42=""))+('Jul 13'!$G$8:$G$42=$T5)*0.5)*('Jul 13'!$AG$8:$AG$42="Delivered")) -> 0 | AH5: =SUMPRODUCT((('Jul 14'!$F$8:$F$42=$T5)*(0.5+0.5*('Jul 14'!$G$8:$G$42=""))+('Jul 14'!$G$8:$G$42=$T5)*0.5)*('Jul 14'!$AG$8:$AG$42="Delivered")) -> 0 | AI5: =SUMPRODUCT((('Jul 15'!$F$8:$F$42=$T5)*(0.5+0.5*('Jul 15'!$G$8:$G$42=""))+('Jul 15'!$G$8:$G$42=$T5)*0.5)*('Jul 15'!$AG$8:$AG$42="Delivered")) -> 0 | AJ5: =SUMPRODUCT((('Jul 16'!$F$8:$F$42=$T5)*(0.5+0.5*('Jul 16'!$G$8:$G$42=""))+('Jul 16'!$G$8:$G$42=$T5)*0.5)*('Jul 16'!$AG$8:$AG$42="Delivered")) -> 0 | AK5: =SUMPRODUCT((('Jul 17'!$F$8:$F$42=$T5)*(0.5+0.5*('Jul 17'!$G$8:$G$42=""))+('Jul 17'!$G$8:$G$42=$T5)*0.5)*('Jul 17'!$AG$8:$AG$42="Delivered")) -> 0 | AL5: =SUMPRODUCT((('Jul 18'!$F$8:$F$42=$T5)*(0.5+0.5*('Jul 18'!$G$8:$G$42=""))+('Jul 18'!$G$8:$G$42=$T5)*0.5)*('Jul 18'!$AG$8:$AG$42="Delivered")) -> 0 | AM5: =SUMPRODUCT((('Jul 19'!$F$8:$F$42=$T5)*(0.5+0.5*('Jul 19'!$G$8:$G$42=""))+('Jul 19'!$G$8:$G$42=$T5)*0.5)*('Jul 19'!$AG$8:$AG$42="Delivered")) -> 0 | AN5: =SUMPRODUCT((('Jul 20'!$F$8:$F$42=$T5)*(0.5+0.5*('Jul 20'!$G$8:$G$42=""))+('Jul 20'!$G$8:$G$42=$T5)*0.5)*('Jul 20'!$AG$8:$AG$42="Delivered")) -> 0 | AO5: =SUMPRODUCT((('Jul 21'!$F$8:$F$42=$T5)*(0.5+0.5*('Jul 21'!$G$8:$G$42=""))+('Jul 21'!$G$8:$G$42=$T5)*0.5)*('Jul 21'!$AG$8:$AG$42="Delivered")) -> 0 | AP5: =SUMPRODUCT((('Jul 22'!$F$8:$F$42=$T5)*(0.5+0.5*('Jul 22'!$G$8:$G$42=""))+('Jul 22'!$G$8:$G$42=$T5)*0.5)*('Jul 22'!$AG$8:$AG$42="Delivered")) -> 0 | AQ5: =SUMPRODUCT((('Jul 23'!$F$8:$F$42=$T5)*(0.5+0.5*('Jul 23'!$G$8:$G$42=""))+('Jul 23'!$G$8:$G$42=$T5)*0.5)*('Jul 23'!$AG$8:$AG$42="Delivered")) -> 0 | AR5: =SUMPRODUCT((('Jul 24'!$F$8:$F$42=$T5)*(0.5+0.5*('Jul 24'!$G$8:$G$42=""))+('Jul 24'!$G$8:$G$42=$T5)*0.5)*('Jul 24'!$AG$8:$AG$42="Delivered")) -> 0 | AS5: =SUMPRODUCT((('Jul 25'!$F$8:$F$42=$T5)*(0.5+0.5*('Jul 25'!$G$8:$G$42=""))+('Jul 25'!$G$8:$G$42=$T5)*0.5)*('Jul 25'!$AG$8:$AG$42="Delivered")) -> 0 | AT5: =SUMPRODUCT((('Jul 26'!$F$8:$F$42=$T5)*(0.5+0.5*('Jul 26'!$G$8:$G$42=""))+('Jul 26'!$G$8:$G$42=$T5)*0.5)*('Jul 26'!$AG$8:$AG$42="Delivered")) -> 0 | AU5: =SUMPRODUCT((('Jul 27'!$F$8:$F$42=$T5)*(0.5+0.5*('Jul 27'!$G$8:$G$42=""))+('Jul 27'!$G$8:$G$42=$T5)*0.5)*('Jul 27'!$AG$8:$AG$42="Delivered")) -> 0 | AV5: =SUMPRODUCT((('Jul 28'!$F$8:$F$42=$T5)*(0.5+0.5*('Jul 28'!$G$8:$G$42=""))+('Jul 28'!$G$8:$G$42=$T5)*0.5)*('Jul 28'!$AG$8:$AG$42="Delivered")) -> 0 | AW5: =SUMPRODUCT((('Jul 29'!$F$8:$F$42=$T5)*(0.5+0.5*('Jul 29'!$G$8:$G$42=""))+('Jul 29'!$G$8:$G$42=$T5)*0.5)*('Jul 29'!$AG$8:$AG$42="Delivered")) -> 0 | AX5: =SUMPRODUCT((('Jul 30'!$F$8:$F$42=$T5)*(0.5+0.5*('Jul 30'!$G$8:$G$42=""))+('Jul 30'!$G$8:$G$42=$T5)*0.5)*('Jul 30'!$AG$8:$AG$42="Delivered")) -> 0 | AY5: =SUMPRODUCT((('Jul 31'!$F$8:$F$42=$T5)*(0.5+0.5*('Jul 31'!$G$8:$G$42=""))+('Jul 31'!$G$8:$G$42=$T5)*0.5)*('Jul 31'!$AG$8:$AG$42="Delivered")) -> 0 | BA5: =SUM(U5:AD5) -> 0 | BB5: =MATCH(BD5,'Pay Plan'!$C$6:$C$12,1) -> 1 | BC5: =SUMPRODUCT(('Jul 1'!$F$8:$F$42=$T5)*('Jul 1'!$AG$8:$AG$42="Delivered")*(('Jul 1'!$AM$8:$AM$42="Y")+('Jul 1'!$AN$8:$AN$42="Y")+('Jul 1'!$AO$8:$AO$42="Y")))+SUMPRODUCT(('Jul 2'!$F$8:$F$42=$T5)*('Jul 2'!$AG$8:$AG$42="Delivered")*(('Jul 2'!$AM$8:$AM$42="Y")+('Jul 2'!$AN$8:$AN$42="Y")+('Jul 2'!$AO$8:$AO$42="Y")))+SUMPRODUCT(('Jul 3'!$F$8:$F$42=$T5)*('Jul 3'!$AG$8:$AG$42="Delivered")*(('Jul 3'!$AM$8:$AM$42="Y")+('Jul 3'!$AN$8:$AN$42="Y")+('Jul 3'!$AO$8:$AO$42="Y")))+SUMPRODUCT(('Jul 4'!$F$8:$F$42=$T5)*('Jul 4'!$AG$8:$AG$42="Delivered")*(('Jul 4'!$AM$8:$AM$42="Y")+('Jul 4'!$AN$8:$AN$42="Y")+('Jul 4'!$AO$8:$AO$42="Y")))+SUMPRODUCT(('Jul 5'!$F$8:$F$42=$T5)*('Jul 5'!$AG$8:$AG$42="Delivered")*(('Jul 5'!$AM$8:$AM$42="Y")+('Jul 5'!$AN$8:$AN$42="Y")+('Jul 5'!$AO$8:$AO$42="Y")))+SUMPRODUCT(('Jul 6'!$F$8:$F$42=$T5)*('Jul 6'!$AG$8:$AG$42="Delivered")*(('Jul 6'!$AM$8:$AM$42="Y")+('Jul 6'!$AN$8:$AN$42="Y")+('Jul 6'!$AO$8:$AO$42="Y")))+SUMPRODUCT(('Jul 7'!$F$8:$F$42=$T5)*('Jul 7'!$AG$8:$AG$42="Delivered")*(('Jul 7'!$AM$8:$AM$42="Y")+('Jul 7'!$AN$8:$AN$42="Y")+('Jul 7'!$AO$8:$AO$42="Y")))+SUMPRODUCT(('Jul 8'!$F$8:$F$42=$T5)*('Jul 8'!$AG$8:$AG$42="Delivered")*(('Jul 8'!$AM$8:$AM$42="Y")+('Jul 8'!$AN$8:$AN$42="Y")+('Jul 8'!$AO$8:$AO$42="Y")))+SUMPRODUCT(('Jul 9'!$F$8:$F$42=$T5)*('Jul 9'!$AG$8:$AG$42="Delivered")*(('Jul 9'!$AM$8:$AM$42="Y")+('Jul 9'!$AN$8:$AN$42="Y")+('Jul 9'!$AO$8:$AO$42="Y")))+SUMPRODUCT(('Jul 10'!$F$8:$F$42=$T5)*('Jul 10'!$AG$8:$AG$42="Delivered")*(('Jul 10'!$AM$8:$AM$42="Y")+('Jul 10'!$AN$8:$AN$42="Y")+('Jul 10'!$AO$8:$AO$42="Y")))+SUMPRODUCT(('Jul 11'!$F$8:$F$42=$T5)*('Jul 11'!$AG$8:$AG$42="Delivered")*(('Jul 11'!$AM$8:$AM$42="Y")+('Jul 11'!$AN$8:$AN$42="Y")+('Jul 11'!$AO$8:$AO$42="Y")))+SUMPRODUCT(('Jul 12'!$F$8:$F$42=$T5)*('Jul 12'!$AG$8:$AG$42="Delivered")*(('Jul 12'!$AM$8:$AM$42="Y")+('Jul 12'!$AN$8:$AN$42="Y")+('Jul 12'!$AO$8:$AO$42="Y")))+SUMPRODUCT(('Jul 13'!$F$8:$F$42=$T5)*('Jul 13'!$AG$8:$AG$42="Delivered")*(('Jul 13'!$AM$8:$AM$42="Y")+('Jul 13'!$AN$8:$AN$42="Y")+('Jul 13'!$AO$8:$AO$42="Y")))+SUMPRODUCT(('Jul 14'!$F$8:$F$42=$T5)*('Jul 14'!$AG$8:$AG$42="Delivered")*(('Jul 14'!$AM$8:$AM$42="Y")+('Jul 14'!$AN$8:$AN$42="Y")+('Jul 14'!$AO$8:$AO$42="Y")))+SUMPRODUCT(('Jul 15'!$F$8:$F$42=$T5)*('Jul 15'!$AG$8:$AG$42="Delivered")*(('Jul 15'!$AM$8:$AM$42="Y")+('Jul 15'!$AN$8:$AN$42="Y")+('Jul 15'!$AO$8:$AO$42="Y")))+SUMPRODUCT(('Jul 16'!$F$8:$F$42=$T5)*('Jul 16'!$AG$8:$AG$42="Delivered")*(('Jul 16'!$AM$8:$AM$42="Y")+('Jul 16'!$AN$8:$AN$42="Y")+('Jul 16'!$AO$8:$AO$42="Y")))+SUMPRODUCT(('Jul 17'!$F$8:$F$42=$T5)*('Jul 17'!$AG$8:$AG$42="Delivered")*(('Jul 17'!$AM$8:$AM$42="Y")+('Jul 17'!$AN$8:$AN$42="Y")+('Jul 17'!$AO$8:$AO$42="Y")))+SUMPRODUCT(('Jul 18'!$F$8:$F$42=$T5)*('Jul 18'!$AG$8:$AG$42="Delivered")*(('Jul 18'!$AM$8:$AM$42="Y")+('Jul 18'!$AN$8:$AN$42="Y")+('Jul 18'!$AO$8:$AO$42="Y")))+SUMPRODUCT(('Jul 19'!$F$8:$F$42=$T5)*('Jul 19'!$AG$8:$AG$42="Delivered")*(('Jul 19'!$AM$8:$AM$42="Y")+('Jul 19'!$AN$8:$AN$42="Y")+('Jul 19'!$AO$8:$AO$42="Y")))+SUMPRODUCT(('Jul 20'!$F$8:$F$42=$T5)*('Jul 20'!$AG$8:$AG$42="Delivered")*(('Jul 20'!$AM$8:$AM$42="Y")+('Jul 20'!$AN$8:$AN$42="Y")+('Jul 20'!$AO$8:$AO$42="Y")))+SUMPRODUCT(('Jul 21'!$F$8:$F$42=$T5)*('Jul 21'!$AG$8:$AG$42="Delivered")*(('Jul 21'!$AM$8:$AM$42="Y")+('Jul 21'!$AN$8:$AN$42="Y")+('Jul 21'!$AO$8:$AO$42="Y")))+SUMPRODUCT(('Jul 22'!$F$8:$F$42=$T5)*('Jul 22'!$AG$8:$AG$42="Delivered")*(('Jul 22'!$AM$8:$AM$42="Y")+('Jul 22'!$AN$8:$AN$42="Y")+('Jul 22'!$AO$8:$AO$42="Y")))+SUMPRODUCT(('Jul 23'!$F$8:$F$42=$T5)*('Jul 23'!$AG$8:$AG$42="Delivered")*(('Jul 23'!$AM$8:$AM$42="Y")+('Jul 23'!$AN$8:$AN$42="Y")+('Jul 23'!$AO$8:$AO$42="Y")))+SUMPRODUCT(('Jul 24'!$F$8:$F$42=$T5)*('Jul 24'!$AG$8:$AG$42="Delivered")*(('Jul 24'!$AM$8:$AM$42="Y")+('Jul 24'!$AN$8:$AN$42="Y")+('Jul 24'!$AO$8:$AO$42="Y")))+SUMPRODUCT(('Jul 25'!$F$8:$F$42=$T5)*('Jul 25'!$AG$8:$AG$42="Delivered")*(('Jul 25'!$AM$8:$AM$42="Y")+('Jul 25'!$AN$8:$AN$42="Y")+('Jul 25'!$AO$8:$AO$42="Y")))+SUMPRODUCT(('Jul 26'!$F$8:$F$42=$T5)*('Jul 26'!$AG$8:$AG$42="Delivered")*(('Jul 26'!$AM$8:$AM$42="Y")+('Jul 26'!$AN$8:$AN$42="Y")+('Jul 26'!$AO$8:$AO$42="Y")))+SUMPRODUCT(('Jul 27'!$F$8:$F$42=$T5)*('Jul 27'!$AG$8:$AG$42="Delivered")*(('Jul 27'!$AM$8:$AM$42="Y")+('Jul 27'!$AN$8:$AN$42="Y")+('Jul 27'!$AO$8:$AO$42="Y")))+SUMPRODUCT(('Jul 28'!$F$8:$F$42=$T5)*('Jul 28'!$AG$8:$AG$42="Delivered")*(('Jul 28'!$AM$8:$AM$42="Y")+('Jul 28'!$AN$8:$AN$42="Y")+('Jul 28'!$AO$8:$AO$42="Y")))+SUMPRODUCT(('Jul 29'!$F$8:$F$42=$T5)*('Jul 29'!$AG$8:$AG$42="Delivered")*(('Jul 29'!$AM$8:$AM$42="Y")+('Jul 29'!$AN$8:$AN$42="Y")+('Jul 29'!$AO$8:$AO$42="Y")))+SUMPRODUCT(('Jul 30'!$F$8:$F$42=$T5)*('Jul 30'!$AG$8:$AG$42="Delivered")*(('Jul 30'!$AM$8:$AM$42="Y")+('Jul 30'!$AN$8:$AN$42="Y")+('Jul 30'!$AO$8:$AO$42="Y")))+SUMPRODUCT(('Jul 31'!$F$8:$F$42=$T5)*('Jul 31'!$AG$8:$AG$42="Delivered")*(('Jul 31'!$AM$8:$AM$42="Y")+('Jul 31'!$AN$8:$AN$42="Y")+('Jul 31'!$AO$8:$AO$42="Y"))) -> 0 | BD5: =SUM(U5:AY5) -> 0 | BE5: =SUM(U24:AY24) -> 0 | BF5: =SUM(U43:AY43) -> 0 | BH5: =SUMPRODUCT(('Jul 1'!$AG$8:$AG$42="Delivered")*(('Jul 1'!$AM$8:$AM$42="Y")+('Jul 1'!$AN$8:$AN$42="Y")+('Jul 1'!$AO$8:$AO$42="Y")))+SUMPRODUCT(('Jul 2'!$AG$8:$AG$42="Delivered")*(('Jul 2'!$AM$8:$AM$42="Y")+('Jul 2'!$AN$8:$AN$42="Y")+('Jul 2'!$AO$8:$AO$42="Y")))+SUMPRODUCT(('Jul 3'!$AG$8:$AG$42="Delivered")*(('Jul 3'!$AM$8:$AM$42="Y")+('Jul 3'!$AN$8:$AN$42="Y")+('Jul 3'!$AO$8:$AO$42="Y")))+SUMPRODUCT(('Jul 4'!$AG$8:$AG$42="Delivered")*(('Jul 4'!$AM$8:$AM$42="Y")+('Jul 4'!$AN$8:$AN$42="Y")+('Jul 4'!$AO$8:$AO$42="Y")))+SUMPRODUCT(('Jul 5'!$AG$8:$AG$42="Delivered")*(('Jul 5'!$AM$8:$AM$42="Y")+('Jul 5'!$AN$8:$AN$42="Y")+('Jul 5'!$AO$8:$AO$42="Y")))+SUMPRODUCT(('Jul 6'!$AG$8:$AG$42="Delivered")*(('Jul 6'!$AM$8:$AM$42="Y")+('Jul 6'!$AN$8:$AN$42="Y")+('Jul 6'!$AO$8:$AO$42="Y")))+SUMPRODUCT(('Jul 7'!$AG$8:$AG$42="Delivered")*(('Jul 7'!$AM$8:$AM$42="Y")+('Jul 7'!$AN$8:$AN$42="Y")+('Jul 7'!$AO$8:$AO$42="Y")))+SUMPRODUCT(('Jul 8'!$AG$8:$AG$42="Delivered")*(('Jul 8'!$AM$8:$AM$42="Y")+('Jul 8'!$AN$8:$AN$42="Y")+('Jul 8'!$AO$8:$AO$42="Y")))+SUMPRODUCT(('Jul 9'!$AG$8:$AG$42="Delivered")*(('Jul 9'!$AM$8:$AM$42="Y")+('Jul 9'!$AN$8:$AN$42="Y")+('Jul 9'!$AO$8:$AO$42="Y")))+SUMPRODUCT(('Jul 10'!$AG$8:$AG$42="Delivered")*(('Jul 10'!$AM$8:$AM$42="Y")+('Jul 10'!$AN$8:$AN$42="Y")+('Jul 10'!$AO$8:$AO$42="Y")))+SUMPRODUCT(('Jul 11'!$AG$8:$AG$42="Delivered")*(('Jul 11'!$AM$8:$AM$42="Y")+('Jul 11'!$AN$8:$AN$42="Y")+('Jul 11'!$AO$8:$AO$42="Y")))+SUMPRODUCT(('Jul 12'!$AG$8:$AG$42="Delivered")*(('Jul 12'!$AM$8:$AM$42="Y")+('Jul 12'!$AN$8:$AN$42="Y")+('Jul 12'!$AO$8:$AO$42="Y")))+SUMPRODUCT(('Jul 13'!$AG$8:$AG$42="Delivered")*(('Jul 13'!$AM$8:$AM$42="Y")+('Jul 13'!$AN$8:$AN$42="Y")+('Jul 13'!$AO$8:$AO$42="Y")))+SUMPRODUCT(('Jul 14'!$AG$8:$AG$42="Delivered")*(('Jul 14'!$AM$8:$AM$42="Y")+('Jul 14'!$AN$8:$AN$42="Y")+('Jul 14'!$AO$8:$AO$42="Y")))+SUMPRODUCT(('Jul 15'!$AG$8:$AG$42="Delivered")*(('Jul 15'!$AM$8:$AM$42="Y")+('Jul 15'!$AN$8:$AN$42="Y")+('Jul 15'!$AO$8:$AO$42="Y")))+SUMPRODUCT(('Jul 16'!$AG$8:$AG$42="Delivered")*(('Jul 16'!$AM$8:$AM$42="Y")+('Jul 16'!$AN$8:$AN$42="Y")+('Jul 16'!$AO$8:$AO$42="Y")))+SUMPRODUCT(('Jul 17'!$AG$8:$AG$42="Delivered")*(('Jul 17'!$AM$8:$AM$42="Y")+('Jul 17'!$AN$8:$AN$42="Y")+('Jul 17'!$AO$8:$AO$42="Y")))+SUMPRODUCT(('Jul 18'!$AG$8:$AG$42="Delivered")*(('Jul 18'!$AM$8:$AM$42="Y")+('Jul 18'!$AN$8:$AN$42="Y")+('Jul 18'!$AO$8:$AO$42="Y")))+SUMPRODUCT(('Jul 19'!$AG$8:$AG$42="Delivered")*(('Jul 19'!$AM$8:$AM$42="Y")+('Jul 19'!$AN$8:$AN$42="Y")+('Jul 19'!$AO$8:$AO$42="Y")))+SUMPRODUCT(('Jul 20'!$AG$8:$AG$42="Delivered")*(('Jul 20'!$AM$8:$AM$42="Y")+('Jul 20'!$AN$8:$AN$42="Y")+('Jul 20'!$AO$8:$AO$42="Y")))+SUMPRODUCT(('Jul 21'!$AG$8:$AG$42="Delivered")*(('Jul 21'!$AM$8:$AM$42="Y")+('Jul 21'!$AN$8:$AN$42="Y")+('Jul 21'!$AO$8:$AO$42="Y")))+SUMPRODUCT(('Jul 22'!$AG$8:$AG$42="Delivered")*(('Jul 22'!$AM$8:$AM$42="Y")+('Jul 22'!$AN$8:$AN$42="Y")+('Jul 22'!$AO$8:$AO$42="Y")))+SUMPRODUCT(('Jul 23'!$AG$8:$AG$42="Delivered")*(('Jul 23'!$AM$8:$AM$42="Y")+('Jul 23'!$AN$8:$AN$42="Y")+('Jul 23'!$AO$8:$AO$42="Y")))+SUMPRODUCT(('Jul 24'!$AG$8:$AG$42="Delivered")*(('Jul 24'!$AM$8:$AM$42="Y")+('Jul 24'!$AN$8:$AN$42="Y")+('Jul 24'!$AO$8:$AO$42="Y")))+SUMPRODUCT(('Jul 25'!$AG$8:$AG$42="Delivered")*(('Jul 25'!$AM$8:$AM$42="Y")+('Jul 25'!$AN$8:$AN$42="Y")+('Jul 25'!$AO$8:$AO$42="Y")))+SUMPRODUCT(('Jul 26'!$AG$8:$AG$42="Delivered")*(('Jul 26'!$AM$8:$AM$42="Y")+('Jul 26'!$AN$8:$AN$42="Y")+('Jul 26'!$AO$8:$AO$42="Y")))+SUMPRODUCT(('Jul 27'!$AG$8:$AG$42="Delivered")*(('Jul 27'!$AM$8:$AM$42="Y")+('Jul 27'!$AN$8:$AN$42="Y")+('Jul 27'!$AO$8:$AO$42="Y")))+SUMPRODUCT(('Jul 28'!$AG$8:$AG$42="Delivered")*(('Jul 28'!$AM$8:$AM$42="Y")+('Jul 28'!$AN$8:$AN$42="Y")+('Jul 28'!$AO$8:$AO$42="Y")))+SUMPRODUCT(('Jul 29'!$AG$8:$AG$42="Delivered")*(('Jul 29'!$AM$8:$AM$42="Y")+('Jul 29'!$AN$8:$AN$42="Y")+('Jul 29'!$AO$8:$AO$42="Y")))+SUMPRODUCT(('Jul 30'!$AG$8:$AG$42="Delivered")*(('Jul 30'!$AM$8:$AM$42="Y")+('Jul 30'!$AN$8:$AN$42="Y")+('Jul 30'!$AO$8:$AO$42="Y")))+SUMPRODUCT(('Jul 31'!$AG$8:$AG$42="Delivered")*(('Jul 31'!$AM$8:$AM$42="Y")+('Jul 31'!$AN$8:$AN$42="Y")+('Jul 31'!$AO$8:$AO$42="Y"))) -> 0
