Workbook

Sheet Guide
A1: GUIDE | C1: GUIDE — HOW THIS WORKBOOK WORKS | G1: =" as of "&TEXT(TODAY(),"ddd mmm d") -> as of Sun Aug 2
C3: Gallatin Ford · Advanced Deal Log v6 · daily driver
B5: ="PVR month-to-date: "&IF('Aug 31'!$C$62=0,"— (no delivered units yet)",TEXT('Aug 31'!$C$63/'Aug 31'!$C$62,"$#,##0")&" per copy · "&'Aug 31'!$C$62&" units · "&TEXT('Aug 31'!$C$63,"$#,##0")&" total gross") -> PVR month-to-date: — (no delivered units yet)
B7: Daily flow | C7: Open today’s day tab (gold TODAY chip, or click a calendar day on the Dashboard). One deal per row: type, stock, deal#, customer, SP1/SP2, vehicle, gross, lender, ad source, status. Splits: put both reps in SP1 and SP2 — credit auto-splits ½/½. The strip at the top of every day tab shows today at a glance.
B8: Status drives everything | C8: Any deal with a Deal# counts (units, gross, pace, pay) unless its Status is Pending, Unwind or Back Out. That one rule now runs the whole book — Commissions included.
B9: Flags on the day tab | C9: Red Front Gross on a used deal = water (losing money on the front). Amber Lender / Front Gross / Ad Source = a delivered deal missing that field. Red ACV−MMR = we allowed more than the over-allowance limit above MMR (tune limits on Staff & Lists → BENCHMARKS).
B10: Dashboard | C10: Live month roll-up: MTD cards, goal & pace band with projected finish (▲/▼ vs goal), clickable calendar, salesperson leaderboard, channel mix, products, and the USED DESK & F&I INTEL band — used:new ratio, water count, wholesale %, product penetration vs target, PVR, per-F&I-manager split.
B11: Deal Explorer | C11: Every deal in one table. Use the header filter arrows, or set the criteria row (Salesperson matches SP1 or SP2, Type, Status, Certified, Min Gross, Search) and filter the ✓ column.
B12: Commissions | C12: Retro pay: final monthly units set the tier for every deal. Draw is entered by payroll (yellow column); Balance = Earnings − Draw. Six internal audits sit under the table.
B13: Trade Report | C13: Per-day trades, turned-in vs kept, ACV, wholesaled count, ACV−MMR spread and aged-kept flags (⏰ after the turn-in deadline). Recap row grades appraisal capture and immediate-wholesale % against the benchmarks.
B14: Nightly Text | C14: Fill the yellow live inputs, wait for “✅ READY TO COPY”, then copy the box at the bottom into Teams. Day-override cell re-runs a prior day. Pace cells show projected units and gross.
B15: Goals, Benchmarks & Pay Plan | C15: Set monthly goals on Goals (yellow). Tune targets on Staff & Lists → BENCHMARKS (yellow) — every flag and verdict reads them live. Pay Plan (hidden tab) is the single source of truth for commission math.

Sheet Goals
A1: GALLATIN FORD — AUGUST 2026 GOALS
A4: MONTH FACTS
A5: Month | C5: August 2026
A6: Days in Month | C6: 31
A7: Closed (Sundays) | C7: 5
A8: Selling Days | C8: 26
A10: MONTHLY GOALS
B11: Units | C11: Gross
A12: New
A13: Used
A14: Total | B14: =IF(COUNT(B12:B13)=0,"",SUM(B12:B13)) | C14: =IF(COUNT(C12:C13)=0,"",SUM(C12:C13))
A17: PVR GOALS (per copy)
A18: Front PVR
A19: Back PVR
A20: Total PVR | B20: =IF(COUNT(B18:B19)=0,"",SUM(B18:B19))
A23: PER-SELLING-DAY TARGETS
A24: Units / Day | B24: =IF(OR($C$8="",$C$8=0,B14=""),"",ROUND(B14/$C$8,1))
A25: Gross / Day | B25: =IF(OR($C$8="",$C$8=0,C14=""),"",ROUND(C14/$C$8,0))
A28: CONSISTENCY CHECK (±2%)
A29: =IF(OR(B14="",C14="",B18="",B19=""),"-",IF(ABS(B14*(B18+B19)-C14)<=0.02*C14,"✓ CONSISTENT — units × PVR ≈ gross goal","⚠ CHECK — units × PVR ≠ gross goal (±2%)")) -> -

Sheet Scoreboard
A1: SCOREBOARD | C1: SCOREBOARD — AUGUST 2026 | E1: =" as of "&TEXT(TODAY(),"ddd mmm d") -> as of Sun Aug 2
C3: Goal vs month-to-date · blank until goals + deals are entered
A6: UNITS
C7: Goal | D7: MTD | E7: % Goal | F7: To Go
B8: New | C8: =IF(GoalUnitsNew="","-",GoalUnitsNew) -> - | D8: =$B$36 -> 0 | E8: =IF(OR(GoalUnitsNew="",GoalUnitsNew=0),"-",$B$36/GoalUnitsNew) -> - | F8: =IF(GoalUnitsNew="","-",MAX(0,GoalUnitsNew-$B$36)) -> - | G8: =IF(OR($C8="-",N($C8)=0),"",REPT("█",MIN(20,ROUND($D8/$C8*20,0)))&IF($D8>=$C8," ✔",""))
B9: Used | C9: =IF(GoalUnitsUsed="","-",GoalUnitsUsed) -> - | D9: =$B$37 -> 0 | E9: =IF(OR(GoalUnitsUsed="",GoalUnitsUsed=0),"-",$B$37/GoalUnitsUsed) -> - | F9: =IF(GoalUnitsUsed="","-",MAX(0,GoalUnitsUsed-$B$37)) -> - | G9: =IF(OR($C9="-",N($C9)=0),"",REPT("█",MIN(20,ROUND($D9/$C9*20,0)))&IF($D9>=$C9," ✔",""))
B10: Total | C10: =IF(GoalUnitsTotal="","-",GoalUnitsTotal) -> - | D10: ='Aug 31'!$C$62 -> 0 | E10: =IF(OR(GoalUnitsTotal="",GoalUnitsTotal=0),"-",'Aug 31'!$C$62/GoalUnitsTotal) -> - | F10: =IF(GoalUnitsTotal="","-",MAX(0,GoalUnitsTotal-'Aug 31'!$C$62)) -> - | G10: =IF(OR($C10="-",N($C10)=0),"",REPT("█",MIN(20,ROUND($D10/$C10*20,0)))&IF($D10>=$C10," ✔",""))
A12: GROSS
C13: Goal | D13: MTD | E13: % Goal | F13: To Go
B14: New | C14: =IF(GoalGrossNew="","-",GoalGrossNew) -> - | D14: =$B$38 -> 0 | E14: =IF(OR(GoalGrossNew="",GoalGrossNew=0),"-",$B$38/GoalGrossNew) -> - | F14: =IF(GoalGrossNew="","-",MAX(0,GoalGrossNew-$B$38)) -> - | G14: =IF(OR($C14="-",N($C14)=0),"",REPT("█",MIN(20,ROUND($D14/$C14*20,0)))&IF($D14>=$C14," ✔",""))
B15: Used | C15: =IF(GoalGrossUsed="","-",GoalGrossUsed) -> - | D15: =$B$39 -> 0 | E15: =IF(OR(GoalGrossUsed="",GoalGrossUsed=0),"-",$B$39/GoalGrossUsed) -> - | F15: =IF(GoalGrossUsed="","-",MAX(0,GoalGrossUsed-$B$39)) -> - | G15: =IF(OR($C15="-",N($C15)=0),"",REPT("█",MIN(20,ROUND($D15/$C15*20,0)))&IF($D15>=$C15," ✔",""))
B16: Total | C16: =IF(GoalGrossTotal="","-",GoalGrossTotal) -> - | D16: ='Aug 31'!$C$63 -> 0 | E16: =IF(OR(GoalGrossTotal="",GoalGrossTotal=0),"-",'Aug 31'!$C$63/GoalGrossTotal) -> - | F16: =IF(GoalGrossTotal="","-",MAX(0,GoalGrossTotal-'Aug 31'!$C$63)) -> - | G16: =IF(OR($C16="-",N($C16)=0),"",REPT("█",MIN(20,ROUND($D16/$C16*20,0)))&IF($D16>=$C16," ✔",""))
A18: PVR & PACE
B19: PVR (MTD) | C19: goal | D19: =IF('Aug 31'!$C$62=0,"-",'Aug 31'!$C$63/'Aug 31'!$C$62) -> - | E19: =IF(GoalPVRTotal="","-",GoalPVRTotal) -> -
B20: Selling days left | D20: =Dashboard!$BT$5 -> 25
B21: % to unit goal | D21: =IF(OR(GoalUnitsTotal="",GoalUnitsTotal=0),"-",'Aug 31'!$C$62/GoalUnitsTotal) -> -
B22: % to gross goal | D22: =IF(OR(GoalGrossTotal="",GoalGrossTotal=0),"-",'Aug 31'!$C$63/GoalGrossTotal) -> -
B24: PACE — projected finish
B25: Units | C25: =IF(Dashboard!$BT$4=0,"-",ROUND('Aug 31'!$C$62/Dashboard!$BT$4*GoalSellingDays,1)) -> 0 | D25: =IF(OR(GoalUnitsTotal="",C25="-"),"-",IF(C25>=GoalUnitsTotal,"▲ +"&TEXT(C25-GoalUnitsTotal,"0.0"),"▼ "&TEXT(C25-GoalUnitsTotal,"0.0"))) -> -
B26: Gross | C26: =IF(Dashboard!$BT$4=0,"-",ROUND('Aug 31'!$C$63/Dashboard!$BT$4*GoalSellingDays,0)) -> 0 | D26: =IF(OR(GoalGrossTotal="",C26="-"),"-",IF(C26>=GoalGrossTotal,"▲ "&TEXT(C26-GoalGrossTotal,"$#,##0"),"▼ "&TEXT(C26-GoalGrossTotal,"$#,##0"))) -> -
B36: ='Aug 1'!$C$46+'Aug 2'!$C$46+'Aug 3'!$C$46+'Aug 4'!$C$46+'Aug 5'!$C$46+'Aug 6'!$C$46+'Aug 7'!$C$46+'Aug 8'!$C$46+'Aug 9'!$C$46+'Aug 10'!$C$46+'Aug 11'!$C$46+'Aug 12'!$C$46+'Aug 13'!$C$46+'Aug 14'!$C$46+'Aug 15'!$C$46+'Aug 16'!$C$46+'Aug 17'!$C$46+'Aug 18'!$C$46+'Aug 19'!$C$46+'Aug 20'!$C$46+'Aug 21'!$C$46+'Aug 22'!$C$46+'Aug 23'!$C$46+'Aug 24'!$C$46+'Aug 25'!$C$46+'Aug 26'!$C$46+'Aug 27'!$C$46+'Aug 28'!$C$46+'Aug 29'!$C$46+'Aug 30'!$C$46+'Aug 31'!$C$46 -> 0
B37: ='Aug 1'!$E$46+'Aug 2'!$E$46+'Aug 3'!$E$46+'Aug 4'!$E$46+'Aug 5'!$E$46+'Aug 6'!$E$46+'Aug 7'!$E$46+'Aug 8'!$E$46+'Aug 9'!$E$46+'Aug 10'!$E$46+'Aug 11'!$E$46+'Aug 12'!$E$46+'Aug 13'!$E$46+'Aug 14'!$E$46+'Aug 15'!$E$46+'Aug 16'!$E$46+'Aug 17'!$E$46+'Aug 18'!$E$46+'Aug 19'!$E$46+'Aug 20'!$E$46+'Aug 21'!$E$46+'Aug 22'!$E$46+'Aug 23'!$E$46+'Aug 24'!$E$46+'Aug 25'!$E$46+'Aug 26'!$E$46+'Aug 27'!$E$46+'Aug 28'!$E$46+'Aug 29'!$E$46+'Aug 30'!$E$46+'Aug 31'!$E$46 -> 0
B38: ='Aug 1'!$C$49+'Aug 2'!$C$49+'Aug 3'!$C$49+'Aug 4'!$C$49+'Aug 5'!$C$49+'Aug 6'!$C$49+'Aug 7'!$C$49+'Aug 8'!$C$49+'Aug 9'!$C$49+'Aug 10'!$C$49+'Aug 11'!$C$49+'Aug 12'!$C$49+'Aug 13'!$C$49+'Aug 14'!$C$49+'Aug 15'!$C$49+'Aug 16'!$C$49+'Aug 17'!$C$49+'Aug 18'!$C$49+'Aug 19'!$C$49+'Aug 20'!$C$49+'Aug 21'!$C$49+'Aug 22'!$C$49+'Aug 23'!$C$49+'Aug 24'!$C$49+'Aug 25'!$C$49+'Aug 26'!$C$49+'Aug 27'!$C$49+'Aug 28'!$C$49+'Aug 29'!$C$49+'Aug 30'!$C$49+'Aug 31'!$C$49 -> 0
B39: ='Aug 1'!$E$49+'Aug 2'!$E$49+'Aug 3'!$E$49+'Aug 4'!$E$49+'Aug 5'!$E$49+'Aug 6'!$E$49+'Aug 7'!$E$49+'Aug 8'!$E$49+'Aug 9'!$E$49+'Aug 10'!$E$49+'Aug 11'!$E$49+'Aug 12'!$E$49+'Aug 13'!$E$49+'Aug 14'!$E$49+'Aug 15'!$E$49+'Aug 16'!$E$49+'Aug 17'!$E$49+'Aug 18'!$E$49+'Aug 19'!$E$49+'Aug 20'!$E$49+'Aug 21'!$E$49+'Aug 22'!$E$49+'Aug 23'!$E$49+'Aug 24'!$E$49+'Aug 25'!$E$49+'Aug 26'!$E$49+'Aug 27'!$E$49+'Aug 28'!$E$49+'Aug 29'!$E$49+'Aug 30'!$E$49+'Aug 31'!$E$49 -> 0

Sheet Deal Explorer
A1: DEAL EXPLORER | C1: DEAL EXPLORER — AUGUST 2026
C3: Every deal in the month, one filterable ledger · set criteria below, then filter the ✓ column (Data → Reapply)
B4: Salesperson (SP1 or SP2) | D4: Type | E4: Status | G4: Cert? | H4: Min Gross | I4: Search text
B6: ="Showing "&COUNTIF(A8:A1092,"✓")&" of "&SUMPRODUCT(($C$8:$C$1092<>"")*($C$8:$C$1092<>0))&" deals booked this month" -> Showing 0 of 0 deals booked this month
A7: ✓ | B7: Date | C7: Deal# | D7: Stock | E7: Customer | F7: Type | G7: SP1 | H7: SP2 | I7: Vehicle | J7: Gross | K7: Status | L7: Cert
A8: =IF(OR(C8="",C8=0),"",IF(AND(OR($B$5="",G8=$B$5,H8=$B$5),OR($D$5="",F8=$D$5),OR($E$5="",K8=$E$5),OR($G$5="",L8=$G$5),OR($H$5="",N(J8)>=$H$5),OR($I$5="",ISNUMBER(SEARCH($I$5,C8&" "&D8&" "&E8&" "&I8)))),"✓","")) | B8: 46235 | C8: ='Aug 1'!$D$8 -> 0 | D8: ='Aug 1'!$B$8 -> 0 | E8: ='Aug 1'!$E$8 -> 0 | F8: ='Aug 1'!$A$8 -> 0 | G8: ='Aug 1'!$F$8 -> 0 | H8: ='Aug 1'!$G$8 -> 0 | I8: ='Aug 1'!$M$8 | J8: ='Aug 1'!$S$8 | K8: ='Aug 1'!$AG$8 -> 0 | L8: ='Aug 1'!$N$8 -> 0
A9: =IF(OR(C9="",C9=0),"",IF(AND(OR($B$5="",G9=$B$5,H9=$B$5),OR($D$5="",F9=$D$5),OR($E$5="",K9=$E$5),OR($G$5="",L9=$G$5),OR($H$5="",N(J9)>=$H$5),OR($I$5="",ISNUMBER(SEARCH($I$5,C9&" "&D9&" "&E9&" "&I9)))),"✓","")) | B9: 46235 | C9: ='Aug 1'!$D$9 -> 0 | D9: ='Aug 1'!$B$9 -> 0 | E9: ='Aug 1'!$E$9 -> 0 | F9: ='Aug 1'!$A$9 -> 0 | G9: ='Aug 1'!$F$9 -> 0 | H9: ='Aug 1'!$G$9 -> 0 | I9: ='Aug 1'!$M$9 | J9: ='Aug 1'!$S$9 | K9: ='Aug 1'!$AG$9 -> 0 | L9: ='Aug 1'!$N$9 -> 0
A10: =IF(OR(C10="",C10=0),"",IF(AND(OR($B$5="",G10=$B$5,H10=$B$5),OR($D$5="",F10=$D$5),OR($E$5="",K10=$E$5),OR($G$5="",L10=$G$5),OR($H$5="",N(J10)>=$H$5),OR($I$5="",ISNUMBER(SEARCH($I$5,C10&" "&D10&" "&E10&" "&I10)))),"✓","")) | B10: 46235 | C10: ='Aug 1'!$D$10 -> 0 | D10: ='Aug 1'!$B$10 -> 0 | E10: ='Aug 1'!$E$10 -> 0 | F10: ='Aug 1'!$A$10 -> 0 | G10: ='Aug 1'!$F$10 -> 0 | H10: ='Aug 1'!$G$10 -> 0 | I10: ='Aug 1'!$M$10 | J10: ='Aug 1'!$S$10 | K10: ='Aug 1'!$AG$10 -> 0 | L10: ='Aug 1'!$N$10 -> 0
A11: =IF(OR(C11="",C11=0),"",IF(AND(OR($B$5="",G11=$B$5,H11=$B$5),OR($D$5="",F11=$D$5),OR($E$5="",K11=$E$5),OR($G$5="",L11=$G$5),OR($H$5="",N(J11)>=$H$5),OR($I$5="",ISNUMBER(SEARCH($I$5,C11&" "&D11&" "&E11&" "&I11)))),"✓","")) | B11: 46235 | C11: ='Aug 1'!$D$11 -> 0 | D11: ='Aug 1'!$B$11 -> 0 | E11: ='Aug 1'!$E$11 -> 0 | F11: ='Aug 1'!$A$11 -> 0 | G11: ='Aug 1'!$F$11 -> 0 | H11: ='Aug 1'!$G$11 -> 0 | I11: ='Aug 1'!$M$11 | J11: ='Aug 1'!$S$11 | K11: ='Aug 1'!$AG$11 -> 0 | L11: ='Aug 1'!$N$11 -> 0
A12: =IF(OR(C12="",C12=0),"",IF(AND(OR($B$5="",G12=$B$5,H12=$B$5),OR($D$5="",F12=$D$5),OR($E$5="",K12=$E$5),OR($G$5="",L12=$G$5),OR($H$5="",N(J12)>=$H$5),OR($I$5="",ISNUMBER(SEARCH($I$5,C12&" "&D12&" "&E12&" "&I12)))),"✓","")) | B12: 46235 | C12: ='Aug 1'!$D$12 -> 0 | D12: ='Aug 1'!$B$12 -> 0 | E12: ='Aug 1'!$E$12 -> 0 | F12: ='Aug 1'!$A$12 -> 0 | G12: ='Aug 1'!$F$12 -> 0 | H12: ='Aug 1'!$G$12 -> 0 | I12: ='Aug 1'!$M$12 | J12: ='Aug 1'!$S$12 | K12: ='Aug 1'!$AG$12 -> 0 | L12: ='Aug 1'!$N$12 -> 0
A13: =IF(OR(C13="",C13=0),"",IF(AND(OR($B$5="",G13=$B$5,H13=$B$5),OR($D$5="",F13=$D$5),OR($E$5="",K13=$E$5),OR($G$5="",L13=$G$5),OR($H$5="",N(J13)>=$H$5),OR($I$5="",ISNUMBER(SEARCH($I$5,C13&" "&D13&" "&E13&" "&I13)))),"✓","")) | B13: 46235 | C13: ='Aug 1'!$D$13 -> 0 | D13: ='Aug 1'!$B$13 -> 0 | E13: ='Aug 1'!$E$13 -> 0 | F13: ='Aug 1'!$A$13 -> 0 | G13: ='Aug 1'!$F$13 -> 0 | H13: ='Aug 1'!$G$13 -> 0 | I13: ='Aug 1'!$M$13 | J13: ='Aug 1'!$S$13 | K13: ='Aug 1'!$AG$13 -> 0 | L13: ='Aug 1'!$N$13 -> 0
A14: =IF(OR(C14="",C14=0),"",IF(AND(OR($B$5="",G14=$B$5,H14=$B$5),OR($D$5="",F14=$D$5),OR($E$5="",K14=$E$5),OR($G$5="",L14=$G$5),OR($H$5="",N(J14)>=$H$5),OR($I$5="",ISNUMBER(SEARCH($I$5,C14&" "&D14&" "&E14&" "&I14)))),"✓","")) | B14: 46235 | C14: ='Aug 1'!$D$14 -> 0 | D14: ='Aug 1'!$B$14 -> 0 | E14: ='Aug 1'!$E$14 -> 0 | F14: ='Aug 1'!$A$14 -> 0 | G14: ='Aug 1'!$F$14 -> 0 | H14: ='Aug 1'!$G$14 -> 0 | I14: ='Aug 1'!$M$14 | J14: ='Aug 1'!$S$14 | K14: ='Aug 1'!$AG$14 -> 0 | L14: ='Aug 1'!$N$14 -> 0
A15: =IF(OR(C15="",C15=0),"",IF(AND(OR($B$5="",G15=$B$5,H15=$B$5),OR($D$5="",F15=$D$5),OR($E$5="",K15=$E$5),OR($G$5="",L15=$G$5),OR($H$5="",N(J15)>=$H$5),OR($I$5="",ISNUMBER(SEARCH($I$5,C15&" "&D15&" "&E15&" "&I15)))),"✓","")) | B15: 46235 | C15: ='Aug 1'!$D$15 -> 0 | D15: ='Aug 1'!$B$15 -> 0 | E15: ='Aug 1'!$E$15 -> 0 | F15: ='Aug 1'!$A$15 -> 0 | G15: ='Aug 1'!$F$15 -> 0 | H15: ='Aug 1'!$G$15 -> 0 | I15: ='Aug 1'!$M$15 | J15: ='Aug 1'!$S$15 | K15: ='Aug 1'!$AG$15 -> 0 | L15: ='Aug 1'!$N$15 -> 0
A16: =IF(OR(C16="",C16=0),"",IF(AND(OR($B$5="",G16=$B$5,H16=$B$5),OR($D$5="",F16=$D$5),OR($E$5="",K16=$E$5),OR($G$5="",L16=$G$5),OR($H$5="",N(J16)>=$H$5),OR($I$5="",ISNUMBER(SEARCH($I$5,C16&" "&D16&" "&E16&" "&I16)))),"✓","")) | B16: 46235 | C16: ='Aug 1'!$D$16 -> 0 | D16: ='Aug 1'!$B$16 -> 0 | E16: ='Aug 1'!$E$16 -> 0 | F16: ='Aug 1'!$A$16 -> 0 | G16: ='Aug 1'!$F$16 -> 0 | H16: ='Aug 1'!$G$16 -> 0 | I16: ='Aug 1'!$M$16 | J16: ='Aug 1'!$S$16 | K16: ='Aug 1'!$AG$16 -> 0 | L16: ='Aug 1'!$N$16 -> 0
A17: =IF(OR(C17="",C17=0),"",IF(AND(OR($B$5="",G17=$B$5,H17=$B$5),OR($D$5="",F17=$D$5),OR($E$5="",K17=$E$5),OR($G$5="",L17=$G$5),OR($H$5="",N(J17)>=$H$5),OR($I$5="",ISNUMBER(SEARCH($I$5,C17&" "&D17&" "&E17&" "&I17)))),"✓","")) | B17: 46235 | C17: ='Aug 1'!$D$17 -> 0 | D17: ='Aug 1'!$B$17 -> 0 | E17: ='Aug 1'!$E$17 -> 0 | F17: ='Aug 1'!$A$17 -> 0 | G17: ='Aug 1'!$F$17 -> 0 | H17: ='Aug 1'!$G$17 -> 0 | I17: ='Aug 1'!$M$17 | J17: ='Aug 1'!$S$17 | K17: ='Aug 1'!$AG$17 -> 0 | L17: ='Aug 1'!$N$17 -> 0
A18: =IF(OR(C18="",C18=0),"",IF(AND(OR($B$5="",G18=$B$5,H18=$B$5),OR($D$5="",F18=$D$5),OR($E$5="",K18=$E$5),OR($G$5="",L18=$G$5),OR($H$5="",N(J18)>=$H$5),OR($I$5="",ISNUMBER(SEARCH($I$5,C18&" "&D18&" "&E18&" "&I18)))),"✓","")) | B18: 46235 | C18: ='Aug 1'!$D$18 -> 0 | D18: ='Aug 1'!$B$18 -> 0 | E18: ='Aug 1'!$E$18 -> 0 | F18: ='Aug 1'!$A$18 -> 0 | G18: ='Aug 1'!$F$18 -> 0 | H18: ='Aug 1'!$G$18 -> 0 | I18: ='Aug 1'!$M$18 | J18: ='Aug 1'!$S$18 | K18: ='Aug 1'!$AG$18 -> 0 | L18: ='Aug 1'!$N$18 -> 0
A19: =IF(OR(C19="",C19=0),"",IF(AND(OR($B$5="",G19=$B$5,H19=$B$5),OR($D$5="",F19=$D$5),OR($E$5="",K19=$E$5),OR($G$5="",L19=$G$5),OR($H$5="",N(J19)>=$H$5),OR($I$5="",ISNUMBER(SEARCH($I$5,C19&" "&D19&" "&E19&" "&I19)))),"✓","")) | B19: 46235 | C19: ='Aug 1'!$D$19 -> 0 | D19: ='Aug 1'!$B$19 -> 0 | E19: ='Aug 1'!$E$19 -> 0 | F19: ='Aug 1'!$A$19 -> 0 | G19: ='Aug 1'!$F$19 -> 0 | H19: ='Aug 1'!$G$19 -> 0 | I19: ='Aug 1'!$M$19 | J19: ='Aug 1'!$S$19 | K19: ='Aug 1'!$AG$19 -> 0 | L19: ='Aug 1'!$N$19 -> 0
A20: =IF(OR(C20="",C20=0),"",IF(AND(OR($B$5="",G20=$B$5,H20=$B$5),OR($D$5="",F20=$D$5),OR($E$5="",K20=$E$5),OR($G$5="",L20=$G$5),OR($H$5="",N(J20)>=$H$5),OR($I$5="",ISNUMBER(SEARCH($I$5,C20&" "&D20&" "&E20&" "&I20)))),"✓","")) | B20: 46235 | C20: ='Aug 1'!$D$20 -> 0 | D20: ='Aug 1'!$B$20 -> 0 | E20: ='Aug 1'!$E$20 -> 0 | F20: ='Aug 1'!$A$20 -> 0 | G20: ='Aug 1'!$F$20 -> 0 | H20: ='Aug 1'!$G$20 -> 0 | I20: ='Aug 1'!$M$20 | J20: ='Aug 1'!$S$20 | K20: ='Aug 1'!$AG$20 -> 0 | L20: ='Aug 1'!$N$20 -> 0
A21: =IF(OR(C21="",C21=0),"",IF(AND(OR($B$5="",G21=$B$5,H21=$B$5),OR($D$5="",F21=$D$5),OR($E$5="",K21=$E$5),OR($G$5="",L21=$G$5),OR($H$5="",N(J21)>=$H$5),OR($I$5="",ISNUMBER(SEARCH($I$5,C21&" "&D21&" "&E21&" "&I21)))),"✓","")) | B21: 46235 | C21: ='Aug 1'!$D$21 -> 0 | D21: ='Aug 1'!$B$21 -> 0 | E21: ='Aug 1'!$E$21 -> 0 | F21: ='Aug 1'!$A$21 -> 0 | G21: ='Aug 1'!$F$21 -> 0 | H21: ='Aug 1'!$G$21 -> 0 | I21: ='Aug 1'!$M$21 | J21: ='Aug 1'!$S$21 | K21: ='Aug 1'!$AG$21 -> 0 | L21: ='Aug 1'!$N$21 -> 0
A22: =IF(OR(C22="",C22=0),"",IF(AND(OR($B$5="",G22=$B$5,H22=$B$5),OR($D$5="",F22=$D$5),OR($E$5="",K22=$E$5),OR($G$5="",L22=$G$5),OR($H$5="",N(J22)>=$H$5),OR($I$5="",ISNUMBER(SEARCH($I$5,C22&" "&D22&" "&E22&" "&I22)))),"✓","")) | B22: 46235 | C22: ='Aug 1'!$D$22 -> 0 | D22: ='Aug 1'!$B$22 -> 0 | E22: ='Aug 1'!$E$22 -> 0 | F22: ='Aug 1'!$A$22 -> 0 | G22: ='Aug 1'!$F$22 -> 0 | H22: ='Aug 1'!$G$22 -> 0 | I22: ='Aug 1'!$M$22 | J22: ='Aug 1'!$S$22 | K22: ='Aug 1'!$AG$22 -> 0 | L22: ='Aug 1'!$N$22 -> 0
A23: =IF(OR(C23="",C23=0),"",IF(AND(OR($B$5="",G23=$B$5,H23=$B$5),OR($D$5="",F23=$D$5),OR($E$5="",K23=$E$5),OR($G$5="",L23=$G$5),OR($H$5="",N(J23)>=$H$5),OR($I$5="",ISNUMBER(SEARCH($I$5,C23&" "&D23&" "&E23&" "&I23)))),"✓","")) | B23: 46235 | C23: ='Aug 1'!$D$23 -> 0 | D23: ='Aug 1'!$B$23 -> 0 | E23: ='Aug 1'!$E$23 -> 0 | F23: ='Aug 1'!$A$23 -> 0 | G23: ='Aug 1'!$F$23 -> 0 | H23: ='Aug 1'!$G$23 -> 0 | I23: ='Aug 1'!$M$23 | J23: ='Aug 1'!$S$23 | K23: ='Aug 1'!$AG$23 -> 0 | L23: ='Aug 1'!$N$23 -> 0
A24: =IF(OR(C24="",C24=0),"",IF(AND(OR($B$5="",G24=$B$5,H24=$B$5),OR($D$5="",F24=$D$5),OR($E$5="",K24=$E$5),OR($G$5="",L24=$G$5),OR($H$5="",N(J24)>=$H$5),OR($I$5="",ISNUMBER(SEARCH($I$5,C24&" "&D24&" "&E24&" "&I24)))),"✓","")) | B24: 46235 | C24: ='Aug 1'!$D$24 -> 0 | D24: ='Aug 1'!$B$24 -> 0 | E24: ='Aug 1'!$E$24 -> 0 | F24: ='Aug 1'!$A$24 -> 0 | G24: ='Aug 1'!$F$24 -> 0 | H24: ='Aug 1'!$G$24 -> 0 | I24: ='Aug 1'!$M$24 | J24: ='Aug 1'!$S$24 | K24: ='Aug 1'!$AG$24 -> 0 | L24: ='Aug 1'!$N$24 -> 0
A25: =IF(OR(C25="",C25=0),"",IF(AND(OR($B$5="",G25=$B$5,H25=$B$5),OR($D$5="",F25=$D$5),OR($E$5="",K25=$E$5),OR($G$5="",L25=$G$5),OR($H$5="",N(J25)>=$H$5),OR($I$5="",ISNUMBER(SEARCH($I$5,C25&" "&D25&" "&E25&" "&I25)))),"✓","")) | B25: 46235 | C25: ='Aug 1'!$D$25 -> 0 | D25: ='Aug 1'!$B$25 -> 0 | E25: ='Aug 1'!$E$25 -> 0 | F25: ='Aug 1'!$A$25 -> 0 | G25: ='Aug 1'!$F$25 -> 0 | H25: ='Aug 1'!$G$25 -> 0 | I25: ='Aug 1'!$M$25 | J25: ='Aug 1'!$S$25 | K25: ='Aug 1'!$AG$25 -> 0 | L25: ='Aug 1'!$N$25 -> 0
A26: =IF(OR(C26="",C26=0),"",IF(AND(OR($B$5="",G26=$B$5,H26=$B$5),OR($D$5="",F26=$D$5),OR($E$5="",K26=$E$5),OR($G$5="",L26=$G$5),OR($H$5="",N(J26)>=$H$5),OR($I$5="",ISNUMBER(SEARCH($I$5,C26&" "&D26&" "&E26&" "&I26)))),"✓","")) | B26: 46235 | C26: ='Aug 1'!$D$26 -> 0 | D26: ='Aug 1'!$B$26 -> 0 | E26: ='Aug 1'!$E$26 -> 0 | F26: ='Aug 1'!$A$26 -> 0 | G26: ='Aug 1'!$F$26 -> 0 | H26: ='Aug 1'!$G$26 -> 0 | I26: ='Aug 1'!$M$26 | J26: ='Aug 1'!$S$26 | K26: ='Aug 1'!$AG$26 -> 0 | L26: ='Aug 1'!$N$26 -> 0
A27: =IF(OR(C27="",C27=0),"",IF(AND(OR($B$5="",G27=$B$5,H27=$B$5),OR($D$5="",F27=$D$5),OR($E$5="",K27=$E$5),OR($G$5="",L27=$G$5),OR($H$5="",N(J27)>=$H$5),OR($I$5="",ISNUMBER(SEARCH($I$5,C27&" "&D27&" "&E27&" "&I27)))),"✓","")) | B27: 46235 | C27: ='Aug 1'!$D$27 -> 0 | D27: ='Aug 1'!$B$27 -> 0 | E27: ='Aug 1'!$E$27 -> 0 | F27: ='Aug 1'!$A$27 -> 0 | G27: ='Aug 1'!$F$27 -> 0 | H27: ='Aug 1'!$G$27 -> 0 | I27: ='Aug 1'!$M$27 | J27: ='Aug 1'!$S$27 | K27: ='Aug 1'!$AG$27 -> 0 | L27: ='Aug 1'!$N$27 -> 0
A28: =IF(OR(C28="",C28=0),"",IF(AND(OR($B$5="",G28=$B$5,H28=$B$5),OR($D$5="",F28=$D$5),OR($E$5="",K28=$E$5),OR($G$5="",L28=$G$5),OR($H$5="",N(J28)>=$H$5),OR($I$5="",ISNUMBER(SEARCH($I$5,C28&" "&D28&" "&E28&" "&I28)))),"✓","")) | B28: 46235 | C28: ='Aug 1'!$D$28 -> 0 | D28: ='Aug 1'!$B$28 -> 0 | E28: ='Aug 1'!$E$28 -> 0 | F28: ='Aug 1'!$A$28 -> 0 | G28: ='Aug 1'!$F$28 -> 0 | H28: ='Aug 1'!$G$28 -> 0 | I28: ='Aug 1'!$M$28 | J28: ='Aug 1'!$S$28 | K28: ='Aug 1'!$AG$28 -> 0 | L28: ='Aug 1'!$N$28 -> 0
A29: =IF(OR(C29="",C29=0),"",IF(AND(OR($B$5="",G29=$B$5,H29=$B$5),OR($D$5="",F29=$D$5),OR($E$5="",K29=$E$5),OR($G$5="",L29=$G$5),OR($H$5="",N(J29)>=$H$5),OR($I$5="",ISNUMBER(SEARCH($I$5,C29&" "&D29&" "&E29&" "&I29)))),"✓","")) | B29: 46235 | C29: ='Aug 1'!$D$29 -> 0 | D29: ='Aug 1'!$B$29 -> 0 | E29: ='Aug 1'!$E$29 -> 0 | F29: ='Aug 1'!$A$29 -> 0 | G29: ='Aug 1'!$F$29 -> 0 | H29: ='Aug 1'!$G$29 -> 0 | I29: ='Aug 1'!$M$29 | J29: ='Aug 1'!$S$29 | K29: ='Aug 1'!$AG$29 -> 0 | L29: ='Aug 1'!$N$29 -> 0
A30: =IF(OR(C30="",C30=0),"",IF(AND(OR($B$5="",G30=$B$5,H30=$B$5),OR($D$5="",F30=$D$5),OR($E$5="",K30=$E$5),OR($G$5="",L30=$G$5),OR($H$5="",N(J30)>=$H$5),OR($I$5="",ISNUMBER(SEARCH($I$5,C30&" "&D30&" "&E30&" "&I30)))),"✓","")) | B30: 46235 | C30: ='Aug 1'!$D$30 -> 0 | D30: ='Aug 1'!$B$30 -> 0 | E30: ='Aug 1'!$E$30 -> 0 | F30: ='Aug 1'!$A$30 -> 0 | G30: ='Aug 1'!$F$30 -> 0 | H30: ='Aug 1'!$G$30 -> 0 | I30: ='Aug 1'!$M$30 | J30: ='Aug 1'!$S$30 | K30: ='Aug 1'!$AG$30 -> 0 | L30: ='Aug 1'!$N$30 -> 0
A31: =IF(OR(C31="",C31=0),"",IF(AND(OR($B$5="",G31=$B$5,H31=$B$5),OR($D$5="",F31=$D$5),OR($E$5="",K31=$E$5),OR($G$5="",L31=$G$5),OR($H$5="",N(J31)>=$H$5),OR($I$5="",ISNUMBER(SEARCH($I$5,C31&" "&D31&" "&E31&" "&I31)))),"✓","")) | B31: 46235 | C31: ='Aug 1'!$D$31 -> 0 | D31: ='Aug 1'!$B$31 -> 0 | E31: ='Aug 1'!$E$31 -> 0 | F31: ='Aug 1'!$A$31 -> 0 | G31: ='Aug 1'!$F$31 -> 0 | H31: ='Aug 1'!$G$31 -> 0 | I31: ='Aug 1'!$M$31 | J31: ='Aug 1'!$S$31 | K31: ='Aug 1'!$AG$31 -> 0 | L31: ='Aug 1'!$N$31 -> 0
A32: =IF(OR(C32="",C32=0),"",IF(AND(OR($B$5="",G32=$B$5,H32=$B$5),OR($D$5="",F32=$D$5),OR($E$5="",K32=$E$5),OR($G$5="",L32=$G$5),OR($H$5="",N(J32)>=$H$5),OR($I$5="",ISNUMBER(SEARCH($I$5,C32&" "&D32&" "&E32&" "&I32)))),"✓","")) | B32: 46235 | C32: ='Aug 1'!$D$32 -> 0 | D32: ='Aug 1'!$B$32 -> 0 | E32: ='Aug 1'!$E$32 -> 0 | F32: ='Aug 1'!$A$32 -> 0 | G32: ='Aug 1'!$F$32 -> 0 | H32: ='Aug 1'!$G$32 -> 0 | I32: ='Aug 1'!$M$32 | J32: ='Aug 1'!$S$32 | K32: ='Aug 1'!$AG$32 -> 0 | L32: ='Aug 1'!$N$32 -> 0
A33: =IF(OR(C33="",C33=0),"",IF(AND(OR($B$5="",G33=$B$5,H33=$B$5),OR($D$5="",F33=$D$5),OR($E$5="",K33=$E$5),OR($G$5="",L33=$G$5),OR($H$5="",N(J33)>=$H$5),OR($I$5="",ISNUMBER(SEARCH($I$5,C33&" "&D33&" "&E33&" "&I33)))),"✓","")) | B33: 46235 | C33: ='Aug 1'!$D$33 -> 0 | D33: ='Aug 1'!$B$33 -> 0 | E33: ='Aug 1'!$E$33 -> 0 | F33: ='Aug 1'!$A$33 -> 0 | G33: ='Aug 1'!$F$33 -> 0 | H33: ='Aug 1'!$G$33 -> 0 | I33: ='Aug 1'!$M$33 | J33: ='Aug 1'!$S$33 | K33: ='Aug 1'!$AG$33 -> 0 | L33: ='Aug 1'!$N$33 -> 0
A34: =IF(OR(C34="",C34=0),"",IF(AND(OR($B$5="",G34=$B$5,H34=$B$5),OR($D$5="",F34=$D$5),OR($E$5="",K34=$E$5),OR($G$5="",L34=$G$5),OR($H$5="",N(J34)>=$H$5),OR($I$5="",ISNUMBER(SEARCH($I$5,C34&" "&D34&" "&E34&" "&I34)))),"✓","")) | B34: 46235 | C34: ='Aug 1'!$D$34 -> 0 | D34: ='Aug 1'!$B$34 -> 0 | E34: ='Aug 1'!$E$34 -> 0 | F34: ='Aug 1'!$A$34 -> 0 | G34: ='Aug 1'!$F$34 -> 0 | H34: ='Aug 1'!$G$34 -> 0 | I34: ='Aug 1'!$M$34 | J34: ='Aug 1'!$S$34 | K34: ='Aug 1'!$AG$34 -> 0 | L34: ='Aug 1'!$N$34 -> 0
A35: =IF(OR(C35="",C35=0),"",IF(AND(OR($B$5="",G35=$B$5,H35=$B$5),OR($D$5="",F35=$D$5),OR($E$5="",K35=$E$5),OR($G$5="",L35=$G$5),OR($H$5="",N(J35)>=$H$5),OR($I$5="",ISNUMBER(SEARCH($I$5,C35&" "&D35&" "&E35&" "&I35)))),"✓","")) | B35: 46235 | C35: ='Aug 1'!$D$35 -> 0 | D35: ='Aug 1'!$B$35 -> 0 | E35: ='Aug 1'!$E$35 -> 0 | F35: ='Aug 1'!$A$35 -> 0 | G35: ='Aug 1'!$F$35 -> 0 | H35: ='Aug 1'!$G$35 -> 0 | I35: ='Aug 1'!$M$35 | J35: ='Aug 1'!$S$35 | K35: ='Aug 1'!$AG$35 -> 0 | L35: ='Aug 1'!$N$35 -> 0
A36: =IF(OR(C36="",C36=0),"",IF(AND(OR($B$5="",G36=$B$5,H36=$B$5),OR($D$5="",F36=$D$5),OR($E$5="",K36=$E$5),OR($G$5="",L36=$G$5),OR($H$5="",N(J36)>=$H$5),OR($I$5="",ISNUMBER(SEARCH($I$5,C36&" "&D36&" "&E36&" "&I36)))),"✓","")) | B36: 46235 | C36: ='Aug 1'!$D$36 -> 0 | D36: ='Aug 1'!$B$36 -> 0 | E36: ='Aug 1'!$E$36 -> 0 | F36: ='Aug 1'!$A$36 -> 0 | G36: ='Aug 1'!$F$36 -> 0 | H36: ='Aug 1'!$G$36 -> 0 | I36: ='Aug 1'!$M$36 | J36: ='Aug 1'!$S$36 | K36: ='Aug 1'!$AG$36 -> 0 | L36: ='Aug 1'!$N$36 -> 0
A37: =IF(OR(C37="",C37=0),"",IF(AND(OR($B$5="",G37=$B$5,H37=$B$5),OR($D$5="",F37=$D$5),OR($E$5="",K37=$E$5),OR($G$5="",L37=$G$5),OR($H$5="",N(J37)>=$H$5),OR($I$5="",ISNUMBER(SEARCH($I$5,C37&" "&D37&" "&E37&" "&I37)))),"✓","")) | B37: 46235 | C37: ='Aug 1'!$D$37 -> 0 | D37: ='Aug 1'!$B$37 -> 0 | E37: ='Aug 1'!$E$37 -> 0 | F37: ='Aug 1'!$A$37 -> 0 | G37: ='Aug 1'!$F$37 -> 0 | H37: ='Aug 1'!$G$37 -> 0 | I37: ='Aug 1'!$M$37 | J37: ='Aug 1'!$S$37 | K37: ='Aug 1'!$AG$37 -> 0 | L37: ='Aug 1'!$N$37 -> 0
A38: =IF(OR(C38="",C38=0),"",IF(AND(OR($B$5="",G38=$B$5,H38=$B$5),OR($D$5="",F38=$D$5),OR($E$5="",K38=$E$5),OR($G$5="",L38=$G$5),OR($H$5="",N(J38)>=$H$5),OR($I$5="",ISNUMBER(SEARCH($I$5,C38&" "&D38&" "&E38&" "&I38)))),"✓","")) | B38: 46235 | C38: ='Aug 1'!$D$38 -> 0 | D38: ='Aug 1'!$B$38 -> 0 | E38: ='Aug 1'!$E$38 -> 0 | F38: ='Aug 1'!$A$38 -> 0 | G38: ='Aug 1'!$F$38 -> 0 | H38: ='Aug 1'!$G$38 -> 0 | I38: ='Aug 1'!$M$38 | J38: ='Aug 1'!$S$38 | K38: ='Aug 1'!$AG$38 -> 0 | L38: ='Aug 1'!$N$38 -> 0
A39: =IF(OR(C39="",C39=0),"",IF(AND(OR($B$5="",G39=$B$5,H39=$B$5),OR($D$5="",F39=$D$5),OR($E$5="",K39=$E$5),OR($G$5="",L39=$G$5),OR($H$5="",N(J39)>=$H$5),OR($I$5="",ISNUMBER(SEARCH($I$5,C39&" "&D39&" "&E39&" "&I39)))),"✓","")) | B39: 46235 | C39: ='Aug 1'!$D$39 -> 0 | D39: ='Aug 1'!$B$39 -> 0 | E39: ='Aug 1'!$E$39 -> 0 | F39: ='Aug 1'!$A$39 -> 0 | G39: ='Aug 1'!$F$39 -> 0 | H39: ='Aug 1'!$G$39 -> 0 | I39: ='Aug 1'!$M$39 | J39: ='Aug 1'!$S$39 | K39: ='Aug 1'!$AG$39 -> 0 | L39: ='Aug 1'!$N$39 -> 0
A40: =IF(OR(C40="",C40=0),"",IF(AND(OR($B$5="",G40=$B$5,H40=$B$5),OR($D$5="",F40=$D$5),OR($E$5="",K40=$E$5),OR($G$5="",L40=$G$5),OR($H$5="",N(J40)>=$H$5),OR($I$5="",ISNUMBER(SEARCH($I$5,C40&" "&D40&" "&E40&" "&I40)))),"✓","")) | B40: 46235 | C40: ='Aug 1'!$D$40 -> 0 | D40: ='Aug 1'!$B$40 -> 0 | E40: ='Aug 1'!$E$40 -> 0 | F40: ='Aug 1'!$A$40 -> 0 | G40: ='Aug 1'!$F$40 -> 0 | H40: ='Aug 1'!$G$40 -> 0 | I40: ='Aug 1'!$M$40 | J40: ='Aug 1'!$S$40 | K40: ='Aug 1'!$AG$40 -> 0 | L40: ='Aug 1'!$N$40 -> 0
A41: =IF(OR(C41="",C41=0),"",IF(AND(OR($B$5="",G41=$B$5,H41=$B$5),OR($D$5="",F41=$D$5),OR($E$5="",K41=$E$5),OR($G$5="",L41=$G$5),OR($H$5="",N(J41)>=$H$5),OR($I$5="",ISNUMBER(SEARCH($I$5,C41&" "&D41&" "&E41&" "&I41)))),"✓","")) | B41: 46235 | C41: ='Aug 1'!$D$41 -> 0 | D41: ='Aug 1'!$B$41 -> 0 | E41: ='Aug 1'!$E$41 -> 0 | F41: ='Aug 1'!$A$41 -> 0 | G41: ='Aug 1'!$F$41 -> 0 | H41: ='Aug 1'!$G$41 -> 0 | I41: ='Aug 1'!$M$41 | J41: ='Aug 1'!$S$41 | K41: ='Aug 1'!$AG$41 -> 0 | L41: ='Aug 1'!$N$41 -> 0
A42: =IF(OR(C42="",C42=0),"",IF(AND(OR($B$5="",G42=$B$5,H42=$B$5),OR($D$5="",F42=$D$5),OR($E$5="",K42=$E$5),OR($G$5="",L42=$G$5),OR($H$5="",N(J42)>=$H$5),OR($I$5="",ISNUMBER(SEARCH($I$5,C42&" "&D42&" "&E42&" "&I42)))),"✓","")) | B42: 46235 | C42: ='Aug 1'!$D$42 -> 0 | D42: ='Aug 1'!$B$42 -> 0 | E42: ='Aug 1'!$E$42 -> 0 | F42: ='Aug 1'!$A$42 -> 0 | G42: ='Aug 1'!$F$42 -> 0 | H42: ='Aug 1'!$G$42 -> 0 | I42: ='Aug 1'!$M$42 | J42: ='Aug 1'!$S$42 | K42: ='Aug 1'!$AG$42 -> 0 | L42: ='Aug 1'!$N$42 -> 0
...

Sheet Commissions
A1: COMMISSIONS | D1: COMMISSIONS — AUGUST 2026 | N1: =" as of "&TEXT(TODAY(),"ddd mmm d") -> as of Sun Aug 2
D3: Retro pay — final monthly units set the tier for every deal · qualifying = delivered · split = ½ flat · product $ to SP1 · draws entered by payroll | T3: COMMISSIONS AGG
T4: ='Staff & Lists'!A5 -> FEDY ALI | U4: =SUMPRODUCT(('Aug 1'!$F$8:$F$42=$T4)*'Aug 1'!$AJ$8:$AJ$42+('Aug 1'!$G$8:$G$42=$T4)*'Aug 1'!$AK$8:$AK$42) -> 0 | V4: =SUMPRODUCT(('Aug 2'!$F$8:$F$42=$T4)*'Aug 2'!$AJ$8:$AJ$42+('Aug 2'!$G$8:$G$42=$T4)*'Aug 2'!$AK$8:$AK$42) -> 0 | W4: =SUMPRODUCT(('Aug 3'!$F$8:$F$42=$T4)*'Aug 3'!$AJ$8:$AJ$42+('Aug 3'!$G$8:$G$42=$T4)*'Aug 3'!$AK$8:$AK$42) -> 0 | X4: =SUMPRODUCT(('Aug 4'!$F$8:$F$42=$T4)*'Aug 4'!$AJ$8:$AJ$42+('Aug 4'!$G$8:$G$42=$T4)*'Aug 4'!$AK$8:$AK$42) -> 0 | Y4: =SUMPRODUCT(('Aug 5'!$F$8:$F$42=$T4)*'Aug 5'!$AJ$8:$AJ$42+('Aug 5'!$G$8:$G$42=$T4)*'Aug 5'!$AK$8:$AK$42) -> 0 | Z4: =SUMPRODUCT(('Aug 6'!$F$8:$F$42=$T4)*'Aug 6'!$AJ$8:$AJ$42+('Aug 6'!$G$8:$G$42=$T4)*'Aug 6'!$AK$8:$AK$42) -> 0 | AA4: =SUMPRODUCT(('Aug 7'!$F$8:$F$42=$T4)*'Aug 7'!$AJ$8:$AJ$42+('Aug 7'!$G$8:$G$42=$T4)*'Aug 7'!$AK$8:$AK$42) -> 0 | AB4: =SUMPRODUCT(('Aug 8'!$F$8:$F$42=$T4)*'Aug 8'!$AJ$8:$AJ$42+('Aug 8'!$G$8:$G$42=$T4)*'Aug 8'!$AK$8:$AK$42) -> 0 | AC4: =SUMPRODUCT(('Aug 9'!$F$8:$F$42=$T4)*'Aug 9'!$AJ$8:$AJ$42+('Aug 9'!$G$8:$G$42=$T4)*'Aug 9'!$AK$8:$AK$42) -> 0 | AD4: =SUMPRODUCT(('Aug 10'!$F$8:$F$42=$T4)*'Aug 10'!$AJ$8:$AJ$42+('Aug 10'!$G$8:$G$42=$T4)*'Aug 10'!$AK$8:$AK$42) -> 0 | AE4: =SUMPRODUCT(('Aug 11'!$F$8:$F$42=$T4)*'Aug 11'!$AJ$8:$AJ$42+('Aug 11'!$G$8:$G$42=$T4)*'Aug 11'!$AK$8:$AK$42) -> 0 | AF4: =SUMPRODUCT(('Aug 12'!$F$8:$F$42=$T4)*'Aug 12'!$AJ$8:$AJ$42+('Aug 12'!$G$8:$G$42=$T4)*'Aug 12'!$AK$8:$AK$42) -> 0 | AG4: =SUMPRODUCT(('Aug 13'!$F$8:$F$42=$T4)*'Aug 13'!$AJ$8:$AJ$42+('Aug 13'!$G$8:$G$42=$T4)*'Aug 13'!$AK$8:$AK$42) -> 0 | AH4: =SUMPRODUCT(('Aug 14'!$F$8:$F$42=$T4)*'Aug 14'!$AJ$8:$AJ$42+('Aug 14'!$G$8:$G$42=$T4)*'Aug 14'!$AK$8:$AK$42) -> 0 | AI4: =SUMPRODUCT(('Aug 15'!$F$8:$F$42=$T4)*'Aug 15'!$AJ$8:$AJ$42+('Aug 15'!$G$8:$G$42=$T4)*'Aug 15'!$AK$8:$AK$42) -> 0 | AJ4: =SUMPRODUCT(('Aug 16'!$F$8:$F$42=$T4)*'Aug 16'!$AJ$8:$AJ$42+('Aug 16'!$G$8:$G$42=$T4)*'Aug 16'!$AK$8:$AK$42) -> 0 | AK4: =SUMPRODUCT(('Aug 17'!$F$8:$F$42=$T4)*'Aug 17'!$AJ$8:$AJ$42+('Aug 17'!$G$8:$G$42=$T4)*'Aug 17'!$AK$8:$AK$42) -> 0 | AL4: =SUMPRODUCT(('Aug 18'!$F$8:$F$42=$T4)*'Aug 18'!$AJ$8:$AJ$42+('Aug 18'!$G$8:$G$42=$T4)*'Aug 18'!$AK$8:$AK$42) -> 0 | AM4: =SUMPRODUCT(('Aug 19'!$F$8:$F$42=$T4)*'Aug 19'!$AJ$8:$AJ$42+('Aug 19'!$G$8:$G$42=$T4)*'Aug 19'!$AK$8:$AK$42) -> 0 | AN4: =SUMPRODUCT(('Aug 20'!$F$8:$F$42=$T4)*'Aug 20'!$AJ$8:$AJ$42+('Aug 20'!$G$8:$G$42=$T4)*'Aug 20'!$AK$8:$AK$42) -> 0 | AO4: =SUMPRODUCT(('Aug 21'!$F$8:$F$42=$T4)*'Aug 21'!$AJ$8:$AJ$42+('Aug 21'!$G$8:$G$42=$T4)*'Aug 21'!$AK$8:$AK$42) -> 0 | AP4: =SUMPRODUCT(('Aug 22'!$F$8:$F$42=$T4)*'Aug 22'!$AJ$8:$AJ$42+('Aug 22'!$G$8:$G$42=$T4)*'Aug 22'!$AK$8:$AK$42) -> 0 | AQ4: =SUMPRODUCT(('Aug 23'!$F$8:$F$42=$T4)*'Aug 23'!$AJ$8:$AJ$42+('Aug 23'!$G$8:$G$42=$T4)*'Aug 23'!$AK$8:$AK$42) -> 0 | AR4: =SUMPRODUCT(('Aug 24'!$F$8:$F$42=$T4)*'Aug 24'!$AJ$8:$AJ$42+('Aug 24'!$G$8:$G$42=$T4)*'Aug 24'!$AK$8:$AK$42) -> 0 | AS4: =SUMPRODUCT(('Aug 25'!$F$8:$F$42=$T4)*'Aug 25'!$AJ$8:$AJ$42+('Aug 25'!$G$8:$G$42=$T4)*'Aug 25'!$AK$8:$AK$42) -> 0 | AT4: =SUMPRODUCT(('Aug 26'!$F$8:$F$42=$T4)*'Aug 26'!$AJ$8:$AJ$42+('Aug 26'!$G$8:$G$42=$T4)*'Aug 26'!$AK$8:$AK$42) -> 0 | AU4: =SUMPRODUCT(('Aug 27'!$F$8:$F$42=$T4)*'Aug 27'!$AJ$8:$AJ$42+('Aug 27'!$G$8:$G$42=$T4)*'Aug 27'!$AK$8:$AK$42) -> 0 | AV4: =SUMPRODUCT(('Aug 28'!$F$8:$F$42=$T4)*'Aug 28'!$AJ$8:$AJ$42+('Aug 28'!$G$8:$G$42=$T4)*'Aug 28'!$AK$8:$AK$42) -> 0 | AW4: =SUMPRODUCT(('Aug 29'!$F$8:$F$42=$T4)*'Aug 29'!$AJ$8:$AJ$42+('Aug 29'!$G$8:$G$42=$T4)*'Aug 29'!$AK$8:$AK$42) -> 0 | AX4: =SUMPRODUCT(('Aug 30'!$F$8:$F$42=$T4)*'Aug 30'!$AJ$8:$AJ$42+('Aug 30'!$G$8:$G$42=$T4)*'Aug 30'!$AK$8:$AK$42) -> 0 | AY4: =SUMPRODUCT(('Aug 31'!$F$8:$F$42=$T4)*'Aug 31'!$AJ$8:$AJ$42+('Aug 31'!$G$8:$G$42=$T4)*'Aug 31'!$AK$8:$AK$42) -> 0 | BA4: =SUM(U4:AD4) -> 0 | BB4: =MATCH(BD4,'Pay Plan'!$C$6:$C$12,1) -> 1 | BC4: =SUMPRODUCT(('Aug 1'!$F$8:$F$42=$T4)*'Aug 1'!$AI$8:$AI$42*(('Aug 1'!$AM$8:$AM$42="Y")+('Aug 1'!$AN$8:$AN$42="Y")+('Aug 1'!$AO$8:$AO$42="Y")))+SUMPRODUCT(('Aug 2'!$F$8:$F$42=$T4)*'Aug 2'!$AI$8:$AI$42*(('Aug 2'!$AM$8:$AM$42="Y")+('Aug 2'!$AN$8:$AN$42="Y")+('Aug 2'!$AO$8:$AO$42="Y")))+SUMPRODUCT(('Aug 3'!$F$8:$F$42=$T4)*'Aug 3'!$AI$8:$AI$42*(('Aug 3'!$AM$8:$AM$42="Y")+('Aug 3'!$AN$8:$AN$42="Y")+('Aug 3'!$AO$8:$AO$42="Y")))+SUMPRODUCT(('Aug 4'!$F$8:$F$42=$T4)*'Aug 4'!$AI$8:$AI$42*(('Aug 4'!$AM$8:$AM$42="Y")+('Aug 4'!$AN$8:$AN$42="Y")+('Aug 4'!$AO$8:$AO$42="Y")))+SUMPRODUCT(('Aug 5'!$F$8:$F$42=$T4)*'Aug 5'!$AI$8:$AI$42*(('Aug 5'!$AM$8:$AM$42="Y")+('Aug 5'!$AN$8:$AN$42="Y")+('Aug 5'!$AO$8:$AO$42="Y")))+SUMPRODUCT(('Aug 6'!$F$8:$F$42=$T4)*'Aug 6'!$AI$8:$AI$42*(('Aug 6'!$AM$8:$AM$42="Y")+('Aug 6'!$AN$8:$AN$42="Y")+('Aug 6'!$AO$8:$AO$42="Y")))+SUMPRODUCT(('Aug 7'!$F$8:$F$42=$T4)*'Aug 7'!$AI$8:$AI$42*(('Aug 7'!$AM$8:$AM$42="Y")+('Aug 7'!$AN$8:$AN$42="Y")+('Aug 7'!$AO$8:$AO$42="Y")))+SUMPRODUCT(('Aug 8'!$F$8:$F$42=$T4)*'Aug 8'!$AI$8:$AI$42*(('Aug 8'!$AM$8:$AM$42="Y")+('Aug 8'!$AN$8:$AN$42="Y")+('Aug 8'!$AO$8:$AO$42="Y")))+SUMPRODUCT(('Aug 9'!$F$8:$F$42=$T4)*'Aug 9'!$AI$8:$AI$42*(('Aug 9'!$AM$8:$AM$42="Y")+('Aug 9'!$AN$8:$AN$42="Y")+('Aug 9'!$AO$8:$AO$42="Y")))+SUMPRODUCT(('Aug 10'!$F$8:$F$42=$T4)*'Aug 10'!$AI$8:$AI$42*(('Aug 10'!$AM$8:$AM$42="Y")+('Aug 10'!$AN$8:$AN$42="Y")+('Aug 10'!$AO$8:$AO$42="Y")))+SUMPRODUCT(('Aug 11'!$F$8:$F$42=$T4)*'Aug 11'!$AI$8:$AI$42*(('Aug 11'!$AM$8:$AM$42="Y")+('Aug 11'!$AN$8:$AN$42="Y")+('Aug 11'!$AO$8:$AO$42="Y")))+SUMPRODUCT(('Aug 12'!$F$8:$F$42=$T4)*'Aug 12'!$AI$8:$AI$42*(('Aug 12'!$AM$8:$AM$42="Y")+('Aug 12'!$AN$8:$AN$42="Y")+('Aug 12'!$AO$8:$AO$42="Y")))+SUMPRODUCT(('Aug 13'!$F$8:$F$42=$T4)*'Aug 13'!$AI$8:$AI$42*(('Aug 13'!$AM$8:$AM$42="Y")+('Aug 13'!$AN$8:$AN$42="Y")+('Aug 13'!$AO$8:$AO$42="Y")))+SUMPRODUCT(('Aug 14'!$F$8:$F$42=$T4)*'Aug 14'!$AI$8:$AI$42*(('Aug 14'!$AM$8:$AM$42="Y")+('Aug 14'!$AN$8:$AN$42="Y")+('Aug 14'!$AO$8:$AO$42="Y")))+SUMPRODUCT(('Aug 15'!$F$8:$F$42=$T4)*'Aug 15'!$AI$8:$AI$42*(('Aug 15'!$AM$8:$AM$42="Y")+('Aug 15'!$AN$8:$AN$42="Y")+('Aug 15'!$AO$8:$AO$42="Y")))+SUMPRODUCT(('Aug 16'!$F$8:$F$42=$T4)*'Aug 16'!$AI$8:$AI$42*(('Aug 16'!$AM$8:$AM$42="Y")+('Aug 16'!$AN$8:$AN$42="Y")+('Aug 16'!$AO$8:$AO$42="Y")))+SUMPRODUCT(('Aug 17'!$F$8:$F$42=$T4)*'Aug 17'!$AI$8:$AI$42*(('Aug 17'!$AM$8:$AM$42="Y")+('Aug 17'!$AN$8:$AN$42="Y")+('Aug 17'!$AO$8:$AO$42="Y")))+SUMPRODUCT(('Aug 18'!$F$8:$F$42=$T4)*'Aug 18'!$AI$8:$AI$42*(('Aug 18'!$AM$8:$AM$42="Y")+('Aug 18'!$AN$8:$AN$42="Y")+('Aug 18'!$AO$8:$AO$42="Y")))+SUMPRODUCT(('Aug 19'!$F$8:$F$42=$T4)*'Aug 19'!$AI$8:$AI$42*(('Aug 19'!$AM$8:$AM$42="Y")+('Aug 19'!$AN$8:$AN$42="Y")+('Aug 19'!$AO$8:$AO$42="Y")))+SUMPRODUCT(('Aug 20'!$F$8:$F$42=$T4)*'Aug 20'!$AI$8:$AI$42*(('Aug 20'!$AM$8:$AM$42="Y")+('Aug 20'!$AN$8:$AN$42="Y")+('Aug 20'!$AO$8:$AO$42="Y")))+SUMPRODUCT(('Aug 21'!$F$8:$F$42=$T4)*'Aug 21'!$AI$8:$AI$42*(('Aug 21'!$AM$8:$AM$42="Y")+('Aug 21'!$AN$8:$AN$42="Y")+('Aug 21'!$AO$8:$AO$42="Y")))+SUMPRODUCT(('Aug 22'!$F$8:$F$42=$T4)*'Aug 22'!$AI$8:$AI$42*(('Aug 22'!$AM$8:$AM$42="Y")+('Aug 22'!$AN$8:$AN$42="Y")+('Aug 22'!$AO$8:$AO$42="Y")))+SUMPRODUCT(('Aug 23'!$F$8:$F$42=$T4)*'Aug 23'!$AI$8:$AI$42*(('Aug 23'!$AM$8:$AM$42="Y")+('Aug 23'!$AN$8:$AN$42="Y")+('Aug 23'!$AO$8:$AO$42="Y")))+SUMPRODUCT(('Aug 24'!$F$8:$F$42=$T4)*'Aug 24'!$AI$8:$AI$42*(('Aug 24'!$AM$8:$AM$42="Y")+('Aug 24'!$AN$8:$AN$42="Y")+('Aug 24'!$AO$8:$AO$42="Y")))+SUMPRODUCT(('Aug 25'!$F$8:$F$42=$T4)*'Aug 25'!$AI$8:$AI$42*(('Aug 25'!$AM$8:$AM$42="Y")+('Aug 25'!$AN$8:$AN$42="Y")+('Aug 25'!$AO$8:$AO$42="Y")))+SUMPRODUCT(('Aug 26'!$F$8:$F$42=$T4)*'Aug 26'!$AI$8:$AI$42*(('Aug 26'!$AM$8:$AM$42="Y")+('Aug 26'!$AN$8:$AN$42="Y")+('Aug 26'!$AO$8:$AO$42="Y")))+SUMPRODUCT(('Aug 27'!$F$8:$F$42=$T4)*'Aug 27'!$AI$8:$AI$42*(('Aug 27'!$AM$8:$AM$42="Y")+('Aug 27'!$AN$8:$AN$42="Y")+('Aug 27'!$AO$8:$AO$42="Y")))+SUMPRODUCT(('Aug 28'!$F$8:$F$42=$T4)*'Aug 28'!$AI$8:$AI$42*(('Aug 28'!$AM$8:$AM$42="Y")+('Aug 28'!$AN$8:$AN$42="Y")+('Aug 28'!$AO$8:$AO$42="Y")))+SUMPRODUCT(('Aug 29'!$F$8:$F$42=$T4)*'Aug 29'!$AI$8:$AI$42*(('Aug 29'!$AM$8:$AM$42="Y")+('Aug 29'!$AN$8:$AN$42="Y")+('Aug 29'!$AO$8:$AO$42="Y")))+SUMPRODUCT(('Aug 30'!$F$8:$F$42=$T4)*'Aug 30'!$AI$8:$AI$42*(('Aug 30'!$AM$8:$AM$42="Y")+('Aug 30'!$AN$8:$AN$42="Y")+('Aug 30'!$AO$8:$AO$42="Y")))+SUMPRODUCT(('Aug 31'!$F$8:$F$42=$T4)*'Aug 31'!$AI$8:$AI$42*(('Aug 31'!$AM$8:$AM$42="Y")+('Aug 31'!$AN$8:$AN$42="Y")+('Aug 31'!$AO$8:$AO$42="Y"))) -> 0 | BD4: =SUM(U4:AY4) -> 0 | BE4: =SUM(U23:AY23) -> 0 | BF4: =SUM(U42:AY42) -> 0 | BH4: ='Aug 1'!$G$46+'Aug 2'!$G$46+'Aug 3'!$G$46+'Aug 4'!$G$46+'Aug 5'!$G$46+'Aug 6'!$G$46+'Aug 7'!$G$46+'Aug 8'!$G$46+'Aug 9'!$G$46+'Aug 10'!$G$46+'Aug 11'!$G$46+'Aug 12'!$G$46+'Aug 13'!$G$46+'Aug 14'!$G$46+'Aug 15'!$G$46+'Aug 16'!$G$46+'Aug 17'!$G$46+'Aug 18'!$G$46+'Aug 19'!$G$46+'Aug 20'!$G$46+'Aug 21'!$G$46+'Aug 22'!$G$46+'Aug 23'!$G$46+'Aug 24'!$G$46+'Aug 25'!$G$46+'Aug 26'!$G$46+'Aug 27'!$G$46+'Aug 28'!$G$46+'Aug 29'!$G$46+'Aug 30'!$G$46+'Aug 31'!$G$46 -> 0
T5: ='Staff & Lists'!A6 -> CHAD EMBRY | U5: =SUMPRODUCT(('Aug 1'!$F$8:$F$42=$T5)*'Aug 1'!$AJ$8:$AJ$42+('Aug 1'!$G$8:$G$42=$T5)*'Aug 1'!$AK$8:$AK$42) -> 0 | V5: =SUMPRODUCT(('Aug 2'!$F$8:$F$42=$T5)*'Aug 2'!$AJ$8:$AJ$42+('Aug 2'!$G$8:$G$42=$T5)*'Aug 2'!$AK$8:$AK$42) -> 0 | W5: =SUMPRODUCT(('Aug 3'!$F$8:$F$42=$T5)*'Aug 3'!$AJ$8:$AJ$42+('Aug 3'!$G$8:$G$42=$T5)*'Aug 3'!$AK$8:$AK$42) -> 0 | X5: =SUMPRODUCT(('Aug 4'!$F$8:$F$42=$T5)*'Aug 4'!$AJ$8:$AJ$42+('Aug 4'!$G$8:$G$42=$T5)*'Aug 4'!$AK$8:$AK$42) -> 0 | Y5: =SUMPRODUCT(('Aug 5'!$F$8:$F$42=$T5)*'Aug 5'!$AJ$8:$AJ$42+('Aug 5'!$G$8:$G$42=$T5)*'Aug 5'!$AK$8:$AK$42) -> 0 | Z5: =SUMPRODUCT(('Aug 6'!$F$8:$F$42=$T5)*'Aug 6'!$AJ$8:$AJ$42+('Aug 6'!$G$8:$G$42=$T5)*'Aug 6'!$AK$8:$AK$42) -> 0 | AA5: =SUMPRODUCT(('Aug 7'!$F$8:$F$42=$T5)*'Aug 7'!$AJ$8:$AJ$42+('Aug 7'!$G$8:$G$42=$T5)*'Aug 7'!$AK$8:$AK$42) -> 0 | AB5: =SUMPRODUCT(('Aug 8'!$F$8:$F$42=$T5)*'Aug 8'!$AJ$8:$AJ$42+('Aug 8'!$G$8:$G$42=$T5)*'Aug 8'!$AK$8:$AK$42) -> 0 | AC5: =SUMPRODUCT(('Aug 9'!$F$8:$F$42=$T5)*'Aug 9'!$AJ$8:$AJ$42+('Aug 9'!$G$8:$G$42=$T5)*'Aug 9'!$AK$8:$AK$42) -> 0 | AD5: =SUMPRODUCT(('Aug 10'!$F$8:$F$42=$T5)*'Aug 10'!$AJ$8:$AJ$42+('Aug 10'!$G$8:$G$42=$T5)*'Aug 10'!$AK$8:$AK$42) -> 0 | AE5: =SUMPRODUCT(('Aug 11'!$F$8:$F$42=$T5)*'Aug 11'!$AJ$8:$AJ$42+('Aug 11'!$G$8:$G$42=$T5)*'Aug 11'!$AK$8:$AK$42) -> 0 | AF5: =SUMPRODUCT(('Aug 12'!$F$8:$F$42=$T5)*'Aug 12'!$AJ$8:$AJ$42+('Aug 12'!$G$8:$G$42=$T5)*'Aug 12'!$AK$8:$AK$42) -> 0 | AG5: =SUMPRODUCT(('Aug 13'!$F$8:$F$42=$T5)*'Aug 13'!$AJ$8:$AJ$42+('Aug 13'!$G$8:$G$42=$T5)*'Aug 13'!$AK$8:$AK$42) -> 0 | AH5: =SUMPRODUCT(('Aug 14'!$F$8:$F$42=$T5)*'Aug 14'!$AJ$8:$AJ$42+('Aug 14'!$G$8:$G$42=$T5)*'Aug 14'!$AK$8:$AK$42) -> 0 | AI5: =SUMPRODUCT(('Aug 15'!$F$8:$F$42=$T5)*'Aug 15'!$AJ$8:$AJ$42+('Aug 15'!$G$8:$G$42=$T5)*'Aug 15'!$AK$8:$AK$42) -> 0 | AJ5: =SUMPRODUCT(('Aug 16'!$F$8:$F$42=$T5)*'Aug 16'!$AJ$8:$AJ$42+('Aug 16'!$G$8:$G$42=$T5)*'Aug 16'!$AK$8:$AK$42) -> 0 | AK5: =SUMPRODUCT(('Aug 17'!$F$8:$F$42=$T5)*'Aug 17'!$AJ$8:$AJ$42+('Aug 17'!$G$8:$G$42=$T5)*'Aug 17'!$AK$8:$AK$42) -> 0 | AL5: =SUMPRODUCT(('Aug 18'!$F$8:$F$42=$T5)*'Aug 18'!$AJ$8:$AJ$42+('Aug 18'!$G$8:$G$42=$T5)*'Aug 18'!$AK$8:$AK$42) -> 0 | AM5: =SUMPRODUCT(('Aug 19'!$F$8:$F$42=$T5)*'Aug 19'!$AJ$8:$AJ$42+('Aug 19'!$G$8:$G$42=$T5)*'Aug 19'!$AK$8:$AK$42) -> 0 | AN5: =SUMPRODUCT(('Aug 20'!$F$8:$F$42=$T5)*'Aug 20'!$AJ$8:$AJ$42+('Aug 20'!$G$8:$G$42=$T5)*'Aug 20'!$AK$8:$AK$42) -> 0 | AO5: =SUMPRODUCT(('Aug 21'!$F$8:$F$42=$T5)*'Aug 21'!$AJ$8:$AJ$42+('Aug 21'!$G$8:$G$42=$T5)*'Aug 21'!$AK$8:$AK$42) -> 0 | AP5: =SUMPRODUCT(('Aug 22'!$F$8:$F$42=$T5)*'Aug 22'!$AJ$8:$AJ$42+('Aug 22'!$G$8:$G$42=$T5)*'Aug 22'!$AK$8:$AK$42) -> 0 | AQ5: =SUMPRODUCT(('Aug 23'!$F$8:$F$42=$T5)*'Aug 23'!$AJ$8:$AJ$42+('Aug 23'!$G$8:$G$42=$T5)*'Aug 23'!$AK$8:$AK$42) -> 0 | AR5: =SUMPRODUCT(('Aug 24'!$F$8:$F$42=$T5)*'Aug 24'!$AJ$8:$AJ$42+('Aug 24'!$G$8:$G$42=$T5)*'Aug 24'!$AK$8:$AK$42) -> 0 | AS5: =SUMPRODUCT(('Aug 25'!$F$8:$F$42=$T5)*'Aug 25'!$AJ$8:$AJ$42+('Aug 25'!$G$8:$G$42=$T5)*'Aug 25'!$AK$8:$AK$42) -> 0 | AT5: =SUMPRODUCT(('Aug 26'!$F$8:$F$42=$T5)*'Aug 26'!$AJ$8:$AJ$42+('Aug 26'!$G$8:$G$42=$T5)*'Aug 26'!$AK$8:$AK$42) -> 0 | AU5: =SUMPRODUCT(('Aug 27'!$F$8:$F$42=$T5)*'Aug 27'!$AJ$8:$AJ$42+('Aug 27'!$G$8:$G$42=$T5)*'Aug 27'!$AK$8:$AK$42) -> 0 | AV5: =SUMPRODUCT(('Aug 28'!$F$8:$F$42=$T5)*'Aug 28'!$AJ$8:$AJ$42+('Aug 28'!$G$8:$G$42=$T5)*'Aug 28'!$AK$8:$AK$42) -> 0 | AW5: =SUMPRODUCT(('Aug 29'!$F$8:$F$42=$T5)*'Aug 29'!$AJ$8:$AJ$42+('Aug 29'!$G$8:$G$42=$T5)*'Aug 29'!$AK$8:$AK$42) -> 0 | AX5: =SUMPRODUCT(('Aug 30'!$F$8:$F$42=$T5)*'Aug 30'!$AJ$8:$AJ$42+('Aug 30'!$G$8:$G$42=$T5)*'Aug 30'!$AK$8:$AK$42) -> 0 | AY5: =SUMPRODUCT(('Aug 31'!$F$8:$F$42=$T5)*'Aug 31'!$AJ$8:$AJ$42+('Aug 31'!$G$8:$G$42=$T5)*'Aug 31'!$AK$8:$AK$42) -> 0 | BA5: =SUM(U5:AD5) -> 0 | BB5: =MATCH(BD5,'Pay Plan'!$C$6:$C$12,1) -> 1 | BC5: =SUMPRODUCT(('Aug 1'!$F$8:$F$42=$T5)*'Aug 1'!$AI$8:$AI$42*(('Aug 1'!$AM$8:$AM$42="Y")+('Aug 1'!$AN$8:$AN$42="Y")+('Aug 1'!$AO$8:$AO$42="Y")))+SUMPRODUCT(('Aug 2'!$F$8:$F$42=$T5)*'Aug 2'!$AI$8:$AI$42*(('Aug 2'!$AM$8:$AM$42="Y")+('Aug 2'!$AN$8:$AN$42="Y")+('Aug 2'!$AO$8:$AO$42="Y")))+SUMPRODUCT(('Aug 3'!$F$8:$F$42=$T5)*'Aug 3'!$AI$8:$AI$42*(('Aug 3'!$AM$8:$AM$42="Y")+('Aug 3'!$AN$8:$AN$42="Y")+('Aug 3'!$AO$8:$AO$42="Y")))+SUMPRODUCT(('Aug 4'!$F$8:$F$42=$T5)*'Aug 4'!$AI$8:$AI$42*(('Aug 4'!$AM$8:$AM$42="Y")+('Aug 4'!$AN$8:$AN$42="Y")+('Aug 4'!$AO$8:$AO$42="Y")))+SUMPRODUCT(('Aug 5'!$F$8:$F$42=$T5)*'Aug 5'!$AI$8:$AI$42*(('Aug 5'!$AM$8:$AM$42="Y")+('Aug 5'!$AN$8:$AN$42="Y")+('Aug 5'!$AO$8:$AO$42="Y")))+SUMPRODUCT(('Aug 6'!$F$8:$F$42=$T5)*'Aug 6'!$AI$8:$AI$42*(('Aug 6'!$AM$8:$AM$42="Y")+('Aug 6'!$AN$8:$AN$42="Y")+('Aug 6'!$AO$8:$AO$42="Y")))+SUMPRODUCT(('Aug 7'!$F$8:$F$42=$T5)*'Aug 7'!$AI$8:$AI$42*(('Aug 7'!$AM$8:$AM$42="Y")+('Aug 7'!$AN$8:$AN$42="Y")+('Aug 7'!$AO$8:$AO$42="Y")))+SUMPRODUCT(('Aug 8'!$F$8:$F$42=$T5)*'Aug 8'!$AI$8:$AI$42*(('Aug 8'!$AM$8:$AM$42="Y")+('Aug 8'!$AN$8:$AN$42="Y")+('Aug 8'!$AO$8:$AO$42="Y")))+SUMPRODUCT(('Aug 9'!$F$8:$F$42=$T5)*'Aug 9'!$AI$8:$AI$42*(('Aug 9'!$AM$8:$AM$42="Y")+('Aug 9'!$AN$8:$AN$42="Y")+('Aug 9'!$AO$8:$AO$42="Y")))+SUMPRODUCT(('Aug 10'!$F$8:$F$42=$T5)*'Aug 10'!$AI$8:$AI$42*(('Aug 10'!$AM$8:$AM$42="Y")+('Aug 10'!$AN$8:$AN$42="Y")+('Aug 10'!$AO$8:$AO$42="Y")))+SUMPRODUCT(('Aug 11'!$F$8:$F$42=$T5)*'Aug 11'!$AI$8:$AI$42*(('Aug 11'!$AM$8:$AM$42="Y")+('Aug 11'!$AN$8:$AN$42="Y")+('Aug 11'!$AO$8:$AO$42="Y")))+SUMPRODUCT(('Aug 12'!$F$8:$F$42=$T5)*'Aug 12'!$AI$8:$AI$42*(('Aug 12'!$AM$8:$AM$42="Y")+('Aug 12'!$AN$8:$AN$42="Y")+('Aug 12'!$AO$8:$AO$42="Y")))+SUMPRODUCT(('Aug 13'!$F$8:$F$42=$T5)*'Aug 13'!$AI$8:$AI$42*(('Aug 13'!$AM$8:$AM$42="Y")+('Aug 13'!$AN$8:$AN$42="Y")+('Aug 13'!$AO$8:$AO$42="Y")))+SUMPRODUCT(('Aug 14'!$F$8:$F$42=$T5)*'Aug 14'!$AI$8:$AI$42*(('Aug 14'!$AM$8:$AM$42="Y")+('Aug 14'!$AN$8:$AN$42="Y")+('Aug 14'!$AO$8:$AO$42="Y")))+SUMPRODUCT(('Aug 15'!$F$8:$F$42=$T5)*'Aug 15'!$AI$8:$AI$42*(('Aug 15'!$AM$8:$AM$42="Y")+('Aug 15'!$AN$8:$AN$42="Y")+('Aug 15'!$AO$8:$AO$42="Y")))+SUMPRODUCT(('Aug 16'!$F$8:$F$42=$T5)*'Aug 16'!$AI$8:$AI$42*(('Aug 16'!$AM$8:$AM$42="Y")+('Aug 16'!$AN$8:$AN$42="Y")+('Aug 16'!$AO$8:$AO$42="Y")))+SUMPRODUCT(('Aug 17'!$F$8:$F$42=$T5)*'Aug 17'!$AI$8:$AI$42*(('Aug 17'!$AM$8:$AM$42="Y")+('Aug 17'!$AN$8:$AN$42="Y")+('Aug 17'!$AO$8:$AO$42="Y")))+SUMPRODUCT(('Aug 18'!$F$8:$F$42=$T5)*'Aug 18'!$AI$8:$AI$42*(('Aug 18'!$AM$8:$AM$42="Y")+('Aug 18'!$AN$8:$AN$42="Y")+('Aug 18'!$AO$8:$AO$42="Y")))+SUMPRODUCT(('Aug 19'!$F$8:$F$42=$T5)*'Aug 19'!$AI$8:$AI$42*(('Aug 19'!$AM$8:$AM$42="Y")+('Aug 19'!$AN$8:$AN$42="Y")+('Aug 19'!$AO$8:$AO$42="Y")))+SUMPRODUCT(('Aug 20'!$F$8:$F$42=$T5)*'Aug 20'!$AI$8:$AI$42*(('Aug 20'!$AM$8:$AM$42="Y")+('Aug 20'!$AN$8:$AN$42="Y")+('Aug 20'!$AO$8:$AO$42="Y")))+SUMPRODUCT(('Aug 21'!$F$8:$F$42=$T5)*'Aug 21'!$AI$8:$AI$42*(('Aug 21'!$AM$8:$AM$42="Y")+('Aug 21'!$AN$8:$AN$42="Y")+('Aug 21'!$AO$8:$AO$42="Y")))+SUMPRODUCT(('Aug 22'!$F$8:$F$42=$T5)*'Aug 22'!$AI$8:$AI$42*(('Aug 22'!$AM$8:$AM$42="Y")+('Aug 22'!$AN$8:$AN$42="Y")+('Aug 22'!$AO$8:$AO$42="Y")))+SUMPRODUCT(('Aug 23'!$F$8:$F$42=$T5)*'Aug 23'!$AI$8:$AI$42*(('Aug 23'!$AM$8:$AM$42="Y")+('Aug 23'!$AN$8:$AN$42="Y")+('Aug 23'!$AO$8:$AO$42="Y")))+SUMPRODUCT(('Aug 24'!$F$8:$F$42=$T5)*'Aug 24'!$AI$8:$AI$42*(('Aug 24'!$AM$8:$AM$42="Y")+('Aug 24'!$AN$8:$AN$42="Y")+('Aug 24'!$AO$8:$AO$42="Y")))+SUMPRODUCT(('Aug 25'!$F$8:$F$42=$T5)*'Aug 25'!$AI$8:$AI$42*(('Aug 25'!$AM$8:$AM$42="Y")+('Aug 25'!$AN$8:$AN$42="Y")+('Aug 25'!$AO$8:$AO$42="Y")))+SUMPRODUCT(('Aug 26'!$F$8:$F$42=$T5)*'Aug 26'!$AI$8:$AI$42*(('Aug 26'!$AM$8:$AM$42="Y")+('Aug 26'!$AN$8:$AN$42="Y")+('Aug 26'!$AO$8:$AO$42="Y")))+SUMPRODUCT(('Aug 27'!$F$8:$F$42=$T5)*'Aug 27'!$AI$8:$AI$42*(('Aug 27'!$AM$8:$AM$42="Y")+('Aug 27'!$AN$8:$AN$42="Y")+('Aug 27'!$AO$8:$AO$42="Y")))+SUMPRODUCT(('Aug 28'!$F$8:$F$42=$T5)*'Aug 28'!$AI$8:$AI$42*(('Aug 28'!$AM$8:$AM$42="Y")+('Aug 28'!$AN$8:$AN$42="Y")+('Aug 28'!$AO$8:$AO$42="Y")))+SUMPRODUCT(('Aug 29'!$F$8:$F$42=$T5)*'Aug 29'!$AI$8:$AI$42*(('Aug 29'!$AM$8:$AM$42="Y")+('Aug 29'!$AN$8:$AN$42="Y")+('Aug 29'!$AO$8:$AO$42="Y")))+SUMPRODUCT(('Aug 30'!$F$8:$F$42=$T5)*'Aug 30'!$AI$8:$AI$42*(('Aug 30'!$AM$8:$AM$42="Y")+('Aug 30'!$AN$8:$AN$42="Y")+('Aug 30'!$AO$8:$AO$42="Y")))+SUMPRODUCT(('Aug 31'!$F$8:$F$42=$T5)*'Aug 31'!$AI$8:$AI$42*(('Aug 31'!$AM$8:$AM$42="Y")+('Aug 31'!$AN$8:$AN$42="Y")+('Aug 31'!$AO$8:$AO$42="Y"))) -> 0 | BD5: =SUM(U5:AY5) -> 0 | BE5: =SUM(U24:AY24) -> 0 | BF5: =SUM(U43:AY43) -> 0 | BH5: =SUMPRODUCT('Aug 1'!$AI$8:$AI$42*(('Aug 1'!$AM$8:$AM$42="Y")+('Aug 1'!$AN$8:$AN$42="Y")+('Aug 1'!$AO$8:$AO$42="Y")))+SUMPRODUCT('Aug 2'!$AI$8:$AI$42*(('Aug 2'!$AM$8:$AM$42="Y")+('Aug 2'!$AN$8:$AN$42="Y")+('Aug 2'!$AO$8:$AO$42="Y")))+SUMPRODUCT('Aug 3'!$AI$8:$AI$42*(('Aug 3'!$AM$8:$AM$42="Y")+('Aug 3'!$AN$8:$AN$42="Y")+('Aug 3'!$AO$8:$AO$42="Y")))+SUMPRODUCT('Aug 4'!$AI$8:$AI$42*(('Aug 4'!$AM$8:$AM$42="Y")+('Aug 4'!$AN$8:$AN$42="Y")+('Aug 4'!$AO$8:$AO$42="Y")))+SUMPRODUCT('Aug 5'!$AI$8:$AI$42*(('Aug 5'!$AM$8:$AM$42="Y")+('Aug 5'!$AN$8:$AN$42="Y")+('Aug 5'!$AO$8:$AO$42="Y")))+SUMPRODUCT('Aug 6'!$AI$8:$AI$42*(('Aug 6'!$AM$8:$AM$42="Y")+('Aug 6'!$AN$8:$AN$42="Y")+('Aug 6'!$AO$8:$AO$42="Y")))+SUMPRODUCT('Aug 7'!$AI$8:$AI$42*(('Aug 7'!$AM$8:$AM$42="Y")+('Aug 7'!$AN$8:$AN$42="Y")+('Aug 7'!$AO$8:$AO$42="Y")))+SUMPRODUCT('Aug 8'!$AI$8:$AI$42*(('Aug 8'!$AM$8:$AM$42="Y")+('Aug 8'!$AN$8:$AN$42="Y")+('Aug 8'!$AO$8:$AO$42="Y")))+SUMPRODUCT('Aug 9'!$AI$8:$AI$42*(('Aug 9'!$AM$8:$AM$42="Y")+('Aug 9'!$AN$8:$AN$42="Y")+('Aug 9'!$AO$8:$AO$42="Y")))+SUMPRODUCT('Aug 10'!$AI$8:$AI$42*(('Aug 10'!$AM$8:$AM$42="Y")+('Aug 10'!$AN$8:$AN$42="Y")+('Aug 10'!$AO$8:$AO$42="Y")))+SUMPRODUCT('Aug 11'!$AI$8:$AI$42*(('Aug 11'!$AM$8:$AM$42="Y")+('Aug 11'!$AN$8:$AN$42="Y")+('Aug 11'!$AO$8:$AO$42="Y")))+SUMPRODUCT('Aug 12'!$AI$8:$AI$42*(('Aug 12'!$AM$8:$AM$42="Y")+('Aug 12'!$AN$8:$AN$42="Y")+('Aug 12'!$AO$8:$AO$42="Y")))+SUMPRODUCT('Aug 13'!$AI$8:$AI$42*(('Aug 13'!$AM$8:$AM$42="Y")+('Aug 13'!$AN$8:$AN$42="Y")+('Aug 13'!$AO$8:$AO$42="Y")))+SUMPRODUCT('Aug 14'!$AI$8:$AI$42*(('Aug 14'!$AM$8:$AM$42="Y")+('Aug 14'!$AN$8:$AN$42="Y")+('Aug 14'!$AO$8:$AO$42="Y")))+SUMPRODUCT('Aug 15'!$AI$8:$AI$42*(('Aug 15'!$AM$8:$AM$42="Y")+('Aug 15'!$AN$8:$AN$42="Y")+('Aug 15'!$AO$8:$AO$42="Y")))+SUMPRODUCT('Aug 16'!$AI$8:$AI$42*(('Aug 16'!$AM$8:$AM$42="Y")+('Aug 16'!$AN$8:$AN$42="Y")+('Aug 16'!$AO$8:$AO$42="Y")))+SUMPRODUCT('Aug 17'!$AI$8:$AI$42*(('Aug 17'!$AM$8:$AM$42="Y")+('Aug 17'!$AN$8:$AN$42="Y")+('Aug 17'!$AO$8:$AO$42="Y")))+SUMPRODUCT('Aug 18'!$AI$8:$AI$42*(('Aug 18'!$AM$8:$AM$42="Y")+('Aug 18'!$AN$8:$AN$42="Y")+('Aug 18'!$AO$8:$AO$42="Y")))+SUMPRODUCT('Aug 19'!$AI$8:$AI$42*(('Aug 19'!$AM$8:$AM$42="Y")+('Aug 19'!$AN$8:$AN$42="Y")+('Aug 19'!$AO$8:$AO$42="Y")))+SUMPRODUCT('Aug 20'!$AI$8:$AI$42*(('Aug 20'!$AM$8:$AM$42="Y")+('Aug 20'!$AN$8:$AN$42="Y")+('Aug 20'!$AO$8:$AO$42="Y")))+SUMPRODUCT('Aug 21'!$AI$8:$AI$42*(('Aug 21'!$AM$8:$AM$42="Y")+('Aug 21'!$AN$8:$AN$42="Y")+('Aug 21'!$AO$8:$AO$42="Y")))+SUMPRODUCT('Aug 22'!$AI$8:$AI$42*(('Aug 22'!$AM$8:$AM$42="Y")+('Aug 22'!$AN$8:$AN$42="Y")+('Aug 22'!$AO$8:$AO$42="Y")))+SUMPRODUCT('Aug 23'!$AI$8:$AI$42*(('Aug 23'!$AM$8:$AM$42="Y")+('Aug 23'!$AN$8:$AN$42="Y")+('Aug 23'!$AO$8:$AO$42="Y")))+SUMPRODUCT('Aug 24'!$AI$8:$AI$42*(('Aug 24'!$AM$8:$AM$42="Y")+('Aug 24'!$AN$8:$AN$42="Y")+('Aug 24'!$AO$8:$AO$42="Y")))+SUMPRODUCT('Aug 25'!$AI$8:$AI$42*(('Aug 25'!$AM$8:$AM$42="Y")+('Aug 25'!$AN$8:$AN$42="Y")+('Aug 25'!$AO$8:$AO$42="Y")))+SUMPRODUCT('Aug 26'!$AI$8:$AI$42*(('Aug 26'!$AM$8:$AM$42="Y")+('Aug 26'!$AN$8:$AN$42="Y")+('Aug 26'!$AO$8:$AO$42="Y")))+SUMPRODUCT('Aug 27'!$AI$8:$AI$42*(('Aug 27'!$AM$8:$AM$42="Y")+('Aug 27'!$AN$8:$AN$42="Y")+('Aug 27'!$AO$8:$AO$42="Y")))+SUMPRODUCT('Aug 28'!$AI$8:$AI$42*(('Aug 28'!$AM$8:$AM$42="Y")+('Aug 28'!$AN$8:$AN$42="Y")+('Aug 28'!$AO$8:$AO$42="Y")))+SUMPRODUCT('Aug 29'!$AI$8:$AI$42*(('Aug 29'!$AM$8:$AM$42="Y")+('Aug 29'!$AN$8:$AN$42="Y")+('Aug 29'!$AO$8:$AO$42="Y")))+SUMPRODUCT('Aug 30'!$AI$8:$AI$42*(('Aug 30'!$AM$8:$AM$42="Y")+('Aug 30'!$AN$8:$AN$42="Y")+('Aug 30'!$AO$8:$AO$42="Y")))+SUMPRODUCT('Aug 31'!$AI$8:$AI$42*(('Aug 31'!$AM$8:$AM$42="Y")+('Aug 31'!$AN$8:$AN$42="Y")+('Aug 31'!$AO$8:$AO$42="Y"))) -> 0
A6: # | B6: Salesperson | C6: Units | D6: Gross | E6: PVR | F6: Tier | G6: Flat | H6: Unit Bon | I6: FastStrt | J6: Prod $ | K6: EARNINGS | N6: Draw | O6: BALANCE | T6: ='Staff & Lists'!A7 -> RICH AMMERMAN | U6: =SUMPRODUCT(('Aug 1'!$F$8:$F$42=$T6)*'Aug 1'!$AJ$8:$AJ$42+('Aug 1'!$G$8:$G$42=$T6)*'Aug 1'!$AK$8:$AK$42) -> 0 | V6: =SUMPRODUCT(('Aug 2'!$F$8:$F$42=$T6)*'Aug 2'!$AJ$8:$AJ$42+('Aug 2'!$G$8:$G$42=$T6)*'Aug 2'!$AK$8:$AK$42) -> 0 | W6: =SUMPRODUCT(('Aug 3'!$F$8:$F$42=$T6)*'Aug 3'!$AJ$8:$AJ$42+('Aug 3'!$G$8:$G$42=$T6)*'Aug 3'!$AK$8:$AK$42) -> 0 | X6: =SUMPRODUCT(('Aug 4'!$F$8:$F$42=$T6)*'Aug 4'!$AJ$8:$AJ$42+('Aug 4'!$G$8:$G$42=$T6)*'Aug 4'!$AK$8:$AK$42) -> 0 | Y6: =SUMPRODUCT(('Aug 5'!$F$8:$F$42=$T6)*'Aug 5'!$AJ$8:$AJ$42+('Aug 5'!$G$8:$G$42=$T6)*'Aug 5'!$AK$8:$AK$42) -> 0 | Z6: =SUMPRODUCT(('Aug 6'!$F$8:$F$42=$T6)*'Aug 6'!$AJ$8:$AJ$42+('Aug 6'!$G$8:$G$42=$T6)*'Aug 6'!$AK$8:$AK$42) -> 0 | AA6: =SUMPRODUCT(('Aug 7'!$F$8:$F$42=$T6)*'Aug 7'!$AJ$8:$AJ$42+('Aug 7'!$G$8:$G$42=$T6)*'Aug 7'!$AK$8:$AK$42) -> 0 | AB6: =SUMPRODUCT(('Aug 8'!$F$8:$F$42=$T6)*'Aug 8'!$AJ$8:$AJ$42+('Aug 8'!$G$8:$G$42=$T6)*'Aug 8'!$AK$8:$AK$42) -> 0 | AC6: =SUMPRODUCT(('Aug 9'!$F$8:$F$42=$T6)*'Aug 9'!$AJ$8:$AJ$42+('Aug 9'!$G$8:$G$42=$T6)*'Aug 9'!$AK$8:$AK$42) -> 0 | AD6: =SUMPRODUCT(('Aug 10'!$F$8:$F$42=$T6)*'Aug 10'!$AJ$8:$AJ$42+('Aug 10'!$G$8:$G$42=$T6)*'Aug 10'!$AK$8:$AK$42) -> 0 | AE6: =SUMPRODUCT(('Aug 11'!$F$8:$F$42=$T6)*'Aug 11'!$AJ$8:$AJ$42+('Aug 11'!$G$8:$G$42=$T6)*'Aug 11'!$AK$8:$AK$42) -> 0 | AF6: =SUMPRODUCT(('Aug 12'!$F$8:$F$42=$T6)*'Aug 12'!$AJ$8:$AJ$42+('Aug 12'!$G$8:$G$42=$T6)*'Aug 12'!$AK$8:$AK$42) -> 0 | AG6: =SUMPRODUCT(('Aug 13'!$F$8:$F$42=$T6)*'Aug 13'!$AJ$8:$AJ$42+('Aug 13'!$G$8:$G$42=$T6)*'Aug 13'!$AK$8:$AK$42) -> 0 | AH6: =SUMPRODUCT(('Aug 14'!$F$8:$F$42=$T6)*'Aug 14'!$AJ$8:$AJ$42+('Aug 14'!$G$8:$G$42=$T6)*'Aug 14'!$AK$8:$AK$42) -> 0 | AI6: =SUMPRODUCT(('Aug 15'!$F$8:$F$42=$T6)*'Aug 15'!$AJ$8:$AJ$42+('Aug 15'!$G$8:$G$42=$T6)*'Aug 15'!$AK$8:$AK$42) -> 0 | AJ6: =SUMPRODUCT(('Aug 16'!$F$8:$F$42=$T6)*'Aug 16'!$AJ$8:$AJ$42+('Aug 16'!$G$8:$G$42=$T6)*'Aug 16'!$AK$8:$AK$42) -> 0 | AK6: =SUMPRODUCT(('Aug 17'!$F$8:$F$42=$T6)*'Aug 17'!$AJ$8:$AJ$42+('Aug 17'!$G$8:$G$42=$T6)*'Aug 17'!$AK$8:$AK$42) -> 0 | AL6: =SUMPRODUCT(('Aug 18'!$F$8:$F$42=$T6)*'Aug 18'!$AJ$8:$AJ$42+('Aug 18'!$G$8:$G$42=$T6)*'Aug 18'!$AK$8:$AK$42) -> 0 | AM6: =SUMPRODUCT(('Aug 19'!$F$8:$F$42=$T6)*'Aug 19'!$AJ$8:$AJ$42+('Aug 19'!$G$8:$G$42=$T6)*'Aug 19'!$AK$8:$AK$42) -> 0 | AN6: =SUMPRODUCT(('Aug 20'!$F$8:$F$42=$T6)*'Aug 20'!$AJ$8:$AJ$42+('Aug 20'!$G$8:$G$42=$T6)*'Aug 20'!$AK$8:$AK$42) -> 0 | AO6: =SUMPRODUCT(('Aug 21'!$F$8:$F$42=$T6)*'Aug 21'!$AJ$8:$AJ$42+('Aug 21'!$G$8:$G$42=$T6)*'Aug 21'!$AK$8:$AK$42) -> 0 | AP6: =SUMPRODUCT(('Aug 22'!$F$8:$F$42=$T6)*'Aug 22'!$AJ$8:$AJ$42+('Aug 22'!$G$8:$G$42=$T6)*'Aug 22'!$AK$8:$AK$42) -> 0 | AQ6: =SUMPRODUCT(('Aug 23'!$F$8:$F$42=$T6)*'Aug 23'!$AJ$8:$AJ$42+('Aug 23'!$G$8:$G$42=$T6)*'Aug 23'!$AK$8:$AK$42) -> 0 | AR6: =SUMPRODUCT(('Aug 24'!$F$8:$F$42=$T6)*'Aug 24'!$AJ$8:$AJ$42+('Aug 24'!$G$8:$G$42=$T6)*'Aug 24'!$AK$8:$AK$42) -> 0 | AS6: =SUMPRODUCT(('Aug 25'!$F$8:$F$42=$T6)*'Aug 25'!$AJ$8:$AJ$42+('Aug 25'!$G$8:$G$42=$T6)*'Aug 25'!$AK$8:$AK$42) -> 0 | AT6: =SUMPRODUCT(('Aug 26'!$F$8:$F$42=$T6)*'Aug 26'!$AJ$8:$AJ$42+('Aug 26'!$G$8:$G$42=$T6)*'Aug 26'!$AK$8:$AK$42) -> 0 | AU6: =SUMPRODUCT(('Aug 27'!$F$8:$F$42=$T6)*'Aug 27'!$AJ$8:$AJ$42+('Aug 27'!$G$8:$G$42=$T6)*'Aug 27'!$AK$8:$AK$42) -> 0 | AV6: =SUMPRODUCT(('Aug 28'!$F$8:$F$42=$T6)*'Aug 28'!$AJ$8:$AJ$42+('Aug 28'!$G$8:$G$42=$T6)*'Aug 28'!$AK$8:$AK$42) -> 0 | AW6: =SUMPRODUCT(('Aug 29'!$F$8:$F$42=$T6)*'Aug 29'!$AJ$8:$AJ$42+('Aug 29'!$G$8:$G$42=$T6)*'Aug 29'!$AK$8:$AK$42) -> 0 | AX6: =SUMPRODUCT(('Aug 30'!$F$8:$F$42=$T6)*'Aug 30'!$AJ$8:$AJ$42+('Aug 30'!$G$8:$G$42=$T6)*'Aug 30'!$AK$8:$AK$42) -> 0 | AY6: =SUMPRODUCT(('Aug 31'!$F$8:$F$42=$T6)*'Aug 31'!$AJ$8:$AJ$42+('Aug 31'!$G$8:$G$42=$T6)*'Aug 31'!$AK$8:$AK$42) -> 0 | BA6: =SUM(U6:AD6) -> 0 | BB6: =MATCH(BD6,'Pay Plan'!$C$6:$C$12,1) -> 1 | BC6: =SUMPRODUCT(('Aug 1'!$F$8:$F$42=$T6)*'Aug 1'!$AI$8:$AI$42*(('Aug 1'!$AM$8:$AM$42="Y")+('Aug 1'!$AN$8:$AN$42="Y")+('Aug 1'!$AO$8:$AO$42="Y")))+SUMPRODUCT(('Aug 2'!$F$8:$F$42=$T6)*'Aug 2'!$AI$8:$AI$42*(('Aug 2'!$AM$8:$AM$42="Y")+('Aug 2'!$AN$8:$AN$42="Y")+('Aug 2'!$AO$8:$AO$42="Y")))+SUMPRODUCT(('Aug 3'!$F$8:$F$42=$T6)*'Aug 3'!$AI$8:$AI$42*(('Aug 3'!$AM$8:$AM$42="Y")+('Aug 3'!$AN$8:$AN$42="Y")+('Aug 3'!$AO$8:$AO$42="Y")))+SUMPRODUCT(('Aug 4'!$F$8:$F$42=$T6)*'Aug 4'!$AI$8:$AI$42*(('Aug 4'!$AM$8:$AM$42="Y")+('Aug 4'!$AN$8:$AN$42="Y")+('Aug 4'!$AO$8:$AO$42="Y")))+SUMPRODUCT(('Aug 5'!$F$8:$F$42=$T6)*'Aug 5'!$AI$8:$AI$42*(('Aug 5'!$AM$8:$AM$42="Y")+('Aug 5'!$AN$8:$AN$42="Y")+('Aug 5'!$AO$8:$AO$42="Y")))+SUMPRODUCT(('Aug 6'!$F$8:$F$42=$T6)*'Aug 6'!$AI$8:$AI$42*(('Aug 6'!$AM$8:$AM$42="Y")+('Aug 6'!$AN$8:$AN$42="Y")+('Aug 6'!$AO$8:$AO$42="Y")))+SUMPRODUCT(('Aug 7'!$F$8:$F$42=$T6)*'Aug 7'!$AI$8:$AI$42*(('Aug 7'!$AM$8:$AM$42="Y")+('Aug 7'!$AN$8:$AN$42="Y")+('Aug 7'!$AO$8:$AO$42="Y")))+SUMPRODUCT(('Aug 8'!$F$8:$F$42=$T6)*'Aug 8'!$AI$8:$AI$42*(('Aug 8'!$AM$8:$AM$42="Y")+('Aug 8'!$AN$8:$AN$42="Y")+('Aug 8'!$AO$8:$AO$42="Y")))+SUMPRODUCT(('Aug 9'!$F$8:$F$42=$T6)*'Aug 9'!$AI$8:$AI$42*(('Aug 9'!$AM$8:$AM$42="Y")+('Aug 9'!$AN$8:$AN$42="Y")+('Aug 9'!$AO$8:$AO$42="Y")))+SUMPRODUCT(('Aug 10'!$F$8:$F$42=$T6)*'Aug 10'!$AI$8:$AI$42*(('Aug 10'!$AM$8:$AM$42="Y")+('Aug 10'!$AN$8:$AN$42="Y")+('Aug 10'!$AO$8:$AO$42="Y")))+SUMPRODUCT(('Aug 11'!$F$8:$F$42=$T6)*'Aug 11'!$AI$8:$AI$42*(('Aug 11'!$AM$8:$AM$42="Y")+('Aug 11'!$AN$8:$AN$42="Y")+('Aug 11'!$AO$8:$AO$42="Y")))+SUMPRODUCT(('Aug 12'!$F$8:$F$42=$T6)*'Aug 12'!$AI$8:$AI$42*(('Aug 12'!$AM$8:$AM$42="Y")+('Aug 12'!$AN$8:$AN$42="Y")+('Aug 12'!$AO$8:$AO$42="Y")))+SUMPRODUCT(('Aug 13'!$F$8:$F$42=$T6)*'Aug 13'!$AI$8:$AI$42*(('Aug 13'!$AM$8:$AM$42="Y")+('Aug 13'!$AN$8:$AN$42="Y")+('Aug 13'!$AO$8:$AO$42="Y")))+SUMPRODUCT(('Aug 14'!$F$8:$F$42=$T6)*'Aug 14'!$AI$8:$AI$42*(('Aug 14'!$AM$8:$AM$42="Y")+('Aug 14'!$AN$8:$AN$42="Y")+('Aug 14'!$AO$8:$AO$42="Y")))+SUMPRODUCT(('Aug 15'!$F$8:$F$42=$T6)*'Aug 15'!$AI$8:$AI$42*(('Aug 15'!$AM$8:$AM$42="Y")+('Aug 15'!$AN$8:$AN$42="Y")+('Aug 15'!$AO$8:$AO$42="Y")))+SUMPRODUCT(('Aug 16'!$F$8:$F$42=$T6)*'Aug 16'!$AI$8:$AI$42*(('Aug 16'!$AM$8:$AM$42="Y")+('Aug 16'!$AN$8:$AN$42="Y")+('Aug 16'!$AO$8:$AO$42="Y")))+SUMPRODUCT(('Aug 17'!$F$8:$F$42=$T6)*'Aug 17'!$AI$8:$AI$42*(('Aug 17'!$AM$8:$AM$42="Y")+('Aug 17'!$AN$8:$AN$42="Y")+('Aug 17'!$AO$8:$AO$42="Y")))+SUMPRODUCT(('Aug 18'!$F$8:$F$42=$T6)*'Aug 18'!$AI$8:$AI$42*(('Aug 18'!$AM$8:$AM$42="Y")+('Aug 18'!$AN$8:$AN$42="Y")+('Aug 18'!$AO$8:$AO$42="Y")))+SUMPRODUCT(('Aug 19'!$F$8:$F$42=$T6)*'Aug 19'!$AI$8:$AI$42*(('Aug 19'!$AM$8:$AM$42="Y")+('Aug 19'!$AN$8:$AN$42="Y")+('Aug 19'!$AO$8:$AO$42="Y")))+SUMPRODUCT(('Aug 20'!$F$8:$F$42=$T6)*'Aug 20'!$AI$8:$AI$42*(('Aug 20'!$AM$8:$AM$42="Y")+('Aug 20'!$AN$8:$AN$42="Y")+('Aug 20'!$AO$8:$AO$42="Y")))+SUMPRODUCT(('Aug 21'!$F$8:$F$42=$T6)*'Aug 21'!$AI$8:$AI$42*(('Aug 21'!$AM$8:$AM$42="Y")+('Aug 21'!$AN$8:$AN$42="Y")+('Aug 21'!$AO$8:$AO$42="Y")))+SUMPRODUCT(('Aug 22'!$F$8:$F$42=$T6)*'Aug 22'!$AI$8:$AI$42*(('Aug 22'!$AM$8:$AM$42="Y")+('Aug 22'!$AN$8:$AN$42="Y")+('Aug 22'!$AO$8:$AO$42="Y")))+SUMPRODUCT(('Aug 23'!$F$8:$F$42=$T6)*'Aug 23'!$AI$8:$AI$42*(('Aug 23'!$AM$8:$AM$42="Y")+('Aug 23'!$AN$8:$AN$42="Y")+('Aug 23'!$AO$8:$AO$42="Y")))+SUMPRODUCT(('Aug 24'!$F$8:$F$42=$T6)*'Aug 24'!$AI$8:$AI$42*(('Aug 24'!$AM$8:$AM$42="Y")+('Aug 24'!$AN$8:$AN$42="Y")+('Aug 24'!$AO$8:$AO$42="Y")))+SUMPRODUCT(('Aug 25'!$F$8:$F$42=$T6)*'Aug 25'!$AI$8:$AI$42*(('Aug 25'!$AM$8:$AM$42="Y")+('Aug 25'!$AN$8:$AN$42="Y")+('Aug 25'!$AO$8:$AO$42="Y")))+SUMPRODUCT(('Aug 26'!$F$8:$F$42=$T6)*'Aug 26'!$AI$8:$AI$42*(('Aug 26'!$AM$8:$AM$42="Y")+('Aug 26'!$AN$8:$AN$42="Y")+('Aug 26'!$AO$8:$AO$42="Y")))+SUMPRODUCT(('Aug 27'!$F$8:$F$42=$T6)*'Aug 27'!$AI$8:$AI$42*(('Aug 27'!$AM$8:$AM$42="Y")+('Aug 27'!$AN$8:$AN$42="Y")+('Aug 27'!$AO$8:$AO$42="Y")))+SUMPRODUCT(('Aug 28'!$F$8:$F$42=$T6)*'Aug 28'!$AI$8:$AI$42*(('Aug 28'!$AM$8:$AM$42="Y")+('Aug 28'!$AN$8:$AN$42="Y")+('Aug 28'!$AO$8:$AO$42="Y")))+SUMPRODUCT(('Aug 29'!$F$8:$F$42=$T6)*'Aug 29'!$AI$8:$AI$42*(('Aug 29'!$AM$8:$AM$42="Y")+('Aug 29'!$AN$8:$AN$42="Y")+('Aug 29'!$AO$8:$AO$42="Y")))+SUMPRODUCT(('Aug 30'!$F$8:$F$42=$T6)*'Aug 30'!$AI$8:$AI$42*(('Aug 30'!$AM$8:$AM$42="Y")+('Aug 30'!$AN$8:$AN$42="Y")+('Aug 30'!$AO$8:$AO$42="Y")))+SUMPRODUCT(('Aug 31'!$F$8:$F$42=$T6)*'Aug 31'!$AI$8:$AI$42*(('Aug 31'!$AM$8:$AM$42="Y")+('Aug 31'!$AN$8:$AN$42="Y")+('Aug 31'!$AO$8:$AO$42="Y"))) -> 0 | BD6: =SUM(U6:AY6) -> 0 | BE6: =SUM(U25:AY25) -> 0 | BF6: =SUM(U44:AY44) -> 0 | BH6: =MIN(BF4:BF19) -> 0
